Workbook
Name BLENDED_RATE: CostStructure!$B$10
Name DIM_PCT_CAR: Inputs!$C$18
Name DIM_PCT_MES: Inputs!$D$18
Name DIM_PCT_TOM: Inputs!$B$18
Name ENUM_MAXPROFIT: Enumeration!$S$1
Name ENUM_OPT_QC: Enumeration!$S$3
Name ENUM_OPT_QM: Enumeration!$S$4
Name ENUM_OPT_QT: Enumeration!$S$2
Name FARMER_HRS: Inputs!$B$7
Name FARMER_HRS_USED: CostStructure!$B$7
Name FARMER_RATE: Inputs!$B$9
Name FARMER_WAGE: Inputs!$B$8
Name FERT_BED_CAR: Inputs!$C$19
Name FERT_BED_MES: Inputs!$D$19
Name FERT_BED_TOM: Inputs!$B$19
Name FIXED_COSTS: Inputs!$B$6
Name LABOR_HRS_CAP: Inputs!$B$14
Name LABOR_HRS_WK_CAR: Inputs!$C$20
Name LABOR_HRS_WK_MES: Inputs!$D$20
Name LABOR_HRS_WK_TOM: Inputs!$B$20
Name MAX_BEDS_CAR: Inputs!$C$22
Name MAX_BEDS_MES: Inputs!$D$22
Name MAX_BEDS_TOM: Inputs!$B$22
Name PRICE_CAR: Inputs!$C$21
Name PRICE_MES: Inputs!$D$21
Name PRICE_TOM: Inputs!$B$21
Name PROFIT: CostStructure!$B$21
Name Q_CAR: Optimization!$B$5
Name Q_MES: Optimization!$B$6
Name Q_TOM: Optimization!$B$4
Name SEASON_WEEKS: Inputs!$B$4
Name SHADOW_PRICE_CAR: Summary!$K$37
Name SHADOW_PRICE_MES: Summary!$K$38
Name SHADOW_PRICE_TOM: Summary!$K$36
Name TEMP_LABOR_HRS: CostStructure!$B$8
Name TEMP_WORKER_HRS: Inputs!$B$11
Name TEMP_WORKER_MAX: Inputs!$B$13
Name TEMP_WORKER_RATE: Inputs!$B$12
Name TEMP_WORKER_WAGE: Inputs!$B$10
Name TOTAL_BEDS: Inputs!$B$5
Name TOTAL_FERT_COST: CostStructure!$B$14
Name TOTAL_LABOR_COST: CostStructure!$B$9
Name TOTAL_LABOR_HRS: CostStructure!$B$6
Name TOTAL_REVENUE: CostStructure!$B$15
Name XING_CAR: MCSchedules!$B$58
Name XING_FIRST_CAR: MCSchedules!$B$59
Name XING_FIRST_MES: MCSchedules!$B$102
Name XING_FIRST_TOM: MCSchedules!$B$28
Name XING_MES: MCSchedules!$B$101
Name XING_TOM: MCSchedules!$B$27

Sheet Inputs
A1: Marginal analysis - Inputs (named contract). Every value is entered once here; everything downstream references these names.
A3: Name | B3: Value | C3: Unit | D3: Source
A4: SEASON_WEEKS | B4: 36 | C4: weeks | D4: Case scenario
A5: TOTAL_BEDS | B5: 64 | C5: beds (16 x 4 plots) | D5: Case scenario
A6: FIXED_COSTS | B6: 20000 | C6: USD per season | D6: Case scenario
A7: FARMER_HRS | B7: 720 | C7: field hours per season | D7: Case scenario ("half her time in the field")
A8: FARMER_WAGE | B8: 50000 | C8: USD per season | D8: Case scenario - feeds FARMER_RATE only, no other formula
A9: FARMER_RATE | B9: =(FARMER_WAGE/2)/FARMER_HRS -> 34.722222 | C9: USD per field hour | D9: Derived (exact quotient); displays 34.72
A10: TEMP_WORKER_WAGE | B10: 25000 | C10: USD per worker per season | D10: Case scenario - feeds TEMP_WORKER_RATE and the hours ceiling only
A11: TEMP_WORKER_HRS | B11: 1440 | C11: hours per worker per season | D11: Case scenario
A12: TEMP_WORKER_RATE | B12: =TEMP_WORKER_WAGE/TEMP_WORKER_HRS -> 17.361111 | C12: USD per hour | D12: Derived (exact quotient); displays 17.36
A13: TEMP_WORKER_MAX | B13: 4 | C13: workers | D13: Case scenario
A14: LABOR_HRS_CAP | B14: =FARMER_HRS+TEMP_WORKER_MAX*TEMP_WORKER_HRS -> 6480 | C14: hours per season | D14: Derived
A16: Per-crop economics (crop table). DIM_PCT is a decimal fraction in its own cell.
A17: Name | B17: TOM | C17: CAR | D17: MES | E17: Unit
A18: DIM_PCT | B18: 0.1 | C18: 0.025 | D18: 0.0125 | E18: per bed (decimal fraction)
A19: FERT_BED | B19: 880 | C19: 440 | D19: 880 | E19: USD per bed
A20: LABOR_HRS_WK | B20: 2.5 | C20: =5/6 -> 0.83333333 | D20: 1.25 | E20: hours per week per bed (CAR held as 5/6, exact, per the Stage 2 published check figures)
A21: PRICE | B21: 8800 | C21: 2094 | D21: 2700 | E21: USD per bed
A22: MAX_BEDS | B22: 20 | C22: 20 | D22: 30 | E22: beds

Sheet CropEconomics
A1: Crop economics - REVENUE, FERT_COST, LABOR_HRS as a function of the crop's own bed count q. Column A (q) is a region grid index: integers 0..MAX_BEDS(c).
A3: TOMATOES
A4: q | B4: REVENUE(TOM,q) | C4: FERT_COST(TOM,q) | D4: LABOR_HRS(TOM,q)
A5: 0 | B5: =A5*PRICE_TOM -> 0 | C5: =A5*FERT_BED_TOM -> 0 | D5: =IF(A5=0,0,A5*LABOR_HRS_WK_TOM*SEASON_WEEKS*(1+DIM_PCT_TOM)^A5) -> 0
A6: 1 | B6: =A6*PRICE_TOM -> 8800 | C6: =A6*FERT_BED_TOM -> 880 | D6: =IF(A6=0,0,A6*LABOR_HRS_WK_TOM*SEASON_WEEKS*(1+DIM_PCT_TOM)^A6) -> 99
A7: 2 | B7: =A7*PRICE_TOM -> 17600 | C7: =A7*FERT_BED_TOM -> 1760 | D7: =IF(A7=0,0,A7*LABOR_HRS_WK_TOM*SEASON_WEEKS*(1+DIM_PCT_TOM)^A7) -> 217.8
A8: 3 | B8: =A8*PRICE_TOM -> 26400 | C8: =A8*FERT_BED_TOM -> 2640 | D8: =IF(A8=0,0,A8*LABOR_HRS_WK_TOM*SEASON_WEEKS*(1+DIM_PCT_TOM)^A8) -> 359.37
A9: 4 | B9: =A9*PRICE_TOM -> 35200 | C9: =A9*FERT_BED_TOM -> 3520 | D9: =IF(A9=0,0,A9*LABOR_HRS_WK_TOM*SEASON_WEEKS*(1+DIM_PCT_TOM)^A9) -> 527.076
A10: 5 | B10: =A10*PRICE_TOM -> 44000 | C10: =A10*FERT_BED_TOM -> 4400 | D10: =IF(A10=0,0,A10*LABOR_HRS_WK_TOM*SEASON_WEEKS*(1+DIM_PCT_TOM)^A10) -> 724.7295
A11: 6 | B11: =A11*PRICE_TOM -> 52800 | C11: =A11*FERT_BED_TOM -> 5280 | D11: =IF(A11=0,0,A11*LABOR_HRS_WK_TOM*SEASON_WEEKS*(1+DIM_PCT_TOM)^A11) -> 956.64294
A12: 7 | B12: =A12*PRICE_TOM -> 61600 | C12: =A12*FERT_BED_TOM -> 6160 | D12: =IF(A12=0,0,A12*LABOR_HRS_WK_TOM*SEASON_WEEKS*(1+DIM_PCT_TOM)^A12) -> 1227.6918
A13: 8 | B13: =A13*PRICE_TOM -> 70400 | C13: =A13*FERT_BED_TOM -> 7040 | D13: =IF(A13=0,0,A13*LABOR_HRS_WK_TOM*SEASON_WEEKS*(1+DIM_PCT_TOM)^A13) -> 1543.3839
A14: 9 | B14: =A14*PRICE_TOM -> 79200 | C14: =A14*FERT_BED_TOM -> 7920 | D14: =IF(A14=0,0,A14*LABOR_HRS_WK_TOM*SEASON_WEEKS*(1+DIM_PCT_TOM)^A14) -> 1909.9376
A15: 10 | B15: =A15*PRICE_TOM -> 88000 | C15: =A15*FERT_BED_TOM -> 8800 | D15: =IF(A15=0,0,A15*LABOR_HRS_WK_TOM*SEASON_WEEKS*(1+DIM_PCT_TOM)^A15) -> 2334.3682
A16: 11 | B16: =A16*PRICE_TOM -> 96800 | C16: =A16*FERT_BED_TOM -> 9680 | D16: =IF(A16=0,0,A16*LABOR_HRS_WK_TOM*SEASON_WEEKS*(1+DIM_PCT_TOM)^A16) -> 2824.5855
... A25: 20 | B25: =A25*PRICE_TOM -> 176000 | C25: =A25*FERT_BED_TOM -> 17600 | D25: =IF(A25=0,0,A25*LABOR_HRS_WK_TOM*SEASON_WEEKS*(1+DIM_PCT_TOM)^A25) -> 12109.5
A27: CARROTS
A28: q | B28: REVENUE(CAR,q) | C28: FERT_COST(CAR,q) | D28: LABOR_HRS(CAR,q)
A29: 0 | B29: =A29*PRICE_CAR -> 0 | C29: =A29*FERT_BED_CAR -> 0 | D29: =IF(A29=0,0,A29*LABOR_HRS_WK_CAR*SEASON_WEEKS*(1+DIM_PCT_CAR)^A29) -> 0
A30: 1 | B30: =A30*PRICE_CAR -> 2094 | C30: =A30*FERT_BED_CAR -> 440 | D30: =IF(A30=0,0,A30*LABOR_HRS_WK_CAR*SEASON_WEEKS*(1+DIM_PCT_CAR)^A30) -> 30.75
A31: 2 | B31: =A31*PRICE_CAR -> 4188 | C31: =A31*FERT_BED_CAR -> 880 | D31: =IF(A31=0,0,A31*LABOR_HRS_WK_CAR*SEASON_WEEKS*(1+DIM_PCT_CAR)^A31) -> 63.0375
A32: 3 | B32: =A32*PRICE_CAR -> 6282 | C32: =A32*FERT_BED_CAR -> 1320 | D32: =IF(A32=0,0,A32*LABOR_HRS_WK_CAR*SEASON_WEEKS*(1+DIM_PCT_CAR)^A32) -> 96.920156
A33: 4 | B33: =A33*PRICE_CAR -> 8376 | C33: =A33*FERT_BED_CAR -> 1760 | D33: =IF(A33=0,0,A33*LABOR_HRS_WK_CAR*SEASON_WEEKS*(1+DIM_PCT_CAR)^A33) -> 132.45755
A34: 5 | B34: =A34*PRICE_CAR -> 10470 | C34: =A34*FERT_BED_CAR -> 2200 | D34: =IF(A34=0,0,A34*LABOR_HRS_WK_CAR*SEASON_WEEKS*(1+DIM_PCT_CAR)^A34) -> 169.71123
A35: 6 | B35: =A35*PRICE_CAR -> 12564 | C35: =A35*FERT_BED_CAR -> 2640 | D35: =IF(A35=0,0,A35*LABOR_HRS_WK_CAR*SEASON_WEEKS*(1+DIM_PCT_CAR)^A35) -> 208.74482
A36: 7 | B36: =A36*PRICE_CAR -> 14658 | C36: =A36*FERT_BED_CAR -> 3080 | D36: =IF(A36=0,0,A36*LABOR_HRS_WK_CAR*SEASON_WEEKS*(1+DIM_PCT_CAR)^A36) -> 249.62401
A37: 8 | B37: =A37*PRICE_CAR -> 16752 | C37: =A37*FERT_BED_CAR -> 3520 | D37: =IF(A37=0,0,A37*LABOR_HRS_WK_CAR*SEASON_WEEKS*(1+DIM_PCT_CAR)^A37) -> 292.4167
A38: 9 | B38: =A38*PRICE_CAR -> 18846 | C38: =A38*FERT_BED_CAR -> 3960 | D38: =IF(A38=0,0,A38*LABOR_HRS_WK_CAR*SEASON_WEEKS*(1+DIM_PCT_CAR)^A38) -> 337.193
A39: 10 | B39: =A39*PRICE_CAR -> 20940 | C39: =A39*FERT_BED_CAR -> 4400 | D39: =IF(A39=0,0,A39*LABOR_HRS_WK_CAR*SEASON_WEEKS*(1+DIM_PCT_CAR)^A39) -> 384.02536
A40: 11 | B40: =A40*PRICE_CAR -> 23034 | C40: =A40*FERT_BED_CAR -> 4840 | D40: =IF(A40=0,0,A40*LABOR_HRS_WK_CAR*SEASON_WEEKS*(1+DIM_PCT_CAR)^A40) -> 432.9886
... A49: 20 | B49: =A49*PRICE_CAR -> 41880 | C49: =A49*FERT_BED_CAR -> 8800 | D49: =IF(A49=0,0,A49*LABOR_HRS_WK_CAR*SEASON_WEEKS*(1+DIM_PCT_CAR)^A49) -> 983.16986
A51: MESCLUN
A52: q | B52: REVENUE(MES,q) | C52: FERT_COST(MES,q) | D52: LABOR_HRS(MES,q)
A53: 0 | B53: =A53*PRICE_MES -> 0 | C53: =A53*FERT_BED_MES -> 0 | D53: =IF(A53=0,0,A53*LABOR_HRS_WK_MES*SEASON_WEEKS*(1+DIM_PCT_MES)^A53) -> 0
A54: 1 | B54: =A54*PRICE_MES -> 2700 | C54: =A54*FERT_BED_MES -> 880 | D54: =IF(A54=0,0,A54*LABOR_HRS_WK_MES*SEASON_WEEKS*(1+DIM_PCT_MES)^A54) -> 45.5625
A55: 2 | B55: =A55*PRICE_MES -> 5400 | C55: =A55*FERT_BED_MES -> 1760 | D55: =IF(A55=0,0,A55*LABOR_HRS_WK_MES*SEASON_WEEKS*(1+DIM_PCT_MES)^A55) -> 92.264062
A56: 3 | B56: =A56*PRICE_MES -> 8100 | C56: =A56*FERT_BED_MES -> 2640 | D56: =IF(A56=0,0,A56*LABOR_HRS_WK_MES*SEASON_WEEKS*(1+DIM_PCT_MES)^A56) -> 140.12604
A57: 4 | B57: =A57*PRICE_MES -> 10800 | C57: =A57*FERT_BED_MES -> 3520 | D57: =IF(A57=0,0,A57*LABOR_HRS_WK_MES*SEASON_WEEKS*(1+DIM_PCT_MES)^A57) -> 189.17016
A58: 5 | B58: =A58*PRICE_MES -> 13500 | C58: =A58*FERT_BED_MES -> 4400 | D58: =IF(A58=0,0,A58*LABOR_HRS_WK_MES*SEASON_WEEKS*(1+DIM_PCT_MES)^A58) -> 239.41848
A59: 6 | B59: =A59*PRICE_MES -> 16200 | C59: =A59*FERT_BED_MES -> 5280 | D59: =IF(A59=0,0,A59*LABOR_HRS_WK_MES*SEASON_WEEKS*(1+DIM_PCT_MES)^A59) -> 290.89346
...

Sheet MCSchedules
A1: Standalone marginal-cost schedules. Each crop as if it were the only crop: full FARMER_HRS available, beds free to MAX_BEDS(c). Uses the farmer/temp split (LABOR_COST_SA), NOT the blended rate. Column A (q) is a region grid index; the q=0 row carries the structural zero TVC(c,0)=0 and the reported schedule is q=1..MAX_BEDS(c).
A3: TOMATOES
A4: q | B4: LABOR_HRS | C4: FARMER_HRS_USED | D4: TEMP_HRS_USED | E4: LABOR_COST_SA | F4: FERT_COST | G4: TVC | H4: MARG_COST | I4: PRICE | J4: MARG_REVENUE | K4: SA_PROFIT | L4: q if MC>=PRICE | M4: DIP
A5: 0 | B5: =IF(A5=0,0,A5*LABOR_HRS_WK_TOM*SEASON_WEEKS*(1+DIM_PCT_TOM)^A5) -> 0 | C5: =MIN(B5,FARMER_HRS) -> 0 | D5: =MAX(0,B5-FARMER_HRS) -> 0 | E5: =C5*FARMER_RATE+D5*TEMP_WORKER_RATE -> 0 | F5: =A5*FERT_BED_TOM -> 0 | G5: =F5+E5 -> 0 | I5: =PRICE_TOM -> 8800 | J5: =PRICE_TOM -> 8800 | K5: =A5*PRICE_TOM-G5 -> 0
A6: 1 | B6: =IF(A6=0,0,A6*LABOR_HRS_WK_TOM*SEASON_WEEKS*(1+DIM_PCT_TOM)^A6) -> 99 | C6: =MIN(B6,FARMER_HRS) -> 99 | D6: =MAX(0,B6-FARMER_HRS) -> 0 | E6: =C6*FARMER_RATE+D6*TEMP_WORKER_RATE -> 3437.5 | F6: =A6*FERT_BED_TOM -> 880 | G6: =F6+E6 -> 4317.5 | H6: =G6-G5 -> 4317.5 | I6: =PRICE_TOM -> 8800 | J6: =PRICE_TOM -> 8800 | K6: =A6*PRICE_TOM-G6 -> 4482.5 | L6: =IF(H6>=PRICE_TOM,A6,"")
A7: 2 | B7: =IF(A7=0,0,A7*LABOR_HRS_WK_TOM*SEASON_WEEKS*(1+DIM_PCT_TOM)^A7) -> 217.8 | C7: =MIN(B7,FARMER_HRS) -> 217.8 | D7: =MAX(0,B7-FARMER_HRS) -> 0 | E7: =C7*FARMER_RATE+D7*TEMP_WORKER_RATE -> 7562.5 | F7: =A7*FERT_BED_TOM -> 1760 | G7: =F7+E7 -> 9322.5 | H7: =G7-G6 -> 5005 | I7: =PRICE_TOM -> 8800 | J7: =PRICE_TOM -> 8800 | K7: =A7*PRICE_TOM-G7 -> 8277.5 | L7: =IF(H7>=PRICE_TOM,A7,"") | M7: =IF(H7<H6,"DIP","")
A8: 3 | B8: =IF(A8=0,0,A8*LABOR_HRS_WK_TOM*SEASON_WEEKS*(1+DIM_PCT_TOM)^A8) -> 359.37 | C8: =MIN(B8,FARMER_HRS) -> 359.37 | D8: =MAX(0,B8-FARMER_HRS) -> 0 | E8: =C8*FARMER_RATE+D8*TEMP_WORKER_RATE -> 12478.125 | F8: =A8*FERT_BED_TOM -> 2640 | G8: =F8+E8 -> 15118.125 | H8: =G8-G7 -> 5795.625 | I8: =PRICE_TOM -> 8800 | J8: =PRICE_TOM -> 8800 | K8: =A8*PRICE_TOM-G8 -> 11281.875 | L8: =IF(H8>=PRICE_TOM,A8,"") | M8: =IF(H8<H7,"DIP","")
A9: 4 | B9: =IF(A9=0,0,A9*LABOR_HRS_WK_TOM*SEASON_WEEKS*(1+DIM_PCT_TOM)^A9) -> 527.076 | C9: =MIN(B9,FARMER_HRS) -> 527.076 | D9: =MAX(0,B9-FARMER_HRS) -> 0 | E9: =C9*FARMER_RATE+D9*TEMP_WORKER_RATE -> 18301.25 | F9: =A9*FERT_BED_TOM -> 3520 | G9: =F9+E9 -> 21821.25 | H9: =G9-G8 -> 6703.125 | I9: =PRICE_TOM -> 8800 | J9: =PRICE_TOM -> 8800 | K9: =A9*PRICE_TOM-G9 -> 13378.75 | L9: =IF(H9>=PRICE_TOM,A9,"") | M9: =IF(H9<H8,"DIP","")
A10: 5 | B10: =IF(A10=0,0,A10*LABOR_HRS_WK_TOM*SEASON_WEEKS*(1+DIM_PCT_TOM)^A10) -> 724.7295 | C10: =MIN(B10,FARMER_HRS) -> 720 | D10: =MAX(0,B10-FARMER_HRS) -> 4.7295 | E10: =C10*FARMER_RATE+D10*TEMP_WORKER_RATE -> 25082.109 | F10: =A10*FERT_BED_TOM -> 4400 | G10: =F10+E10 -> 29482.109 | H10: =G10-G9 -> 7660.8594 | I10: =PRICE_TOM -> 8800 | J10: =PRICE_TOM -> 8800 | K10: =A10*PRICE_TOM-G10 -> 14517.891 | L10: =IF(H10>=PRICE_TOM,A10,"") | M10: =IF(H10<H9,"DIP","")
A11: 6 | B11: =IF(A11=0,0,A11*LABOR_HRS_WK_TOM*SEASON_WEEKS*(1+DIM_PCT_TOM)^A11) -> 956.64294 | C11: =MIN(B11,FARMER_HRS) -> 720 | D11: =MAX(0,B11-FARMER_HRS) -> 236.64294 | E11: =C11*FARMER_RATE+D11*TEMP_WORKER_RATE -> 29108.384 | F11: =A11*FERT_BED_TOM -> 5280 | G11: =F11+E11 -> 34388.384 | H11: =G11-G10 -> 4906.275 | I11: =PRICE_TOM -> 8800 | J11: =PRICE_TOM -> 8800 | K11: =A11*PRICE_TOM-G11 -> 18411.616 | L11: =IF(H11>=PRICE_TOM,A11,"") | M11: =IF(H11<H10,"DIP","") -> DIP
A12: 7 | B12: =IF(A12=0,0,A12*LABOR_HRS_WK_TOM*SEASON_WEEKS*(1+DIM_PCT_TOM)^A12) -> 1227.6918 | C12: =MIN(B12,FARMER_HRS) -> 720 | D12: =MAX(0,B12-FARMER_HRS) -> 507.69177 | E12: =C12*FARMER_RATE+D12*TEMP_WORKER_RATE -> 33814.093 | F12: =A12*FERT_BED_TOM -> 6160 | G12: =F12+E12 -> 39974.093 | H12: =G12-G11 -> 5585.7089 | I12: =PRICE_TOM -> 8800 | J12: =PRICE_TOM -> 8800 | K12: =A12*PRICE_TOM-G12 -> 21625.907 | L12: =IF(H12>=PRICE_TOM,A12,"") | M12: =IF(H12<H11,"DIP","")
A13: 8 | B13: =IF(A13=0,0,A13*LABOR_HRS_WK_TOM*SEASON_WEEKS*(1+DIM_PCT_TOM)^A13) -> 1543.3839 | C13: =MIN(B13,FARMER_HRS) -> 720 | D13: =MAX(0,B13-FARMER_HRS) -> 823.38394 | E13: =C13*FARMER_RATE+D13*TEMP_WORKER_RATE -> 39294.86 | F13: =A13*FERT_BED_TOM -> 7040 | G13: =F13+E13 -> 46334.86 | H13: =G13-G12 -> 6360.7668 | I13: =PRICE_TOM -> 8800 | J13: =PRICE_TOM -> 8800 | K13: =A13*PRICE_TOM-G13 -> 24065.14 | L13: =IF(H13>=PRICE_TOM,A13,"") | M13: =IF(H13<H12,"DIP","")
A14: 9 | B14: =IF(A14=0,0,A14*LABOR_HRS_WK_TOM*SEASON_WEEKS*(1+DIM_PCT_TOM)^A14) -> 1909.9376 | C14: =MIN(B14,FARMER_HRS) -> 720 | D14: =MAX(0,B14-FARMER_HRS) -> 1189.9376 | E14: =C14*FARMER_RATE+D14*TEMP_WORKER_RATE -> 45658.639 | F14: =A14*FERT_BED_TOM -> 7920 | G14: =F14+E14 -> 53578.639 | H14: =G14-G13 -> 7243.7793 | I14: =PRICE_TOM -> 8800 | J14: =PRICE_TOM -> 8800 | K14: =A14*PRICE_TOM-G14 -> 25621.361 | L14: =IF(H14>=PRICE_TOM,A14,"") | M14: =IF(H14<H13,"DIP","")
A15: 10 | B15: =IF(A15=0,0,A15*LABOR_HRS_WK_TOM*SEASON_WEEKS*(1+DIM_PCT_TOM)^A15) -> 2334.3682 | C15: =MIN(B15,FARMER_HRS) -> 720 | D15: =MAX(0,B15-FARMER_HRS) -> 1614.3682 | E15: =C15*FARMER_RATE+D15*TEMP_WORKER_RATE -> 53027.226 | F15: =A15*FERT_BED_TOM -> 8800 | G15: =F15+E15 -> 61827.226 | H15: =G15-G14 -> 8248.5865 | I15: =PRICE_TOM -> 8800 | J15: =PRICE_TOM -> 8800 | K15: =A15*PRICE_TOM-G15 -> 26172.774 | L15: =IF(H15>=PRICE_TOM,A15,"") | M15: =IF(H15<H14,"DIP","")
A16: 11 | B16: =IF(A16=0,0,A16*LABOR_HRS_WK_TOM*SEASON_WEEKS*(1+DIM_PCT_TOM)^A16) -> 2824.5855 | C16: =MIN(B16,FARMER_HRS) -> 720 | D16: =MAX(0,B16-FARMER_HRS) -> 2104.5855 | E16: =C16*FARMER_RATE+D16*TEMP_WORKER_RATE -> 61537.943 | F16: =A16*FERT_BED_TOM -> 9680 | G16: =F16+E16 -> 71217.943 | H16: =G16-G15 -> 9390.7174 | I16: =PRICE_TOM -> 8800 | J16: =PRICE_TOM -> 8800 | K16: =A16*PRICE_TOM-G16 -> 25582.057 | L16: =IF(H16>=PRICE_TOM,A16,"") -> 11 | M16: =IF(H16<H15,"DIP","")
A17: 12 | B17: =IF(A17=0,0,A17*LABOR_HRS_WK_TOM*SEASON_WEEKS*(1+DIM_PCT_TOM)^A17) -> 3389.5026 | C17: =MIN(B17,FARMER_HRS) -> 720 | D17: =MAX(0,B17-FARMER_HRS) -> 2669.5026 | E17: =C17*FARMER_RATE+D17*TEMP_WORKER_RATE -> 71345.532 | F17: =A17*FERT_BED_TOM -> 10560 | G17: =F17+E17 -> 81905.532 | H17: =G17-G16 -> 10687.589 | I17: =PRICE_TOM -> 8800 | J17: =PRICE_TOM -> 8800 | K17: =A17*PRICE_TOM-G17 -> 23694.468 | L17: =IF(H17>=PRICE_TOM,A17,"") -> 12 | M17: =IF(H17<H16,"DIP","")
A18: 13 | B18: =IF(A18=0,0,A18*LABOR_HRS_WK_TOM*SEASON_WEEKS*(1+DIM_PCT_TOM)^A18) -> 4039.1573 | C18: =MIN(B18,FARMER_HRS) -> 720 | D18: =MAX(0,B18-FARMER_HRS) -> 3319.1573 | E18: =C18*FARMER_RATE+D18*TEMP_WORKER_RATE -> 82624.259 | F18: =A18*FERT_BED_TOM -> 11440 | G18: =F18+E18 -> 94064.259 | H18: =G18-G17 -> 12158.727 | I18: =PRICE_TOM -> 8800 | J18: =PRICE_TOM -> 8800 | K18: =A18*PRICE_TOM-G18 -> 20335.741 | L18: =IF(H18>=PRICE_TOM,A18,"") -> 13 | M18: =IF(H18<H17,"DIP","")
... A25: 20 | B25: =IF(A25=0,0,A25*LABOR_HRS_WK_TOM*SEASON_WEEKS*(1+DIM_PCT_TOM)^A25) -> 12109.5 | C25: =MIN(B25,FARMER_HRS) -> 720 | D25: =MAX(0,B25-FARMER_HRS) -> 11389.5 | E25: =C25*FARMER_RATE+D25*TEMP_WORKER_RATE -> 222734.37 | F25: =A25*FERT_BED_TOM -> 17600 | G25: =F25+E25 -> 240334.37 | H25: =G25-G24 -> 29548.324 | I25: =PRICE_TOM -> 8800 | J25: =PRICE_TOM -> 8800 | K25: =A25*PRICE_TOM-G25 -> -64334.373 | L25: =IF(H25>=PRICE_TOM,A25,"") -> 20 | M25: =IF(H25<H24,"DIP","")
A27: XING(TOM) | B27: =INDEX(A5:A25,MATCH(MAX(K5:K25),K5:K25,0)) -> 10
A28: XING_FIRST(TOM) | B28: =IF(COUNT(L5:L25)=0,"none below cap",MIN(L5:L25)) -> 11
A29: dip in TOM schedule? | B29: =IF(COUNTIF(M5:M25,"DIP")>0,"yes - non-monotonic","no") -> yes - non-monotonic
A34: CARROTS
A35: q | B35: LABOR_HRS | C35: FARMER_HRS_USED | D35: TEMP_HRS_USED | E35: LABOR_COST_SA | F35: FERT_COST | G35: TVC | H35: MARG_COST | I35: PRICE | J35: MARG_REVENUE | K35: SA_PROFIT | L35: q if MC>=PRICE | M35: DIP
A36: 0 | B36: =IF(A36=0,0,A36*LABOR_HRS_WK_CAR*SEASON_WEEKS*(1+DIM_PCT_CAR)^A36) -> 0 | C36: =MIN(B36,FARMER_HRS) -> 0 | D36: =MAX(0,B36-FARMER_HRS) -> 0 | E36: =C36*FARMER_RATE+D36*TEMP_WORKER_RATE -> 0 | F36: =A36*FERT_BED_CAR -> 0 | G36: =F36+E36 -> 0 | I36: =PRICE_CAR -> 2094 | J36: =PRICE_CAR -> 2094 | K36: =A36*PRICE_CAR-G36 -> 0
A37: 1 | B37: =IF(A37=0,0,A37*LABOR_HRS_WK_CAR*SEASON_WEEKS*(1+DIM_PCT_CAR)^A37) -> 30.75 | C37: =MIN(B37,FARMER_HRS) -> 30.75 | D37: =MAX(0,B37-FARMER_HRS) -> 0 | E37: =C37*FARMER_RATE+D37*TEMP_WORKER_RATE -> 1067.7083 | F37: =A37*FERT_BED_CAR -> 440 | G37: =F37+E37 -> 1507.7083 | H37: =G37-G36 -> 1507.7083 | I37: =PRICE_CAR -> 2094 | J37: =PRICE_CAR -> 2094 | K37: =A37*PRICE_CAR-G37 -> 586.29167 | L37: =IF(H37>=PRICE_CAR,A37,"")
A38: 2 | B38: =IF(A38=0,0,A38*LABOR_HRS_WK_CAR*SEASON_WEEKS*(1+DIM_PCT_CAR)^A38) -> 63.0375 | C38: =MIN(B38,FARMER_HRS) -> 63.0375 | D38: =MAX(0,B38-FARMER_HRS) -> 0 | E38: =C38*FARMER_RATE+D38*TEMP_WORKER_RATE -> 2188.8021 | F38: =A38*FERT_BED_CAR -> 880 | G38: =F38+E38 -> 3068.8021 | H38: =G38-G37 -> 1561.0937 | I38: =PRICE_CAR -> 2094 | J38: =PRICE_CAR -> 2094 | K38: =A38*PRICE_CAR-G38 -> 1119.1979 | L38: =IF(H38>=PRICE_CAR,A38,"") | M38: =IF(H38<H37,"DIP","")
A39: 3 | B39: =IF(A39=0,0,A39*LABOR_HRS_WK_CAR*SEASON_WEEKS*(1+DIM_PCT_CAR)^A39) -> 96.920156 | C39: =MIN(B39,FARMER_HRS) -> 96.920156 | D39: =MAX(0,B39-FARMER_HRS) -> 0 | E39: =C39*FARMER_RATE+D39*TEMP_WORKER_RATE -> 3365.2832 | F39: =A39*FERT_BED_CAR -> 1320 | G39: =F39+E39 -> 4685.2832 | H39: =G39-G38 -> 1616.4811 | I39: =PRICE_CAR -> 2094 | J39: =PRICE_CAR -> 2094 | K39: =A39*PRICE_CAR-G39 -> 1596.7168 | L39: =IF(H39>=PRICE_CAR,A39,"") | M39: =IF(H39<H38,"DIP","")
A40: 4 | B40: =IF(A40=0,0,A40*LABOR_HRS_WK_CAR*SEASON_WEEKS*(1+DIM_PCT_CAR)^A40) -> 132.45755 | C40: =MIN(B40,FARMER_HRS) -> 132.45755 | D40: =MAX(0,B40-FARMER_HRS) -> 0 | E40: =C40*FARMER_RATE+D40*TEMP_WORKER_RATE -> 4599.2204 | F40: =A40*FERT_BED_CAR -> 1760 | G40: =F40+E40 -> 6359.2204 | H40: =G40-G39 -> 1673.9372 | I40: =PRICE_CAR -> 2094 | J40: =PRICE_CAR -> 2094 | K40: =A40*PRICE_CAR-G40 -> 2016.7796 | L40: =IF(H40>=PRICE_CAR,A40,"") | M40: =IF(H40<H39,"DIP","")
A41: 5 | B41: =IF(A41=0,0,A41*LABOR_HRS_WK_CAR*SEASON_WEEKS*(1+DIM_PCT_CAR)^A41) -> 169.71123 | C41: =MIN(B41,FARMER_HRS) -> 169.71123 | D41: =MAX(0,B41-FARMER_HRS) -> 0 | E41: =C41*FARMER_RATE+D41*TEMP_WORKER_RATE -> 5892.7511 | F41: =A41*FERT_BED_CAR -> 2200 | G41: =F41+E41 -> 8092.7511 | H41: =G41-G40 -> 1733.5307 | I41: =PRICE_CAR -> 2094 | J41: =PRICE_CAR -> 2094 | K41: =A41*PRICE_CAR-G41 -> 2377.2489 | L41: =IF(H41>=PRICE_CAR,A41,"") | M41: =IF(H41<H40,"DIP","")
A42: 6 | B42: =IF(A42=0,0,A42*LABOR_HRS_WK_CAR*SEASON_WEEKS*(1+DIM_PCT_CAR)^A42) -> 208.74482 | C42: =MIN(B42,FARMER_HRS) -> 208.74482 | D42: =MAX(0,B42-FARMER_HRS) -> 0 | E42: =C42*FARMER_RATE+D42*TEMP_WORKER_RATE -> 7248.0839 | F42: =A42*FERT_BED_CAR -> 2640 | G42: =F42+E42 -> 9888.0839 | H42: =G42-G41 -> 1795.3328 | I42: =PRICE_CAR -> 2094 | J42: =PRICE_CAR -> 2094 | K42: =A42*PRICE_CAR-G42 -> 2675.9161 | L42: =IF(H42>=PRICE_CAR,A42,"") | M42: =IF(H42<H41,"DIP","")
A43: 7 | B43: =IF(A43=0,0,A43*LABOR_HRS_WK_CAR*SEASON_WEEKS*(1+DIM_PCT_CAR)^A43) -> 249.62401 | C43: =MIN(B43,FARMER_HRS) -> 249.62401 | D43: =MAX(0,B43-FARMER_HRS) -> 0 | E43: =C43*FARMER_RATE+D43*TEMP_WORKER_RATE -> 8667.5003 | F43: =A43*FERT_BED_CAR -> 3080 | G43: =F43+E43 -> 11747.5 | H43: =G43-G42 -> 1859.4164 | I43: =PRICE_CAR -> 2094 | J43: =PRICE_CAR -> 2094 | K43: =A43*PRICE_CAR-G43 -> 2910.4997 | L43: =IF(H43>=PRICE_CAR,A43,"") | M43: =IF(H43<H42,"DIP","")
A44: 8 | B44: =IF(A44=0,0,A44*LABOR_HRS_WK_CAR*SEASON_WEEKS*(1+DIM_PCT_CAR)^A44) -> 292.4167 | C44: =MIN(B44,FARMER_HRS) -> 292.4167 | D44: =MAX(0,B44-FARMER_HRS) -> 0 | E44: =C44*FARMER_RATE+D44*TEMP_WORKER_RATE -> 10153.357 | F44: =A44*FERT_BED_CAR -> 3520 | G44: =F44+E44 -> 13673.357 | H44: =G44-G43 -> 1925.8572 | I44: =PRICE_CAR -> 2094 | J44: =PRICE_CAR -> 2094 | K44: =A44*PRICE_CAR-G44 -> 3078.6425 | L44: =IF(H44>=PRICE_CAR,A44,"") | M44: =IF(H44<H43,"DIP","")
A45: 9 | B45: =IF(A45=0,0,A45*LABOR_HRS_WK_CAR*SEASON_WEEKS*(1+DIM_PCT_CAR)^A45) -> 337.193 | C45: =MIN(B45,FARMER_HRS) -> 337.193 | D45: =MAX(0,B45-FARMER_HRS) -> 0 | E45: =C45*FARMER_RATE+D45*TEMP_WORKER_RATE -> 11708.09 | F45: =A45*FERT_BED_CAR -> 3960 | G45: =F45+E45 -> 15668.09 | H45: =G45-G44 -> 1994.7329 | I45: =PRICE_CAR -> 2094 | J45: =PRICE_CAR -> 2094 | K45: =A45*PRICE_CAR-G45 -> 3177.9097 | L45: =IF(H45>=PRICE_CAR,A45,"") | M45: =IF(H45<H44,"DIP","")
A46: 10 | B46: =IF(A46=0,0,A46*LABOR_HRS_WK_CAR*SEASON_WEEKS*(1+DIM_PCT_CAR)^A46) -> 384.02536 | C46: =MIN(B46,FARMER_HRS) -> 384.02536 | D46: =MAX(0,B46-FARMER_HRS) -> 0 | E46: =C46*FARMER_RATE+D46*TEMP_WORKER_RATE -> 13334.214 | F46: =A46*FERT_BED_CAR -> 4400 | G46: =F46+E46 -> 17734.214 | H46: =G46-G45 -> 2066.1237 | I46: =PRICE_CAR -> 2094 | J46: =PRICE_CAR -> 2094 | K46: =A46*PRICE_CAR-G46 -> 3205.786 | L46: =IF(H46>=PRICE_CAR,A46,"") | M46: =IF(H46<H45,"DIP","")
A47: 11 | B47: =IF(A47=0,0,A47*LABOR_HRS_WK_CAR*SEASON_WEEKS*(1+DIM_PCT_CAR)^A47) -> 432.9886 | C47: =MIN(B47,FARMER_HRS) -> 432.9886 | D47: =MAX(0,B47-FARMER_HRS) -> 0 | E47: =C47*FARMER_RATE+D47*TEMP_WORKER_RATE -> 15034.326 | F47: =A47*FERT_BED_CAR -> 4840 | G47: =F47+E47 -> 19874.326 | H47: =G47-G46 -> 2140.1123 | I47: =PRICE_CAR -> 2094 | J47: =PRICE_CAR -> 2094 | K47: =A47*PRICE_CAR-G47 -> 3159.6737 | L47: =IF(H47>=PRICE_CAR,A47,"") -> 11 | M47: =IF(H47<H46,"DIP","")
A48: 12 | B48: =IF(A48=0,0,A48*LABOR_HRS_WK_CAR*SEASON_WEEKS*(1+DIM_PCT_CAR)^A48) -> 484.15998 | C48: =MIN(B48,FARMER_HRS) -> 484.15998 | D48: =MAX(0,B48-FARMER_HRS) -> 0 | E48: =C48*FARMER_RATE+D48*TEMP_WORKER_RATE -> 16811.11 | F48: =A48*FERT_BED_CAR -> 5280 | G48: =F48+E48 -> 22091.11 | H48: =G48-G47 -> 2216.784 | I48: =PRICE_CAR -> 2094 | J48: =PRICE_CAR -> 2094 | K48: =A48*PRICE_CAR-G48 -> 3036.8897 | L48: =IF(H48>=PRICE_CAR,A48,"") -> 12 | M48: =IF(H48<H47,"DIP","")
A49: 13 | B49: =IF(A49=0,0,A49*LABOR_HRS_WK_CAR*SEASON_WEEKS*(1+DIM_PCT_CAR)^A49) -> 537.61931 | C49: =MIN(B49,FARMER_HRS) -> 537.61931 | D49: =MAX(0,B49-FARMER_HRS) -> 0 | E49: =C49*FARMER_RATE+D49*TEMP_WORKER_RATE -> 18667.337 | F49: =A49*FERT_BED_CAR -> 5720 | G49: =F49+E49 -> 24387.337 | H49: =G49-G48 -> 2296.2268 | I49: =PRICE_CAR -> 2094 | J49: =PRICE_CAR -> 2094 | K49: =A49*PRICE_CAR-G49 -> 2834.6629 | L49: =IF(H49>=PRICE_CAR,A49,"") -> 13 | M49: =IF(H49<H48,"DIP","")
... A56: 20 | B56: =IF(A56=0,0,A56*LABOR_HRS_WK_CAR*SEASON_WEEKS*(1+DIM_PCT_CAR)^A56) -> 983.16986 | C56: =MIN(B56,FARMER_HRS) -> 720 | D56: =MAX(0,B56-FARMER_HRS) -> 263.16986 | E56: =C56*FARMER_RATE+D56*TEMP_WORKER_RATE -> 29568.921 | F56: =A56*FERT_BED_CAR -> 8800 | G56: =F56+E56 -> 38368.921 | H56: =G56-G55 -> 1688.9455 | I56: =PRICE_CAR -> 2094 | J56: =PRICE_CAR -> 2094 | K56: =A56*PRICE_CAR-G56 -> 3511.0787 | L56: =IF(H56>=PRICE_CAR,A56,"") | M56: =IF(H56<H55,"DIP","")
A58: XING(CAR) | B58: =INDEX(A36:A56,MATCH(MAX(K36:K56),K36:K56,0)) -> 20
A59: XING_FIRST(CAR) | B59: =IF(COUNT(L36:L56)=0,"none below cap",MIN(L36:L56)) -> 11
...

Sheet CostStructure
A1: Cost structure at the current allocation (q(TOM), q(CAR), q(MES) on the Optimization sheet).
A3: LABOR_HRS(TOM, q(TOM)) | B3: =IF(Q_TOM=0,0,Q_TOM*LABOR_HRS_WK_TOM*SEASON_WEEKS*(1+DIM_PCT_TOM)^Q_TOM) -> 2334.3682
A4: LABOR_HRS(CAR, q(CAR)) | B4: =IF(Q_CAR=0,0,Q_CAR*LABOR_HRS_WK_CAR*SEASON_WEEKS*(1+DIM_PCT_CAR)^Q_CAR) -> 983.16986
A5: LABOR_HRS(MES, q(MES)) | B5: =IF(Q_MES=0,0,Q_MES*LABOR_HRS_WK_MES*SEASON_WEEKS*(1+DIM_PCT_MES)^Q_MES) -> 1959.678
A6: TOTAL_LABOR_HRS | B6: =B3+B4+B5 -> 5277.2161
A7: FARMER_HRS_USED | B7: =MIN(TOTAL_LABOR_HRS,FARMER_HRS) -> 720
A8: TEMP_LABOR_HRS | B8: =MAX(0,TOTAL_LABOR_HRS-FARMER_HRS) -> 4557.2161
A9: TOTAL_LABOR_COST | B9: =FARMER_HRS_USED*FARMER_RATE+TEMP_LABOR_HRS*TEMP_WORKER_RATE -> 104118.34
A10: BLENDED_RATE | B10: =IF(TOTAL_LABOR_HRS=0,0,TOTAL_LABOR_COST/TOTAL_LABOR_HRS) -> 19.729784
A11: ALLOC_LABOR_COST(TOM) | B11: =B3*BLENDED_RATE -> 46056.581
A12: ALLOC_LABOR_COST(CAR) | B12: =B4*BLENDED_RATE -> 19397.729
A13: ALLOC_LABOR_COST(MES) | B13: =B5*BLENDED_RATE -> 38664.025
A14: TOTAL_FERT_COST | B14: =Q_TOM*FERT_BED_TOM+Q_CAR*FERT_BED_CAR+Q_MES*FERT_BED_MES -> 44000
A15: TOTAL_REVENUE | B15: =Q_TOM*PRICE_TOM+Q_CAR*PRICE_CAR+Q_MES*PRICE_MES -> 210880
A16: MARGIN(TOM) | B16: =Q_TOM*PRICE_TOM-Q_TOM*FERT_BED_TOM-B11 -> 33143.419
A17: MARGIN(CAR) | B17: =Q_CAR*PRICE_CAR-Q_CAR*FERT_BED_CAR-B12 -> 13682.271
A18: MARGIN(MES) | B18: =Q_MES*PRICE_MES-Q_MES*FERT_BED_MES-B13 -> 15935.975
A19: FIXED_COSTS | B19: =FIXED_COSTS -> 20000
A20: TOTAL_COST | B20: =TOTAL_FERT_COST+TOTAL_LABOR_COST+FIXED_COSTS -> 168118.34
A21: PROFIT | B21: =TOTAL_REVENUE-TOTAL_FERT_COST-TOTAL_LABOR_COST-FIXED_COSTS -> 42761.665
A22: implied temp-worker count (TEMP_LABOR_HRS / TEMP_WORKER_HRS) | B22: =TEMP_LABOR_HRS/TEMP_WORKER_HRS -> 3.1647334
A24: tie-out SUM(ALLOC_LABOR_COST) - TOTAL_LABOR_COST | B24: =B11+B12+B13-TOTAL_LABOR_COST -> 0
A25: tie-out SUM(MARGIN) - (PROFIT + FIXED_COSTS) | B25: =B16+B17+B18-(PROFIT+FIXED_COSTS) -> 0

Sheet Enumeration
A1: Every integer (q(TOM),q(CAR),q(MES)) with 0<=q(c)<=MAX_BEDS(c): 21 x 21 x 31 = 13,671 combos. Columns A-C are region grid indices. "feasible" applies the 64-bed total and the temp-hour ceiling; per-crop caps are enforced by the enumerated ranges. | R1: MAXPROFIT | S1: =MAX(P4:P13674) -> 42761.665
R2: opt q(TOM) | S2: =INDEX(A4:A13674,MATCH(S1,P4:P13674,0)) -> 10
A3: q(TOM) | B3: q(CAR) | C3: q(MES) | D3: beds | E3: hrs(TOM) | F3: hrs(CAR) | G3: hrs(MES) | H3: total hrs | I3: farmer hrs | J3: temp hrs | K3: labor cost | L3: revenue | M3: fert cost | N3: feasible | O3: profit | P3: feasible profit | R3: opt q(CAR) | S3: =INDEX(B4:B13674,MATCH(S1,P4:P13674,0)) -> 20
A4: 0 | B4: 0 | C4: 0 | D4: =A4+B4+C4 -> 0 | E4: =IF(A4=0,0,A4*LABOR_HRS_WK_TOM*SEASON_WEEKS*(1+DIM_PCT_TOM)^A4) -> 0 | F4: =IF(B4=0,0,B4*LABOR_HRS_WK_CAR*SEASON_WEEKS*(1+DIM_PCT_CAR)^B4) -> 0 | G4: =IF(C4=0,0,C4*LABOR_HRS_WK_MES*SEASON_WEEKS*(1+DIM_PCT_MES)^C4) -> 0 | H4: =E4+F4+G4 -> 0 | I4: =MIN(H4,FARMER_HRS) -> 0 | J4: =MAX(0,H4-FARMER_HRS) -> 0 | K4: =I4*FARMER_RATE+J4*TEMP_WORKER_RATE -> 0 | L4: =A4*PRICE_TOM+B4*PRICE_CAR+C4*PRICE_MES -> 0 | M4: =A4*FERT_BED_TOM+B4*FERT_BED_CAR+C4*FERT_BED_MES -> 0 | N4: =IF(AND(D4<=TOTAL_BEDS,J4<=TEMP_WORKER_MAX*TEMP_WORKER_HRS),1,0) -> 1 | O4: =L4-M4-K4-FIXED_COSTS -> -20000 | P4: =IF(N4=1,O4,"") -> -20000 | R4: opt q(MES) | S4: =INDEX(C4:C13674,MATCH(S1,P4:P13674,0)) -> 30
A5: 0 | B5: 0 | C5: 1 | D5: =A5+B5+C5 -> 1 | E5: =IF(A5=0,0,A5*LABOR_HRS_WK_TOM*SEASON_WEEKS*(1+DIM_PCT_TOM)^A5) -> 0 | F5: =IF(B5=0,0,B5*LABOR_HRS_WK_CAR*SEASON_WEEKS*(1+DIM_PCT_CAR)^B5) -> 0 | G5: =IF(C5=0,0,C5*LABOR_HRS_WK_MES*SEASON_WEEKS*(1+DIM_PCT_MES)^C5) -> 45.5625 | H5: =E5+F5+G5 -> 45.5625 | I5: =MIN(H5,FARMER_HRS) -> 45.5625 | J5: =MAX(0,H5-FARMER_HRS) -> 0 | K5: =I5*FARMER_RATE+J5*TEMP_WORKER_RATE -> 1582.0312 | L5: =A5*PRICE_TOM+B5*PRICE_CAR+C5*PRICE_MES -> 2700 | M5: =A5*FERT_BED_TOM+B5*FERT_BED_CAR+C5*FERT_BED_MES -> 880 | N5: =IF(AND(D5<=TOTAL_BEDS,J5<=TEMP_WORKER_MAX*TEMP_WORKER_HRS),1,0) -> 1 | O5: =L5-M5-K5-FIXED_COSTS -> -19762.031 | P5: =IF(N5=1,O5,"") -> -19762.031 | R5: feasible combos | S5: =SUM(N4:N13674) -> 9726
A6: 0 | B6: 0 | C6: 2 | D6: =A6+B6+C6 -> 2 | E6: =IF(A6=0,0,A6*LABOR_HRS_WK_TOM*SEASON_WEEKS*(1+DIM_PCT_TOM)^A6) -> 0 | F6: =IF(B6=0,0,B6*LABOR_HRS_WK_CAR*SEASON_WEEKS*(1+DIM_PCT_CAR)^B6) -> 0 | G6: =IF(C6=0,0,C6*LABOR_HRS_WK_MES*SEASON_WEEKS*(1+DIM_PCT_MES)^C6) -> 92.264062 | H6: =E6+F6+G6 -> 92.264062 | I6: =MIN(H6,FARMER_HRS) -> 92.264062 | J6: =MAX(0,H6-FARMER_HRS) -> 0 | K6: =I6*FARMER_RATE+J6*TEMP_WORKER_RATE -> 3203.6133 | L6: =A6*PRICE_TOM+B6*PRICE_CAR+C6*PRICE_MES -> 5400 | M6: =A6*FERT_BED_TOM+B6*FERT_BED_CAR+C6*FERT_BED_MES -> 1760 | N6: =IF(AND(D6<=TOTAL_BEDS,J6<=TEMP_WORKER_MAX*TEMP_WORKER_HRS),1,0) -> 1 | O6: =L6-M6-K6-FIXED_COSTS -> -19563.613 | P6: =IF(N6=1,O6,"") -> -19563.613 | R6: combos enumerated | S6: =COUNT(O4:O13674) -> 13671
A7: 0 | B7: 0 | C7: 3 | D7: =A7+B7+C7 -> 3 | E7: =IF(A7=0,0,A7*LABOR_HRS_WK_TOM*SEASON_WEEKS*(1+DIM_PCT_TOM)^A7) -> 0 | F7: =IF(B7=0,0,B7*LABOR_HRS_WK_CAR*SEASON_WEEKS*(1+DIM_PCT_CAR)^B7) -> 0 | G7: =IF(C7=0,0,C7*LABOR_HRS_WK_MES*SEASON_WEEKS*(1+DIM_PCT_MES)^C7) -> 140.12604 | H7: =E7+F7+G7 -> 140.12604 | I7: =MIN(H7,FARMER_HRS) -> 140.12604 | J7: =MAX(0,H7-FARMER_HRS) -> 0 | K7: =I7*FARMER_RATE+J7*TEMP_WORKER_RATE -> 4865.4877 | L7: =A7*PRICE_TOM+B7*PRICE_CAR+C7*PRICE_MES -> 8100 | M7: =A7*FERT_BED_TOM+B7*FERT_BED_CAR+C7*FERT_BED_MES -> 2640 | N7: =IF(AND(D7<=TOTAL_BEDS,J7<=TEMP_WORKER_MAX*TEMP_WORKER_HRS),1,0) -> 1 | O7: =L7-M7-K7-FIXED_COSTS -> -19405.488 | P7: =IF(N7=1,O7,"") -> -19405.488 | R7: beds used at opt | S7: =S2+S3+S4 -> 60
A8: 0 | B8: 0 | C8: 4 | D8: =A8+B8+C8 -> 4 | E8: =IF(A8=0,0,A8*LABOR_HRS_WK_TOM*SEASON_WEEKS*(1+DIM_PCT_TOM)^A8) -> 0 | F8: =IF(B8=0,0,B8*LABOR_HRS_WK_CAR*SEASON_WEEKS*(1+DIM_PCT_CAR)^B8) -> 0 | G8: =IF(C8=0,0,C8*LABOR_HRS_WK_MES*SEASON_WEEKS*(1+DIM_PCT_MES)^C8) -> 189.17016 | H8: =E8+F8+G8 -> 189.17016 | I8: =MIN(H8,FARMER_HRS) -> 189.17016 | J8: =MAX(0,H8-FARMER_HRS) -> 0 | K8: =I8*FARMER_RATE+J8*TEMP_WORKER_RATE -> 6568.4084 | L8: =A8*PRICE_TOM+B8*PRICE_CAR+C8*PRICE_MES -> 10800 | M8: =A8*FERT_BED_TOM+B8*FERT_BED_CAR+C8*FERT_BED_MES -> 3520 | N8: =IF(AND(D8<=TOTAL_BEDS,J8<=TEMP_WORKER_MAX*TEMP_WORKER_HRS),1,0) -> 1 | O8: =L8-M8-K8-FIXED_COSTS -> -19288.408 | P8: =IF(N8=1,O8,"") -> -19288.408
A9: 0 | B9: 0 | C9: 5 | D9: =A9+B9+C9 -> 5 | E9: =IF(A9=0,0,A9*LABOR_HRS_WK_TOM*SEASON_WEEKS*(1+DIM_PCT_TOM)^A9) -> 0 | F9: =IF(B9=0,0,B9*LABOR_HRS_WK_CAR*SEASON_WEEKS*(1+DIM_PCT_CAR)^B9) -> 0 | G9: =IF(C9=0,0,C9*LABOR_HRS_WK_MES*SEASON_WEEKS*(1+DIM_PCT_MES)^C9) -> 239.41848 | H9: =E9+F9+G9 -> 239.41848 | I9: =MIN(H9,FARMER_HRS) -> 239.41848 | J9: =MAX(0,H9-FARMER_HRS) -> 0 | K9: =I9*FARMER_RATE+J9*TEMP_WORKER_RATE -> 8313.1418 | L9: =A9*PRICE_TOM+B9*PRICE_CAR+C9*PRICE_MES -> 13500 | M9: =A9*FERT_BED_TOM+B9*FERT_BED_CAR+C9*FERT_BED_MES -> 4400 | N9: =IF(AND(D9<=TOTAL_BEDS,J9<=TEMP_WORKER_MAX*TEMP_WORKER_HRS),1,0) -> 1 | O9: =L9-M9-K9-FIXED_COSTS -> -19213.142 | P9: =IF(N9=1,O9,"") -> -19213.142
A10: 0 | B10: 0 | C10: 6 | D10: =A10+B10+C10 -> 6 | E10: =IF(A10=0,0,A10*LABOR_HRS_WK_TOM*SEASON_WEEKS*(1+DIM_PCT_TOM)^A10) -> 0 | F10: =IF(B10=0,0,B10*LABOR_HRS_WK_CAR*SEASON_WEEKS*(1+DIM_PCT_CAR)^B10) -> 0 | G10: =IF(C10=0,0,C10*LABOR_HRS_WK_MES*SEASON_WEEKS*(1+DIM_PCT_MES)^C10) -> 290.89346 | H10: =E10+F10+G10 -> 290.89346 | I10: =MIN(H10,FARMER_HRS) -> 290.89346 | J10: =MAX(0,H10-FARMER_HRS) -> 0 | K10: =I10*FARMER_RATE+J10*TEMP_WORKER_RATE -> 10100.467 | L10: =A10*PRICE_TOM+B10*PRICE_CAR+C10*PRICE_MES -> 16200 | M10: =A10*FERT_BED_TOM+B10*FERT_BED_CAR+C10*FERT_BED_MES -> 5280 | N10: =IF(AND(D10<=TOTAL_BEDS,J10<=TEMP_WORKER_MAX*TEMP_WORKER_HRS),1,0) -> 1 | O10: =L10-M10-K10-FIXED_COSTS -> -19180.467 | P10: =IF(N10=1,O10,"") -> -19180.467
A11: 0 | B11: 0 | C11: 7 | D11: =A11+B11+C11 -> 7 | E11: =IF(A11=0,0,A11*LABOR_HRS_WK_TOM*SEASON_WEEKS*(1+DIM_PCT_TOM)^A11) -> 0 | F11: =IF(B11=0,0,B11*LABOR_HRS_WK_CAR*SEASON_WEEKS*(1+DIM_PCT_CAR)^B11) -> 0 | G11: =IF(C11=0,0,C11*LABOR_HRS_WK_MES*SEASON_WEEKS*(1+DIM_PCT_MES)^C11) -> 343.6179 | H11: =E11+F11+G11 -> 343.6179 | I11: =MIN(H11,FARMER_HRS) -> 343.6179 | J11: =MAX(0,H11-FARMER_HRS) -> 0 | K11: =I11*FARMER_RATE+J11*TEMP_WORKER_RATE -> 11931.177 | L11: =A11*PRICE_TOM+B11*PRICE_CAR+C11*PRICE_MES -> 18900 | M11: =A11*FERT_BED_TOM+B11*FERT_BED_CAR+C11*FERT_BED_MES -> 6160 | N11: =IF(AND(D11<=TOTAL_BEDS,J11<=TEMP_WORKER_MAX*TEMP_WORKER_HRS),1,0) -> 1 | O11: =L11-M11-K11-FIXED_COSTS -> -19191.177 | P11: =IF(N11=1,O11,"") -> -19191.177
A12: 0 | B12: 0 | C12: 8 | D12: =A12+B12+C12 -> 8 | E12: =IF(A12=0,0,A12*LABOR_HRS_WK_TOM*SEASON_WEEKS*(1+DIM_PCT_TOM)^A12) -> 0 | F12: =IF(B12=0,0,B12*LABOR_HRS_WK_CAR*SEASON_WEEKS*(1+DIM_PCT_CAR)^B12) -> 0 | G12: =IF(C12=0,0,C12*LABOR_HRS_WK_MES*SEASON_WEEKS*(1+DIM_PCT_MES)^C12) -> 397.615 | H12: =E12+F12+G12 -> 397.615 | I12: =MIN(H12,FARMER_HRS) -> 397.615 | J12: =MAX(0,H12-FARMER_HRS) -> 0 | K12: =I12*FARMER_RATE+J12*TEMP_WORKER_RATE -> 13806.076 | L12: =A12*PRICE_TOM+B12*PRICE_CAR+C12*PRICE_MES -> 21600 | M12: =A12*FERT_BED_TOM+B12*FERT_BED_CAR+C12*FERT_BED_MES -> 7040 | N12: =IF(AND(D12<=TOTAL_BEDS,J12<=TEMP_WORKER_MAX*TEMP_WORKER_HRS),1,0) -> 1 | O12: =L12-M12-K12-FIXED_COSTS -> -19246.076 | P12: =IF(N12=1,O12,"") -> -19246.076
A13: 0 | B13: 0 | C13: 9 | D13: =A13+B13+C13 -> 9 | E13: =IF(A13=0,0,A13*LABOR_HRS_WK_TOM*SEASON_WEEKS*(1+DIM_PCT_TOM)^A13) -> 0 | F13: =IF(B13=0,0,B13*LABOR_HRS_WK_CAR*SEASON_WEEKS*(1+DIM_PCT_CAR)^B13) -> 0 | G13: =IF(C13=0,0,C13*LABOR_HRS_WK_MES*SEASON_WEEKS*(1+DIM_PCT_MES)^C13) -> 452.90833 | H13: =E13+F13+G13 -> 452.90833 | I13: =MIN(H13,FARMER_HRS) -> 452.90833 | J13: =MAX(0,H13-FARMER_HRS) -> 0 | K13: =I13*FARMER_RATE+J13*TEMP_WORKER_RATE -> 15725.984 | L13: =A13*PRICE_TOM+B13*PRICE_CAR+C13*PRICE_MES -> 24300 | M13: =A13*FERT_BED_TOM+B13*FERT_BED_CAR+C13*FERT_BED_MES -> 7920 | N13: =IF(AND(D13<=TOTAL_BEDS,J13<=TEMP_WORKER_MAX*TEMP_WORKER_HRS),1,0) -> 1 | O13: =L13-M13-K13-FIXED_COSTS -> -19345.984 | P13: =IF(N13=1,O13,"") -> -19345.984
A14: 0 | B14: 0 | C14: 10 | D14: =A14+B14+C14 -> 10 | E14: =IF(A14=0,0,A14*LABOR_HRS_WK_TOM*SEASON_WEEKS*(1+DIM_PCT_TOM)^A14) -> 0 | F14: =IF(B14=0,0,B14*LABOR_HRS_WK_CAR*SEASON_WEEKS*(1+DIM_PCT_CAR)^B14) -> 0 | G14: =IF(C14=0,0,C14*LABOR_HRS_WK_MES*SEASON_WEEKS*(1+DIM_PCT_MES)^C14) -> 509.52187 | H14: =E14+F14+G14 -> 509.52187 | I14: =MIN(H14,FARMER_HRS) -> 509.52187 | J14: =MAX(0,H14-FARMER_HRS) -> 0 | K14: =I14*FARMER_RATE+J14*TEMP_WORKER_RATE -> 17691.732 | L14: =A14*PRICE_TOM+B14*PRICE_CAR+C14*PRICE_MES -> 27000 | M14: =A14*FERT_BED_TOM+B14*FERT_BED_CAR+C14*FERT_BED_MES -> 8800 | N14: =IF(AND(D14<=TOTAL_BEDS,J14<=TEMP_WORKER_MAX*TEMP_WORKER_HRS),1,0) -> 1 | O14: =L14-M14-K14-FIXED_COSTS -> -19491.732 | P14: =IF(N14=1,O14,"") -> -19491.732
A15: 0 | B15: 0 | C15: 11 | D15: =A15+B15+C15 -> 11 | E15: =IF(A15=0,0,A15*LABOR_HRS_WK_TOM*SEASON_WEEKS*(1+DIM_PCT_TOM)^A15) -> 0 | F15: =IF(B15=0,0,B15*LABOR_HRS_WK_CAR*SEASON_WEEKS*(1+DIM_PCT_CAR)^B15) -> 0 | G15: =IF(C15=0,0,C15*LABOR_HRS_WK_MES*SEASON_WEEKS*(1+DIM_PCT_MES)^C15) -> 567.47999 | H15: =E15+F15+G15 -> 567.47999 | I15: =MIN(H15,FARMER_HRS) -> 567.47999 | J15: =MAX(0,H15-FARMER_HRS) -> 0 | K15: =I15*FARMER_RATE+J15*TEMP_WORKER_RATE -> 19704.166 | L15: =A15*PRICE_TOM+B15*PRICE_CAR+C15*PRICE_MES -> 29700 | M15: =A15*FERT_BED_TOM+B15*FERT_BED_CAR+C15*FERT_BED_MES -> 9680 | N15: =IF(AND(D15<=TOTAL_BEDS,J15<=TEMP_WORKER_MAX*TEMP_WORKER_HRS),1,0) -> 1 | O15: =L15-M15-K15-FIXED_COSTS -> -19684.166 | P15: =IF(N15=1,O15,"") -> -19684.166
A16: 0 | B16: 0 | C16: 12 | D16: =A16+B16+C16 -> 12 | E16: =IF(A16=0,0,A16*LABOR_HRS_WK_TOM*SEASON_WEEKS*(1+DIM_PCT_TOM)^A16) -> 0 | F16: =IF(B16=0,0,B16*LABOR_HRS_WK_CAR*SEASON_WEEKS*(1+DIM_PCT_CAR)^B16) -> 0 | G16: =IF(C16=0,0,C16*LABOR_HRS_WK_MES*SEASON_WEEKS*(1+DIM_PCT_MES)^C16) -> 626.80744 | H16: =E16+F16+G16 -> 626.80744 | I16: =MIN(H16,FARMER_HRS) -> 626.80744 | J16: =MAX(0,H16-FARMER_HRS) -> 0 | K16: =I16*FARMER_RATE+J16*TEMP_WORKER_RATE -> 21764.147 | L16: =A16*PRICE_TOM+B16*PRICE_CAR+C16*PRICE_MES -> 32400 | M16: =A16*FERT_BED_TOM+B16*FERT_BED_CAR+C16*FERT_BED_MES -> 10560 | N16: =IF(AND(D16<=TOTAL_BEDS,J16<=TEMP_WORKER_MAX*TEMP_WORKER_HRS),1,0) -> 1 | O16: =L16-M16-K16-FIXED_COSTS -> -19924.147 | P16: =IF(N16=1,O16,"") -> -19924.147
A17: 0 | B17: 0 | C17: 13 | D17: =A17+B17+C17 -> 13 | E17: =IF(A17=0,0,A17*LABOR_HRS_WK_TOM*SEASON_WEEKS*(1+DIM_PCT_TOM)^A17) -> 0 | F17: =IF(B17=0,0,B17*LABOR_HRS_WK_CAR*SEASON_WEEKS*(1+DIM_PCT_CAR)^B17) -> 0 | G17: =IF(C17=0,0,C17*LABOR_HRS_WK_MES*SEASON_WEEKS*(1+DIM_PCT_MES)^C17) -> 687.52941 | H17: =E17+F17+G17 -> 687.52941 | I17: =MIN(H17,FARMER_HRS) -> 687.52941 | J17: =MAX(0,H17-FARMER_HRS) -> 0 | K17: =I17*FARMER_RATE+J17*TEMP_WORKER_RATE -> 23872.549 | L17: =A17*PRICE_TOM+B17*PRICE_CAR+C17*PRICE_MES -> 35100 | M17: =A17*FERT_BED_TOM+B17*FERT_BED_CAR+C17*FERT_BED_MES -> 11440 | N17: =IF(AND(D17<=TOTAL_BEDS,J17<=TEMP_WORKER_MAX*TEMP_WORKER_HRS),1,0) -> 1 | O17: =L17-M17-K17-FIXED_COSTS -> -20212.549 | P17: =IF(N17=1,O17,"") -> -20212.549
A18: 0 | B18: 0 | C18: 14 | D18: =A18+B18+C18 -> 14 | E18: =IF(A18=0,0,A18*LABOR_HRS_WK_TOM*SEASON_WEEKS*(1+DIM_PCT_TOM)^A18) -> 0 | F18: =IF(B18=0,0,B18*LABOR_HRS_WK_CAR*SEASON_WEEKS*(1+DIM_PCT_CAR)^B18) -> 0 | G18: =IF(C18=0,0,C18*LABOR_HRS_WK_MES*SEASON_WEEKS*(1+DIM_PCT_MES)^C18) -> 749.67149 | H18: =E18+F18+G18 -> 749.67149 | I18: =MIN(H18,FARMER_HRS) -> 720 | J18: =MAX(0,H18-FARMER_HRS) -> 29.671492 | K18: =I18*FARMER_RATE+J18*TEMP_WORKER_RATE -> 25515.13 | L18: =A18*PRICE_TOM+B18*PRICE_CAR+C18*PRICE_MES -> 37800 | M18: =A18*FERT_BED_TOM+B18*FERT_BED_CAR+C18*FERT_BED_MES -> 12320 | N18: =IF(AND(D18<=TOTAL_BEDS,J18<=TEMP_WORKER_MAX*TEMP_WORKER_HRS),1,0) -> 1 | O18: =L18-M18-K18-FIXED_COSTS -> -20035.13 | P18: =IF(N18=1,O18,"") -> -20035.13
A19: 0 | B19: 0 | C19: 15 | D19: =A19+B19+C19 -> 15 | E19: =IF(A19=0,0,A19*LABOR_HRS_WK_TOM*SEASON_WEEKS*(1+DIM_PCT_TOM)^A19) -> 0 | F19: =IF(B19=0,0,B19*LABOR_HRS_WK_CAR*SEASON_WEEKS*(1+DIM_PCT_CAR)^B19) -> 0 | G19: =IF(C19=0,0,C19*LABOR_HRS_WK_MES*SEASON_WEEKS*(1+DIM_PCT_MES)^C19) -> 813.2597 | H19: =E19+F19+G19 -> 813.2597 | I19: =MIN(H19,FARMER_HRS) -> 720 | J19: =MAX(0,H19-FARMER_HRS) -> 93.259698 | K19: =I19*FARMER_RATE+J19*TEMP_WORKER_RATE -> 26619.092 | L19: =A19*PRICE_TOM+B19*PRICE_CAR+C19*PRICE_MES -> 40500 | M19: =A19*FERT_BED_TOM+B19*FERT_BED_CAR+C19*FERT_BED_MES -> 13200 | N19: =IF(AND(D19<=TOTAL_BEDS,J19<=TEMP_WORKER_MAX*TEMP_WORKER_HRS),1,0) -> 1 | O19: =L19-M19-K19-FIXED_COSTS -> -19319.092 | P19: =IF(N19=1,O19,"") -> -19319.092
... A13674: 20 | B13674: 20 | C13674: 30 | D13674: =A13674+B13674+C13674 -> 70 | E13674: =IF(A13674=0,0,A13674*LABOR_HRS_WK_TOM*SEASON_WEEKS*(1+DIM_PCT_TOM)^A13674) -> 12109.5 | F13674: =IF(B13674=0,0,B13674*LABOR_HRS_WK_CAR*SEASON_WEEKS*(1+DIM_PCT_CAR)^B13674) -> 983.16986 | G13674: =IF(C13674=0,0,C13674*LABOR_HRS_WK_MES*SEASON_WEEKS*(1+DIM_PCT_MES)^C13674) -> 1959.678 | H13674: =E13674+F13674+G13674 -> 15052.348 | I13674: =MIN(H13674,FARMER_HRS) -> 720 | J13674: =MAX(0,H13674-FARMER_HRS) -> 14332.348 | K13674: =I13674*FARMER_RATE+J13674*TEMP_WORKER_RATE -> 273825.48 | L13674: =A13674*PRICE_TOM+B13674*PRICE_CAR+C13674*PRICE_MES -> 298880 | M13674: =A13674*FERT_BED_TOM+B13674*FERT_BED_CAR+C13674*FERT_BED_MES -> 52800 | N13674: =IF(AND(D13674<=TOTAL_BEDS,J13674<=TEMP_WORKER_MAX*TEMP_WORKER_HRS),1,0) -> 0 | O13674: =L13674-M13674-K13674-FIXED_COSTS -> -47745.483 | P13674: =IF(N13674=1,O13674,"")

Sheet Optimization
A1: Optimization (Solver). Decision cells B4:B6 are populated from the Enumeration maximum. Excel Solver was not run in this build environment; run it to confirm - the Enumeration maximum is authoritative if they differ.
A3: Decision variables (integer beds; Solver changing cells)
A4: q(TOM) | B4: 10
A5: q(CAR) | B5: 20
A6: q(MES) | B6: 30
A7: beds used | B7: =Q_TOM+Q_CAR+Q_MES -> 60
A9: Objective
A10: PROFIT (maximize) | B10: =PROFIT -> 42761.665
A12: Constraints (each an explicit Solver constraint)
A13: constraint | B13: LHS | C13: rel | D13: RHS | E13: slack | F13: status | H13: lower bound (beds >= 0) | I13: 0
A14: q(TOM)+q(CAR)+q(MES) <= TOTAL_BEDS | B14: =Q_TOM+Q_CAR+Q_MES -> 60 | C14: <= | D14: =TOTAL_BEDS -> 64 | E14: =D14-B14 -> 4 | F14: =IF(B14<=D14,"ok","VIOLATED") -> ok
A15: q(TOM) <= MAX_BEDS_TOM | B15: =Q_TOM -> 10 | C15: <= | D15: =MAX_BEDS_TOM -> 20 | E15: =D15-B15 -> 10 | F15: =IF(B15<=D15,"ok","VIOLATED") -> ok
A16: q(CAR) <= MAX_BEDS_CAR | B16: =Q_CAR -> 20 | C16: <= | D16: =MAX_BEDS_CAR -> 20 | E16: =D16-B16 -> 0 | F16: =IF(B16<=D16,"ok","VIOLATED") -> ok
A17: q(MES) <= MAX_BEDS_MES | B17: =Q_MES -> 30 | C17: <= | D17: =MAX_BEDS_MES -> 30 | E17: =D17-B17 -> 0 | F17: =IF(B17<=D17,"ok","VIOLATED") -> ok
A18: q(TOM) >= 0 | B18: =Q_TOM -> 10 | C18: >= | D18: =$I$13 -> 0 | E18: =B18-D18 -> 10 | F18: =IF(B18>=D18,"ok","VIOLATED") -> ok
A19: q(CAR) >= 0 | B19: =Q_CAR -> 20 | C19: >= | D19: =$I$13 -> 0 | E19: =B19-D19 -> 20 | F19: =IF(B19>=D19,"ok","VIOLATED") -> ok
A20: q(MES) >= 0 | B20: =Q_MES -> 30 | C20: >= | D20: =$I$13 -> 0 | E20: =B20-D20 -> 30 | F20: =IF(B20>=D20,"ok","VIOLATED") -> ok
A21: TEMP_LABOR_HRS <= TEMP_WORKER_MAX*TEMP_WORKER_HRS | B21: =TEMP_LABOR_HRS -> 4557.2161 | C21: <= | D21: =TEMP_WORKER_MAX*TEMP_WORKER_HRS -> 5760 | E21: =D21-B21 -> 1202.7839 | F21: =IF(B21<=D21,"ok","VIOLATED") -> ok
A22: TOTAL_LABOR_HRS <= LABOR_HRS_CAP | B22: =TOTAL_LABOR_HRS -> 5277.2161 | C22: <= | D22: =LABOR_HRS_CAP -> 6480 | E22: =D22-B22 -> 1202.7839 | F22: =IF(B22<=D22,"ok","VIOLATED") -> ok
A23: q(TOM), q(CAR), q(MES) = integer
A25: Solver engine: GRG Nonlinear. Options: Integer Optimality = 0%.
A26: Start points: (0,0,0) and (20,0,0); confirm both converge to the same allocation.
A27: If they differ, the Enumeration-maximum row (Enumeration sheet, S1:S4) is authoritative.
A29: Binding constraint at this allocation | B29: =IF(Q_TOM+Q_CAR+Q_MES=TOTAL_BEDS,"64-bed total",IF(TEMP_LABOR_HRS=TEMP_WORKER_MAX*TEMP_WORKER_HRS,"temp-hour ceiling",IF(OR(Q_TOM=MAX_BEDS_TOM,Q_CAR=MAX_BEDS_CAR,Q_MES=MAX_BEDS_MES),"MAX_BEDS cap: "&IF(Q_TOM=MAX_BEDS_TOM,"TOM ","")&IF(Q_CAR=MAX_BEDS_CAR,"CAR ","")&IF(Q_MES=MAX_BEDS_MES,"MES ",""),"interior"))) -> MAX_BEDS cap: CAR MES
A30: Solver vs Enumeration | B30: =IF(AND(Q_TOM=ENUM_OPT_QT,Q_CAR=ENUM_OPT_QC,Q_MES=ENUM_OPT_QM),"solved = enumeration max","MISMATCH - see Enumeration") -> solved = enumeration max

Sheet WorkedExample
A1: Worked example - the model recomputed by live formulas at the fixed anchor q=(5,5,5), a non-optimal numeric anchor from the spec. B3:B5 are region grid inputs. Column D holds the spec's published figures (reference, shown to the cent); column E flags the match.
A3: q(TOM) [anchor] | B3: 5
A4: q(CAR) [anchor] | B4: 5
A5: q(MES) [anchor] | B5: 5
A6: figure | B6: model (live) | D6: spec anchor | E6: match?
A7: LABOR_HRS(TOM,5) | B7: =IF($B$3=0,0,$B$3*LABOR_HRS_WK_TOM*SEASON_WEEKS*(1+DIM_PCT_TOM)^$B$3) -> 724.7295 | D7: 724.7295 | E7: =IF(ABS(B7-D7)<0.001,"match","DIFF") -> match
A8: LABOR_HRS(CAR,5) | B8: =IF($B$4=0,0,$B$4*LABOR_HRS_WK_CAR*SEASON_WEEKS*(1+DIM_PCT_CAR)^$B$4) -> 169.71123 | D8: 169.7112 | E8: =IF(ABS(B8-D8)<0.001,"match","DIFF") -> match
A9: LABOR_HRS(MES,5) | B9: =IF($B$5=0,0,$B$5*LABOR_HRS_WK_MES*SEASON_WEEKS*(1+DIM_PCT_MES)^$B$5) -> 239.41848 | D9: 239.4185 | E9: =IF(ABS(B9-D9)<0.001,"match","DIFF") -> match
A10: TOTAL_LABOR_HRS | B10: =B7+B8+B9 -> 1133.8592 | D10: 1133.8592 | E10: =IF(ABS(B10-D10)<0.001,"match","DIFF") -> match
A11: FARMER_HRS_USED | B11: =MIN(B10,FARMER_HRS) -> 720 | D11: 720 | E11: =IF(ABS(B11-D11)<0.001,"match","DIFF") -> match
A12: TEMP_LABOR_HRS | B12: =MAX(0,B10-FARMER_HRS) -> 413.85922 | D12: 413.8592 | E12: =IF(ABS(B12-D12)<0.001,"match","DIFF") -> match
A13: TOTAL_LABOR_COST | B13: =B11*FARMER_RATE+B12*TEMP_WORKER_RATE -> 32185.056 | D13: 32185.06 | E13: =IF(ABS(B13-D13)<0.01,"match","DIFF") -> match
A14: BLENDED_RATE | B14: =B13/B10 -> 28.385407 | D14: 28.385407 | E14: =IF(ABS(B14-D14)<0.00001,"match","DIFF") -> match
A15: ALLOC_LABOR_COST(TOM) | B15: =B7*B14 -> 20571.742 | D15: 20571.74 | E15: =IF(ABS(B15-D15)<0.02,"match","DIFF") -> match
A16: ALLOC_LABOR_COST(CAR) | B16: =B8*B14 -> 4817.3225 | D16: 4817.32 | E16: =IF(ABS(B16-D16)<0.02,"match","DIFF") -> match
A17: ALLOC_LABOR_COST(MES) | B17: =B9*B14 -> 6795.9912 | D17: 6795.99 | E17: =IF(ABS(B17-D17)<0.02,"match","DIFF") -> match
A18: TOTAL_REVENUE | B18: =B3*PRICE_TOM+B4*PRICE_CAR+B5*PRICE_MES -> 67970 | D18: 67970 | E18: =IF(ABS(B18-D18)<0.01,"match","DIFF") -> match
A19: TOTAL_FERT_COST | B19: =B3*FERT_BED_TOM+B4*FERT_BED_CAR+B5*FERT_BED_MES -> 11000 | D19: 11000 | E19: =IF(ABS(B19-D19)<0.01,"match","DIFF") -> match
A20: FIXED_COSTS | B20: =FIXED_COSTS -> 20000 | D20: 20000 | E20: =IF(ABS(B20-D20)<0.01,"match","DIFF") -> match
A21: PROFIT | B21: =B18-B19-B13-B20 -> 4784.9442 | D21: 4784.94 | E21: =IF(ABS(B21-D21)<0.02,"match","DIFF") -> match
A23: tie-out SUM(ALLOC) - TOTAL_LABOR_COST | B23: =B15+B16+B17-B13 -> 0
A24: tie-out SUM(MARGIN) - (PROFIT+FIXED_COSTS) | B24: =(B18-B19-(B15+B16+B17))-(B21+B20) -> 0

Sheet Checks
A1: Checks - live PASS/FAIL. Column D is exactly "PASS" or "FALL"->"PASS"/"FAIL"; notes in column E.
A3: check | B3: computed | C3: expected | D3: result | E3: note
A4: FARMER_RATE = (FARMER_WAGE/2)/FARMER_HRS | B4: =FARMER_RATE -> 34.722222 | C4: =(FARMER_WAGE/2)/FARMER_HRS -> 34.722222 | D4: =IF(ABS(B4-C4)<0.0000001,"PASS","FAIL") -> PASS
A5: TEMP_WORKER_RATE = TEMP_WORKER_WAGE/TEMP_WORKER_HRS | B5: =TEMP_WORKER_RATE -> 17.361111 | C5: =TEMP_WORKER_WAGE/TEMP_WORKER_HRS -> 17.361111 | D5: =IF(ABS(B5-C5)<0.0000001,"PASS","FAIL") -> PASS
A6: LABOR_HRS_CAP = FARMER_HRS + TEMP_WORKER_MAX*TEMP_WORKER_HRS | B6: =LABOR_HRS_CAP -> 6480 | C6: =FARMER_HRS+TEMP_WORKER_MAX*TEMP_WORKER_HRS -> 6480 | D6: =IF(ABS(B6-C6)<0.0000001,"PASS","FAIL") -> PASS
A7: q(TOM)+q(CAR)+q(MES) <= TOTAL_BEDS | B7: =Q_TOM+Q_CAR+Q_MES -> 60 | C7: =TOTAL_BEDS -> 64 | D7: =IF(B7<=C7,"PASS","FAIL") -> PASS
A8: 0 <= q(TOM) <= MAX_BEDS_TOM | B8: =Q_TOM -> 10 | C8: =MAX_BEDS_TOM -> 20 | D8: =IF(AND(B8>=0,B8<=C8),"PASS","FAIL") -> PASS
A9: 0 <= q(CAR) <= MAX_BEDS_CAR | B9: =Q_CAR -> 20 | C9: =MAX_BEDS_CAR -> 20 | D9: =IF(AND(B9>=0,B9<=C9),"PASS","FAIL") -> PASS
A10: 0 <= q(MES) <= MAX_BEDS_MES | B10: =Q_MES -> 30 | C10: =MAX_BEDS_MES -> 30 | D10: =IF(AND(B10>=0,B10<=C10),"PASS","FAIL") -> PASS
A11: TEMP_LABOR_HRS <= TEMP_WORKER_MAX*TEMP_WORKER_HRS (solved) | B11: =TEMP_LABOR_HRS -> 4557.2161 | C11: =TEMP_WORKER_MAX*TEMP_WORKER_HRS -> 5760 | D11: =IF(B11<=C11,"PASS","FAIL") -> PASS
A12: TOTAL_LABOR_HRS <= LABOR_HRS_CAP (solved) | B12: =TOTAL_LABOR_HRS -> 5277.2161 | C12: =LABOR_HRS_CAP -> 6480 | D12: =IF(B12<=C12,"PASS","FAIL") -> PASS
A13: SUM(ALLOC_LABOR_COST) = TOTAL_LABOR_COST | B13: =CostStructure!B11+CostStructure!B12+CostStructure!B13 -> 104118.34 | C13: =TOTAL_LABOR_COST -> 104118.34 | D13: =IF(ABS(B13-C13)<0.000001,"PASS","FAIL") -> PASS
A14: SUM(MARGIN) = PROFIT + FIXED_COSTS | B14: =CostStructure!B16+CostStructure!B17+CostStructure!B18 -> 62761.665 | C14: =PROFIT+FIXED_COSTS -> 62761.665 | D14: =IF(ABS(B14-C14)<0.000001,"PASS","FAIL") -> PASS
A15: exponent guard: LABOR_HRS(TOM,1) = LABOR_HRS_WK_TOM*SEASON_WEEKS*(1+DIM_PCT_TOM) | B15: =CropEconomics!D6 -> 99 | C15: =LABOR_HRS_WK_TOM*SEASON_WEEKS*(1+DIM_PCT_TOM) -> 99 | D15: =IF(ABS(B15-C15)<0.0000001,"PASS","FAIL") -> PASS
A16: exponent not dropped: LABOR_HRS(TOM,1) > LABOR_HRS_WK_TOM*SEASON_WEEKS | B16: =CropEconomics!D6 -> 99 | C16: =LABOR_HRS_WK_TOM*SEASON_WEEKS -> 90 | D16: =IF(B16>C16,"PASS","FAIL") -> PASS | E16: =IF(B16>C16,"exponent present","exponent DROPPED") -> exponent present
A17: exponent guard: LABOR_HRS(CAR,1) = LABOR_HRS_WK_CAR*SEASON_WEEKS*(1+DIM_PCT_CAR) | B17: =CropEconomics!D30 -> 30.75 | C17: =LABOR_HRS_WK_CAR*SEASON_WEEKS*(1+DIM_PCT_CAR) -> 30.75 | D17: =IF(ABS(B17-C17)<0.0000001,"PASS","FAIL") -> PASS
A18: exponent not dropped: LABOR_HRS(CAR,1) > LABOR_HRS_WK_CAR*SEASON_WEEKS | B18: =CropEconomics!D30 -> 30.75 | C18: =LABOR_HRS_WK_CAR*SEASON_WEEKS -> 30 | D18: =IF(B18>C18,"PASS","FAIL") -> PASS | E18: =IF(B18>C18,"exponent present","exponent DROPPED") -> exponent present
A19: exponent guard: LABOR_HRS(MES,1) = LABOR_HRS_WK_MES*SEASON_WEEKS*(1+DIM_PCT_MES) | B19: =CropEconomics!D54 -> 45.5625 | C19: =LABOR_HRS_WK_MES*SEASON_WEEKS*(1+DIM_PCT_MES) -> 45.5625 | D19: =IF(ABS(B19-C19)<0.0000001,"PASS","FAIL") -> PASS
A20: exponent not dropped: LABOR_HRS(MES,1) > LABOR_HRS_WK_MES*SEASON_WEEKS | B20: =CropEconomics!D54 -> 45.5625 | C20: =LABOR_HRS_WK_MES*SEASON_WEEKS -> 45 | D20: =IF(B20>C20,"PASS","FAIL") -> PASS | E20: =IF(B20>C20,"exponent present","exponent DROPPED") -> exponent present
A21: solved allocation = Enumeration maximum row | B21: =Q_TOM&"/"&Q_CAR&"/"&Q_MES -> 10/20/30 | C21: =ENUM_OPT_QT&"/"&ENUM_OPT_QC&"/"&ENUM_OPT_QM -> 10/20/30 | D21: =IF(AND(Q_TOM=ENUM_OPT_QT,Q_CAR=ENUM_OPT_QC,Q_MES=ENUM_OPT_QM),"PASS","FAIL") -> PASS
A22: worked example PROFIT reconciles to spec anchor (to the cent) | B22: =WorkedExample!B21 -> 4784.9442 | C22: =WorkedExample!D21 -> 4784.94 | D22: =IF(ABS(B22-C22)<0.02,"PASS","FAIL") -> PASS
A23: worked example: every figure in column E = "match" | B23: =COUNTIF(WorkedExample!E7:E21,"match") -> 15 | C23: =COUNTA(WorkedExample!E7:E21) -> 15 | D23: =IF(B23=C23,"PASS","FAIL") -> PASS
A24: tomato standalone MC schedule dip is flagged | B24: =COUNTIF(MCSchedules!M5:M25,"DIP") -> 1 | C24: >= 1 | D24: =IF(B24>=1,"PASS","FAIL") -> PASS
A25: no error values: Inputs | B25: =SUMPRODUCT(--ISERROR(Inputs!A1:E22)) -> 0 | C25: 0 | D25: =IF(B25=0,"PASS","FAIL") -> PASS
A26: no error values: CropEconomics | B26: =SUMPRODUCT(--ISERROR(CropEconomics!A1:D83)) -> 0 | C26: 0 | D26: =IF(B26=0,"PASS","FAIL") -> PASS
A27: no error values: MCSchedules | B27: =SUMPRODUCT(--ISERROR(MCSchedules!A1:M110)) -> 0 | C27: 0 | D27: =IF(B27=0,"PASS","FAIL") -> PASS
A28: no error values: CostStructure | B28: =SUMPRODUCT(--ISERROR(CostStructure!A1:B25)) -> 0 | C28: 0 | D28: =IF(B28=0,"PASS","FAIL") -> PASS
A29: no error values: Optimization | B29: =SUMPRODUCT(--ISERROR(Optimization!A1:I30)) -> 0 | C29: 0 | D29: =IF(B29=0,"PASS","FAIL") -> PASS
A30: no error values: Enumeration head | B30: =SUMPRODUCT(--ISERROR(Enumeration!A1:S7)) -> 0 | C30: 0 | D30: =IF(B30=0,"PASS","FAIL") -> PASS
A31: no error values: WorkedExample | B31: =SUMPRODUCT(--ISERROR(WorkedExample!A1:E24)) -> 0 | C31: 0 | D31: =IF(B31=0,"PASS","FAIL") -> PASS
A32: no error values: Summary | B32: =SUMPRODUCT(--ISERROR(Summary!A1:H30)) -> 0 | C32: 0 | D32: =IF(B32=0,"PASS","FAIL") -> PASS
A33: no error values: Enumeration body (O column count = 13,671; errors upstream would drop the count) | B33: =COUNT(Enumeration!O4:O13674) -> 13671 | C33: =(MAX_BEDS_TOM+1)*(MAX_BEDS_CAR+1)*(MAX_BEDS_MES+1) -> 13671 | D33: =IF(B33=C33,"PASS","FAIL") -> PASS
A34: no error values: Checks sheet (rows 1-33) | B34: =SUMPRODUCT(--ISERROR(A1:E33)) -> 0 | C34: 0 | D34: =IF(B34=0,"PASS","FAIL") -> PASS
A36: ALL CHECKS | B36: =IF(AND(COUNTIF(D4:D34,"FAIL")=0,COUNTIF(D4:D34,"PASS")=COUNTA(D4:D34)),"ALL PASS","REVIEW") -> ALL PASS | C36: =COUNTIF(D4:D34,"PASS") -> 31

Sheet Summary
A1: Summary - solved allocation and named outputs. Solved = current (after Solver); decision cells populated from the Enumeration maximum.
A3: q(TOM) | B3: =Q_TOM -> 10
A4: q(CAR) | B4: =Q_CAR -> 20
A5: q(MES) | B5: =Q_MES -> 30
A6: beds used | B6: =Q_TOM+Q_CAR+Q_MES -> 60
A7: beds idle | B7: =TOTAL_BEDS-(Q_TOM+Q_CAR+Q_MES) -> 4
A9: TOTAL_REVENUE | B9: =TOTAL_REVENUE -> 210880
A10: TOTAL_FERT_COST | B10: =TOTAL_FERT_COST -> 44000
A11: TOTAL_LABOR_COST | B11: =TOTAL_LABOR_COST -> 104118.34
A12: FIXED_COSTS | B12: =FIXED_COSTS -> 20000
A13: PROFIT | B13: =PROFIT -> 42761.665
A15: TOTAL_LABOR_HRS | B15: =TOTAL_LABOR_HRS -> 5277.2161
A16: FARMER_HRS_USED | B16: =FARMER_HRS_USED -> 720
A17: TEMP_LABOR_HRS | B17: =TEMP_LABOR_HRS -> 4557.2161
A18: implied temp-worker count | B18: =TEMP_LABOR_HRS/TEMP_WORKER_HRS -> 3.1647334
A19: BLENDED_RATE | B19: =BLENDED_RATE -> 19.729784
A21: crop | B21: ALLOC_LABOR_COST | C21: MARGIN | D21: MARG_REVENUE | E21: MARG_COST at q(c) | F21: XING | G21: XING_FIRST
A22: TOM | B22: =CostStructure!B11 -> 46056.581 | C22: =CostStructure!B16 -> 33143.419 | D22: =PRICE_TOM -> 8800 | E22: =IF(Q_TOM=0,"n/a",INDEX(MCSchedules!H5:H25,MATCH(Q_TOM,MCSchedules!A5:A25,0))) -> 8248.5865 | F22: =XING_TOM -> 10 | G22: =XING_FIRST_TOM -> 11
A23: CAR | B23: =CostStructure!B12 -> 19397.729 | C23: =CostStructure!B17 -> 13682.271 | D23: =PRICE_CAR -> 2094 | E23: =IF(Q_CAR=0,"n/a",INDEX(MCSchedules!H36:H56,MATCH(Q_CAR,MCSchedules!A36:A56,0))) -> 1688.9455 | F23: =XING_CAR -> 20 | G23: =XING_FIRST_CAR -> 11
A24: MES | B24: =CostStructure!B13 -> 38664.025 | C24: =CostStructure!B18 -> 15935.975 | D24: =PRICE_MES -> 2700 | E24: =IF(Q_MES=0,"n/a",INDEX(MCSchedules!H69:H99,MATCH(Q_MES,MCSchedules!A69:A99,0))) -> 2420.0991 | F24: =XING_MES -> 30 | G24: =XING_FIRST_MES -> 7
A26: binding constraint at optimum | B26: =Optimization!B29 -> MAX_BEDS cap: CAR MES
A27: standalone MC-schedule dip(s) | B27: =IF(COUNTIF(MCSchedules!M5:M25,"DIP")+COUNTIF(MCSchedules!M36:M56,"DIP")+COUNTIF(MCSchedules!M69:M99,"DIP")>0,"flagged in TOM/CAR/MES standalone schedules (non-monotonic); cause deferred to Stage 3","none") -> flagged in TOM/CAR/MES standalone schedules (non-monotonic); cause deferred to Stage 3
A28: Solver vs enumeration | B28: =Optimization!B30 -> solved = enumeration max
A30: PROFIT (season, at optimum) | B30: =PROFIT -> 42761.665
A32: Shadow prices - value of relaxing a binding constraint by one unit (Stage 3 addition)
A33: Shadow price of a capped crop = PRICE(c) - marginal cost of its next bed (bed q+1) at the solved allocation. A non-binding constraint has shadow price 0.
A34: Extra hours for bed q+1 = LABOR_HRS(c,q+1) - LABOR_HRS(c,q), priced farm-level: farmer hours first at FARMER_RATE, then TEMP_WORKER_RATE. Valid for one extra bed only.
A35: crop | B35: q(c) at solved allocation | C35: MAX_BEDS(c) | D35: cap binding? | E35: extra labor hrs, bed q+1 | F35: extra labor cost, bed q+1 | G35: MC of bed q+1 (farm-level) | H35: PRICE(c) | I35: PRICE - MC(q+1) | J35: feasible with +1 bed? | K35: SHADOW PRICE (cap)
A36: TOM | B36: =Q_TOM -> 10 | C36: =MAX_BEDS_TOM -> 20 | D36: =IF(Q_TOM>=MAX_BEDS_TOM,"YES","no") -> no | E36: =(Q_TOM+1)*LABOR_HRS_WK_TOM*SEASON_WEEKS*(1+DIM_PCT_TOM)^(Q_TOM+1)-Q_TOM*LABOR_HRS_WK_TOM*SEASON_WEEKS*(1+DIM_PCT_TOM)^Q_TOM -> 490.21732 | F36: =(MIN(TOTAL_LABOR_HRS+E36,FARMER_HRS)*FARMER_RATE+MAX(TOTAL_LABOR_HRS+E36-FARMER_HRS,0)*TEMP_WORKER_RATE)-(MIN(TOTAL_LABOR_HRS,FARMER_HRS)*FARMER_RATE+MAX(TOTAL_LABOR_HRS-FARMER_HRS,0)*TEMP_WORKER_RATE) -> 8510.7174 | G36: =FERT_BED_TOM+F36 -> 9390.7174 | H36: =PRICE_TOM -> 8800 | I36: =H36-G36 -> -590.71745 | J36: =IF(AND(Q_TOM+Q_CAR+Q_MES+1<=TOTAL_BEDS,TOTAL_LABOR_HRS+E36<=LABOR_HRS_CAP),"feasible","BLOCKED") -> feasible | K36: =IF(AND(D36="YES",J36="feasible"),MAX(0,I36),0) -> 0
A37: CAR | B37: =Q_CAR -> 20 | C37: =MAX_BEDS_CAR -> 20 | D37: =IF(Q_CAR>=MAX_BEDS_CAR,"YES","no") -> YES | E37: =(Q_CAR+1)*LABOR_HRS_WK_CAR*SEASON_WEEKS*(1+DIM_PCT_CAR)^(Q_CAR+1)-Q_CAR*LABOR_HRS_WK_CAR*SEASON_WEEKS*(1+DIM_PCT_CAR)^Q_CAR -> 74.966702 | F37: =(MIN(TOTAL_LABOR_HRS+E37,FARMER_HRS)*FARMER_RATE+MAX(TOTAL_LABOR_HRS+E37-FARMER_HRS,0)*TEMP_WORKER_RATE)-(MIN(TOTAL_LABOR_HRS,FARMER_HRS)*FARMER_RATE+MAX(TOTAL_LABOR_HRS-FARMER_HRS,0)*TEMP_WORKER_RATE) -> 1301.5052 | G37: =FERT_BED_CAR+F37 -> 1741.5052 | H37: =PRICE_CAR -> 2094 | I37: =H37-G37 -> 352.49475 | J37: =IF(AND(Q_TOM+Q_CAR+Q_MES+1<=TOTAL_BEDS,TOTAL_LABOR_HRS+E37<=LABOR_HRS_CAP),"feasible","BLOCKED") -> feasible | K37: =IF(AND(D37="YES",J37="feasible"),MAX(0,I37),0) -> 352.49475
A38: MES | B38: =Q_MES -> 30 | C38: =MAX_BEDS_MES -> 30 | D38: =IF(Q_MES>=MAX_BEDS_MES,"YES","no") -> YES | E38: =(Q_MES+1)*LABOR_HRS_WK_MES*SEASON_WEEKS*(1+DIM_PCT_MES)^(Q_MES+1)-Q_MES*LABOR_HRS_WK_MES*SEASON_WEEKS*(1+DIM_PCT_MES)^Q_MES -> 90.635109 | F38: =(MIN(TOTAL_LABOR_HRS+E38,FARMER_HRS)*FARMER_RATE+MAX(TOTAL_LABOR_HRS+E38-FARMER_HRS,0)*TEMP_WORKER_RATE)-(MIN(TOTAL_LABOR_HRS,FARMER_HRS)*FARMER_RATE+MAX(TOTAL_LABOR_HRS-FARMER_HRS,0)*TEMP_WORKER_RATE) -> 1573.5262 | G38: =FERT_BED_MES+F38 -> 2453.5262 | H38: =PRICE_MES -> 2700 | I38: =H38-G38 -> 246.4738 | J38: =IF(AND(Q_TOM+Q_CAR+Q_MES+1<=TOTAL_BEDS,TOTAL_LABOR_HRS+E38<=LABOR_HRS_CAP),"feasible","BLOCKED") -> feasible | K38: =IF(AND(D38="YES",J38="feasible"),MAX(0,I38),0) -> 246.4738
A40: constraint | B40: limit | C40: used | D40: slack | E40: binding? | F40: shadow price
A41: TOTAL_BEDS (beds) | B41: =TOTAL_BEDS -> 64 | C41: =Q_TOM+Q_CAR+Q_MES -> 60 | D41: =B41-C41 -> 4 | E41: =IF(D41<=0,"YES","no") -> no | F41: =IF(D41>0,0,"binding - re-solve") -> 0
A42: Temp-labor hours (TEMP_WORKER_MAX x TEMP_WORKER_HRS) | B42: =TEMP_WORKER_MAX*TEMP_WORKER_HRS -> 5760 | C42: =TEMP_LABOR_HRS -> 4557.2161 | D42: =B42-C42 -> 1202.7839 | E42: =IF(D42<=0,"YES","no") -> no | F42: =IF(D42>0,0,"binding - re-solve") -> 0
A43: Temp workers, implied (same constraint, in workers) | B43: =TEMP_WORKER_MAX -> 4 | C43: =TEMP_LABOR_HRS/TEMP_WORKER_HRS -> 3.1647334 | D43: =B43-C43 -> 0.83526659 | E43: =IF(D43<=0,"YES","no") -> no | F43: =IF(D43>0,0,"binding - re-solve") -> 0
A45: tie-out: farmer-first labor cost = TOTAL_LABOR_COST | B45: =MIN(TOTAL_LABOR_HRS,FARMER_HRS)*FARMER_RATE+MAX(TOTAL_LABOR_HRS-FARMER_HRS,0)*TEMP_WORKER_RATE -> 104118.34 | C45: =TOTAL_LABOR_COST -> 104118.34 | D45: =IF(ABS(B45-C45)<0.005,"PASS","FAIL") -> PASS
