Workbook
Name AVOID_COST_HI: Inputs!$B$10
Name AVOID_COST_LO: Inputs!$B$9
Name BENCH_DAYS: Inputs!$B$7
Name BENCH_TOTAL: Waitlist!$C$4:$C$11
Name CAP_RATIO: Capacity!$D$4:$D$11
Name CAP_RATIO_STAFF_2024: Capacity!$D$14
Name COND_A_GAP: Conditions!$E$7:$E$8
Name COST_FWD: Conditions!$C$5:$C$8
Name COST_FY: Inputs!$A$61:$A$73
Name COUNTY: Inputs!$A$34:$A$37
Name COVID_FLAG: Waitlist!$U$4:$U$11
Name COVID_YEARS: Inputs!$B$16:$B$17
Name CTY_DAY_SHARE: County!$D$4:$E$7
Name CTY_DAYS: Inputs!$D$34:$E$37
Name CTY_DAYS_PER_PT: County!$B$4:$C$7
Name CTY_PATIENTS: Inputs!$B$34:$C$37
Name DATE_ADJ_2021: Inputs!$B$13
Name DATE_RESET_2024: Inputs!$B$14
Name DAYS_IN_YEAR: Waitlist!$I$4:$I$11
Name DAYS_PER_PT: Waitlist!$B$4:$B$11
Name DEC31_NF: Inputs!$L$22:$L$29
Name DEC31_TOTAL: Inputs!$K$22:$K$29
Name EXCESS_BEDS: Waitlist!$J$4:$J$11
Name EXCESS_COST_HI: Cost!$C$11:$D$11
Name EXCESS_COST_HI_NOW: Cost!$E$11
Name EXCESS_COST_LO: Cost!$C$10:$D$10
Name EXCESS_COST_LO_NOW: Cost!$E$10
Name EXCESS_DAYS: Waitlist!$F$4:$F$11
Name EXCESS_SHARE: Waitlist!$H$4:$H$11
Name FLAG_2017_INCOMPLETE: Waitlist!$B$14
Name GAP_PER_PT: Waitlist!$D$4:$D$11
Name KFF_COST_DAY: Inputs!$B$8
Name LARGEST_REASON: Tests!$B$19:$B$26
Name LTC_UNSTAFFED: Inputs!$M$22:$M$29
Name LTC_UNSTAFFED_STAFF_2024: Inputs!$B$6
Name MB_GROSS: Inputs!$B$78:$B$81
Name MEETS_BENCH: Waitlist!$K$4:$K$11
Name NET_COST_HI: Cost!$C$9:$D$9
Name NET_COST_HI_NOW: Cost!$E$9
Name NET_COST_LO: Cost!$C$8:$D$8
Name NET_COST_LO_NOW: Cost!$E$8
Name NF_COST_ALL: Inputs!$B$61:$B$73
Name NF_COST_MCD_HEAVY: Inputs!$C$61:$C$73
Name NF_RATE_MEDIAN: Inputs!$C$41:$C$57
Name NF_SHARE_DEC31: Cost!$C$12:$D$12
Name RATE_DATE: Inputs!$A$41:$A$57
Name RATE_FWD: Conditions!$D$7:$D$8
Name RATE_GROWTH_2024_2026: Conditions!$B$10
Name REASON_BEHAVIOR: Inputs!$E$22:$E$29
Name REASON_FINANCIAL: Inputs!$G$22:$G$29
Name REASON_GUARDIANSHIP: Inputs!$H$22:$H$29
Name REASON_NO_BED: Inputs!$D$22:$D$29
Name REASON_OTHER: Inputs!$J$22:$J$29
Name REASON_PASARR: Inputs!$I$22:$I$29
Name REASON_SPECIAL_CARE: Inputs!$F$22:$F$29
Name REASON_SUM: Waitlist!$L$4:$L$11
Name SHARE_BEHAVIOR: Waitlist!$N$4:$N$11
Name SHARE_FINANCIAL: Waitlist!$P$4:$P$11
Name SHARE_GUARDIANSHIP: Waitlist!$Q$4:$Q$11
Name SHARE_NO_BED: Waitlist!$M$4:$M$11

Sheet Inputs
A1: Inputs: every manual input (yellow). Values are drafts until verified against the source.
A2: Input rows with a verification date | B2: =COUNT(R6:R17,R22:R29,R34:R37,R41:R57,R61:R73,R78:R81) -> 57 | C2: ="of "&(ROWS(R6:R17)+ROWS(R22:R29)+ROWS(R34:R37)+ROWS(R41:R57)+ROWS(R61:R73)+ROWS(R78:R81)) -> of 58
A4: Scalar inputs
A5: Name | B5: Value | C5: Unit | D5: Source | P5: Source page | Q5: Verified by | R5: Date verified
A6: LTC_UNSTAFFED_STAFF_2024 | B6: 353 | C6: beds, Dec 31, 2024 | D6: SHPDA Table 16 (2024), reason text naming staffing (Okutsu Veterans Home's 21 "staff to census" excluded) | P6: SHPDA 2024 Table 16, pp. 80-82 (staffing rows, Kula counted) | Q6: MK | R6: 46294
A7: BENCH_DAYS | B7: 14 | C7: days per patient (average) | D7: My benchmark; reference: Scotland's 2-week maximum (NHS Borders, 2015) | P7: Brief (main) lines 19, 81 | Q7: MK | R7: 46294
A8: KFF_COST_DAY | B8: 3664 | C8: USD per adjusted inpatient day, 2023 | D8: KFF (AHA Annual Survey), Hawaii nonprofit hospitals ($3,663.56) | P8: KFF indicator, 2023 timeframe, Hawaii, Non-Profit ($3,663.56) | Q8: MK | R8: 46294
A9: AVOID_COST_LO | B9: 550 | C9: USD per waitlisted day | D9: About 15% of KFF_COST_DAY, rounded (brief) | P9: Brief line 51 (15% and 40% of $3,663.56, to nearest $10) | Q9: MK | R9: 46294
A10: AVOID_COST_HI | B10: 1470 | C10: USD per waitlisted day | D10: About 40% of KFF_COST_DAY, rounded (brief; unrounded 1,466) | P10: Brief line 51 (15% and 40% of $3,663.56, to nearest $10) | Q10: MK | R10: 46294
A11: WL_RATE_2026 | B11: 486.76 | C11: USD per waitlisted day | D11: Med-QUEST QI-2532 (Jan 2026), the current case | P11: QI-2532 p. 2, Attachment A | Q11: MK | R11: 46294
A12: WL_RATE_LEAHI_2026 | B12: 480.19 | C12: USD per waitlisted day | D12: QI-2532; reported as a note, not used in a calculation | P12: QI-2532 p. 2, Leahi row | Q12: MK | R12: 46294
A13: DATE_ADJ_2021 | B13: 44209 | C13: date | D13: SPA HI-23-0014, Attachment 4.19-D p. 38: 12% adjustment for private homes (first seen in the January 2021 memo, QI-2041) | P13: SPA HI-23-0014, Att. 4.19-D p. 38 (PDF p. 5) | Q13: MK | R13: 46294
A14: DATE_RESET_2024 | B14: 45292 | C14: date | D14: SPA HI-23-0014; QI-2342 | P14: SPA Att. 4.19-D p. 38; QI-2342 p. 2 | Q14: MK | R14: 46294
A15: T1_MIN_DROP_PTS | B15: 5 | C15: percentage points | D15: Brief, test 1 | P15: Brief line 72 | Q15: MK | R15: 46294
A16: COVID_YEARS | B16: 2020 | C16: years | D16: Brief | P16: Brief line 79 | Q16: MK | R16: 46294
A17: (COVID_YEARS, 2nd) | B17: 2021 | P17: Brief line 79 | Q17: MK | R17: 46294
A19: Year table (SHPDA Table 18 statewide; Table 16 statewide; Med-QUEST waitlisted rates)
A20: Year | B20: WL_PATIENTS | C20: WL_DAYS | D20: REASON_NO_BED | E20: REASON_BEHAVIOR | F20: REASON_SPECIAL_CARE | G20: REASON_FINANCIAL | H20: REASON_GUARDIANSHIP | I20: REASON_PASARR | J20: REASON_OTHER | K20: DEC31_TOTAL | L20: DEC31_NF | M20: LTC_UNSTAFFED | N20: WL_RATE_JAN | O20: WL_RATE_JUL | P20: Source page | Q20: Verified by | R20: Date verified
A21: Source | B21: T18 total | C21: T18 total | D21: T18 reason F | E21: T18 reason G | F21: T18 reason H | G21: T18 reason I | H21: T18 reason J | I21: T18 reason K | J21: T18 reason L | K21: T18 by level of care | L21: T18 type A | M21: T16 statewide | N21: QI-2225, QI-2342 | O21: QI-2326, QI-2413
A22: 2017 | B22: 6187 | C22: 61470 | D22: 39 | E22: 16 | F22: 23 | G22: 18 | H22: 11 | I22: 2 | J22: 11 | K22: 157 | M22: 128 | P22: T18 2017 p. 72; T16 2017 p. 69 | Q22: MK | R22: 46294
A23: 2018 | B23: 5294 | C23: 66091 | D23: 57 | E23: 29 | F23: 17 | G23: 31 | H23: 18 | I23: 2 | J23: 17 | K23: 171 | M23: 160 | P23: T18 2018 p. 82; T16 p. 79 | Q23: MK | R23: 46294
A24: 2019 | B24: 4790 | C24: 78911 | D24: 72 | E24: 27 | F24: 21 | G24: 32 | H24: 26 | I24: 0 | J24: 6 | K24: 184 | M24: 248 | P24: T18 2019 p. 82; T16 p. 79 | Q24: MK | R24: 46294
A25: 2020 | B25: 4553 | C25: 57297 | D25: 41 | E25: 24 | F25: 22 | G25: 30 | H25: 15 | I25: 0 | J25: 12 | K25: 144 | M25: 462 | P25: T18 2020 p. 85; T16 p. 81 | Q25: MK | R25: 46294
A26: 2021 | B26: 4927 | C26: 60050 | D26: 50 | E26: 36 | F26: 22 | G26: 43 | H26: 20 | I26: 0 | J26: 18 | K26: 189 | M26: 614 | P26: T18 2021 p. 87; T16 p. 83 | Q26: MK | R26: 46294
A27: 2022 | B27: 3681 | C27: 78561 | D27: 57 | E27: 35 | F27: 39 | G27: 75 | H27: 29 | I27: 5 | J27: 10 | K27: 250 | M27: 661 | P27: T18 2022 p. 86; T16 p. 82 | Q27: MK | R27: 46294
A28: 2023 | B28: 3610 | C28: 83097 | D28: 42 | E28: 48 | F28: 26 | G28: 45 | H28: 28 | I28: 1 | J28: 1 | K28: 191 | L28: 157 | M28: 510 | N28: 283.6 | O28: 302.89 | P28: T18 2023 p. 86; T16 p. 82; QI-2225 p. 2; QI-2326 p. 2 | Q28: MK | R28: 46294
A29: 2024 | B29: 3123 | C29: 60876 | D29: 31 | E29: 29 | F29: 18 | G29: 60 | H29: 31 | I29: 0 | J29: 4 | K29: 173 | L29: 120 | M29: 548 | N29: 464.97 | O29: 455.59 | P29: T18 2024 p. 86; T16 p. 82; QI-2342 p. 2; QI-2413 p. 2 | Q29: MK | R29: 46294
A30: Reason columns F to L; 2017 reasons sum to 120 against 157 by level of care (Maui Memorial records reasons for 6 of 47 patients; Queen's Punchbowl's reasons sum to 43 against 39). DEC31_NF and the waitlisted rates exist for 2023 and 2024 only (blank, not inputs, in other years).
A32: County table (Table 18 hospital rows summed by county, shpda-table18-by-hospital-2023-2024.csv)
A33: COUNTY | B33: CTY_PATIENTS 2023 | C33: CTY_PATIENTS 2024 | D33: CTY_DAYS 2023 | E33: CTY_DAYS 2024 | P33: Source page | Q33: Verified by | R33: Date verified
A34: Hawaii | B34: 869 | C34: 727 | D34: 23212 | E34: 20174 | P34: T18 2023 and 2024, pp. 85-86 (hospital rows summed; county totals) | Q34: MK | R34: 46294
A35: Honolulu | B35: 2255 | C35: 1979 | D35: 40327 | E35: 27380 | P35: T18 2023 and 2024, pp. 85-86 (hospital rows summed; county totals) | Q35: MK | R35: 46294
A36: Kauai | B36: 86 | C36: 64 | D36: 1720 | E36: 1927 | P36: T18 2023 and 2024, pp. 85-86 (hospital rows summed; county totals) | Q36: MK | R36: 46294
A37: Maui | B37: 400 | C37: 353 | D37: 17838 | E37: 11395 | P37: T18 2023 and 2024, pp. 85-86 (hospital rows summed; county totals) | Q37: MK | R37: 46294
A39: Median nursing-facility rate by memo (Med-QUEST memos, hi-medicaid-rate-series-2016-2026.csv)
A40: RATE_DATE (effective month) | B40: Memo | C40: NF_RATE_MEDIAN | P40: Source page | Q40: Verified by | R40: Date verified
A41: 42370 | B41: QI-1521 | C41: 246.97 | P41: QI-1521 p. 2 | Q41: MK | R41: 46294
A42: 42552 | B42: QI-1607 | C42: 252.4 | P42: QI-1607 p. 5 | Q42: MK | R42: 46294
A43: 42736 | B43: QI-1622 | C43: 251.93 | P43: QI-1622 p. 2 | Q43: MK | R43: 46294
A44: 42917 | B44: QI-1710 | C44: 261.45 | P44: QI-1710 p. 8 | Q44: MK | R44: 46294
...

Sheet Waitlist
A1: Waitlist: days per patient against the benchmark, excess days, beds and reason shares, 2017 to 2024
A3: Year | B3: Days per patient | C3: Benchmark days (patients x 14) | D3: Signed gap per patient (days) | E3: Waitlist days | F3: Excess days (floored at 0) | G3: Days within the benchmark | H3: Excess share of days | I3: Days in year | J3: Excess beds (average day) | K3: Meets benchmark | L3: Reasons total (F to L) | M3: Share: No bed | N3: Share: Behavior | O3: Share: Special care | P3: Share: Financial | Q3: Share: Guardianship | R3: Share: PASARR | S3: Share: Other | T3: Unstaffed LTC beds, Dec 31 | U3: COVID flag
A4: =INDEX(YEAR,1) -> 2017 | B4: =INDEX(WL_DAYS,1)/INDEX(WL_PATIENTS,1) -> 9.9353483 | C4: =INDEX(WL_PATIENTS,1)*BENCH_DAYS -> 86618 | D4: =INDEX(DAYS_PER_PT,1)-BENCH_DAYS -> -4.0646517 | E4: =INDEX(WL_DAYS,1) -> 61470 | F4: =MAX(0,INDEX(WL_DAYS,1)-INDEX(BENCH_TOTAL,1)) -> 0 | G4: =INDEX(WL_DAYS,1)-INDEX(EXCESS_DAYS,1) -> 61470 | H4: =INDEX(EXCESS_DAYS,1)/INDEX(WL_DAYS,1) -> 0 | I4: =DATE(INDEX(YEAR,1)+1,1,1)-DATE(INDEX(YEAR,1),1,1) -> 365 | J4: =INDEX(EXCESS_DAYS,1)/INDEX(DAYS_IN_YEAR,1) -> 0 | K4: =INDEX(DAYS_PER_PT,1)<=BENCH_DAYS -> TRUE | L4: =INDEX(REASON_NO_BED,1)+INDEX(REASON_BEHAVIOR,1)+INDEX(REASON_SPECIAL_CARE,1)+INDEX(REASON_FINANCIAL,1)+INDEX(REASON_GUARDIANSHIP,1)+INDEX(REASON_PASARR,1)+INDEX(REASON_OTHER,1) -> 120 | M4: =INDEX(REASON_NO_BED,1)/INDEX(REASON_SUM,1) -> 0.325 | N4: =INDEX(REASON_BEHAVIOR,1)/INDEX(REASON_SUM,1) -> 0.13333333 | O4: =INDEX(REASON_SPECIAL_CARE,1)/INDEX(REASON_SUM,1) -> 0.19166667 | P4: =INDEX(REASON_FINANCIAL,1)/INDEX(REASON_SUM,1) -> 0.15 | Q4: =INDEX(REASON_GUARDIANSHIP,1)/INDEX(REASON_SUM,1) -> 0.091666667 | R4: =INDEX(REASON_PASARR,1)/INDEX(REASON_SUM,1) -> 0.016666667 | S4: =INDEX(REASON_OTHER,1)/INDEX(REASON_SUM,1) -> 0.091666667 | T4: =INDEX(LTC_UNSTAFFED,1) -> 128 | U4: =COUNTIF(COVID_YEARS,INDEX(YEAR,1))>0 -> FALSE
A5: =INDEX(YEAR,2) -> 2018 | B5: =INDEX(WL_DAYS,2)/INDEX(WL_PATIENTS,2) -> 12.484133 | C5: =INDEX(WL_PATIENTS,2)*BENCH_DAYS -> 74116 | D5: =INDEX(DAYS_PER_PT,2)-BENCH_DAYS -> -1.515867 | E5: =INDEX(WL_DAYS,2) -> 66091 | F5: =MAX(0,INDEX(WL_DAYS,2)-INDEX(BENCH_TOTAL,2)) -> 0 | G5: =INDEX(WL_DAYS,2)-INDEX(EXCESS_DAYS,2) -> 66091 | H5: =INDEX(EXCESS_DAYS,2)/INDEX(WL_DAYS,2) -> 0 | I5: =DATE(INDEX(YEAR,2)+1,1,1)-DATE(INDEX(YEAR,2),1,1) -> 365 | J5: =INDEX(EXCESS_DAYS,2)/INDEX(DAYS_IN_YEAR,2) -> 0 | K5: =INDEX(DAYS_PER_PT,2)<=BENCH_DAYS -> TRUE | L5: =INDEX(REASON_NO_BED,2)+INDEX(REASON_BEHAVIOR,2)+INDEX(REASON_SPECIAL_CARE,2)+INDEX(REASON_FINANCIAL,2)+INDEX(REASON_GUARDIANSHIP,2)+INDEX(REASON_PASARR,2)+INDEX(REASON_OTHER,2) -> 171 | M5: =INDEX(REASON_NO_BED,2)/INDEX(REASON_SUM,2) -> 0.33333333 | N5: =INDEX(REASON_BEHAVIOR,2)/INDEX(REASON_SUM,2) -> 0.16959064 | O5: =INDEX(REASON_SPECIAL_CARE,2)/INDEX(REASON_SUM,2) -> 0.099415205 | P5: =INDEX(REASON_FINANCIAL,2)/INDEX(REASON_SUM,2) -> 0.18128655 | Q5: =INDEX(REASON_GUARDIANSHIP,2)/INDEX(REASON_SUM,2) -> 0.10526316 | R5: =INDEX(REASON_PASARR,2)/INDEX(REASON_SUM,2) -> 0.011695906 | S5: =INDEX(REASON_OTHER,2)/INDEX(REASON_SUM,2) -> 0.099415205 | T5: =INDEX(LTC_UNSTAFFED,2) -> 160 | U5: =COUNTIF(COVID_YEARS,INDEX(YEAR,2))>0 -> FALSE
A6: =INDEX(YEAR,3) -> 2019 | B6: =INDEX(WL_DAYS,3)/INDEX(WL_PATIENTS,3) -> 16.474113 | C6: =INDEX(WL_PATIENTS,3)*BENCH_DAYS -> 67060 | D6: =INDEX(DAYS_PER_PT,3)-BENCH_DAYS -> 2.4741127 | E6: =INDEX(WL_DAYS,3) -> 78911 | F6: =MAX(0,INDEX(WL_DAYS,3)-INDEX(BENCH_TOTAL,3)) -> 11851 | G6: =INDEX(WL_DAYS,3)-INDEX(EXCESS_DAYS,3) -> 67060 | H6: =INDEX(EXCESS_DAYS,3)/INDEX(WL_DAYS,3) -> 0.15018185 | I6: =DATE(INDEX(YEAR,3)+1,1,1)-DATE(INDEX(YEAR,3),1,1) -> 365 | J6: =INDEX(EXCESS_DAYS,3)/INDEX(DAYS_IN_YEAR,3) -> 32.468493 | K6: =INDEX(DAYS_PER_PT,3)<=BENCH_DAYS -> FALSE | L6: =INDEX(REASON_NO_BED,3)+INDEX(REASON_BEHAVIOR,3)+INDEX(REASON_SPECIAL_CARE,3)+INDEX(REASON_FINANCIAL,3)+INDEX(REASON_GUARDIANSHIP,3)+INDEX(REASON_PASARR,3)+INDEX(REASON_OTHER,3) -> 184 | M6: =INDEX(REASON_NO_BED,3)/INDEX(REASON_SUM,3) -> 0.39130435 | N6: =INDEX(REASON_BEHAVIOR,3)/INDEX(REASON_SUM,3) -> 0.14673913 | O6: =INDEX(REASON_SPECIAL_CARE,3)/INDEX(REASON_SUM,3) -> 0.11413043 | P6: =INDEX(REASON_FINANCIAL,3)/INDEX(REASON_SUM,3) -> 0.17391304 | Q6: =INDEX(REASON_GUARDIANSHIP,3)/INDEX(REASON_SUM,3) -> 0.14130435 | R6: =INDEX(REASON_PASARR,3)/INDEX(REASON_SUM,3) -> 0 | S6: =INDEX(REASON_OTHER,3)/INDEX(REASON_SUM,3) -> 0.032608696 | T6: =INDEX(LTC_UNSTAFFED,3) -> 248 | U6: =COUNTIF(COVID_YEARS,INDEX(YEAR,3))>0 -> FALSE
A7: =INDEX(YEAR,4) -> 2020 | B7: =INDEX(WL_DAYS,4)/INDEX(WL_PATIENTS,4) -> 12.58445 | C7: =INDEX(WL_PATIENTS,4)*BENCH_DAYS -> 63742 | D7: =INDEX(DAYS_PER_PT,4)-BENCH_DAYS -> -1.4155502 | E7: =INDEX(WL_DAYS,4) -> 57297 | F7: =MAX(0,INDEX(WL_DAYS,4)-INDEX(BENCH_TOTAL,4)) -> 0 | G7: =INDEX(WL_DAYS,4)-INDEX(EXCESS_DAYS,4) -> 57297 | H7: =INDEX(EXCESS_DAYS,4)/INDEX(WL_DAYS,4) -> 0 | I7: =DATE(INDEX(YEAR,4)+1,1,1)-DATE(INDEX(YEAR,4),1,1) -> 366 | J7: =INDEX(EXCESS_DAYS,4)/INDEX(DAYS_IN_YEAR,4) -> 0 | K7: =INDEX(DAYS_PER_PT,4)<=BENCH_DAYS -> TRUE | L7: =INDEX(REASON_NO_BED,4)+INDEX(REASON_BEHAVIOR,4)+INDEX(REASON_SPECIAL_CARE,4)+INDEX(REASON_FINANCIAL,4)+INDEX(REASON_GUARDIANSHIP,4)+INDEX(REASON_PASARR,4)+INDEX(REASON_OTHER,4) -> 144 | M7: =INDEX(REASON_NO_BED,4)/INDEX(REASON_SUM,4) -> 0.28472222 | N7: =INDEX(REASON_BEHAVIOR,4)/INDEX(REASON_SUM,4) -> 0.16666667 | O7: =INDEX(REASON_SPECIAL_CARE,4)/INDEX(REASON_SUM,4) -> 0.15277778 | P7: =INDEX(REASON_FINANCIAL,4)/INDEX(REASON_SUM,4) -> 0.20833333 | Q7: =INDEX(REASON_GUARDIANSHIP,4)/INDEX(REASON_SUM,4) -> 0.10416667 | R7: =INDEX(REASON_PASARR,4)/INDEX(REASON_SUM,4) -> 0 | S7: =INDEX(REASON_OTHER,4)/INDEX(REASON_SUM,4) -> 0.083333333 | T7: =INDEX(LTC_UNSTAFFED,4) -> 462 | U7: =COUNTIF(COVID_YEARS,INDEX(YEAR,4))>0 -> TRUE
A8: =INDEX(YEAR,5) -> 2021 | B8: =INDEX(WL_DAYS,5)/INDEX(WL_PATIENTS,5) -> 12.187944 | C8: =INDEX(WL_PATIENTS,5)*BENCH_DAYS -> 68978 | D8: =INDEX(DAYS_PER_PT,5)-BENCH_DAYS -> -1.812056 | E8: =INDEX(WL_DAYS,5) -> 60050 | F8: =MAX(0,INDEX(WL_DAYS,5)-INDEX(BENCH_TOTAL,5)) -> 0 | G8: =INDEX(WL_DAYS,5)-INDEX(EXCESS_DAYS,5) -> 60050 | H8: =INDEX(EXCESS_DAYS,5)/INDEX(WL_DAYS,5) -> 0 | I8: =DATE(INDEX(YEAR,5)+1,1,1)-DATE(INDEX(YEAR,5),1,1) -> 365 | J8: =INDEX(EXCESS_DAYS,5)/INDEX(DAYS_IN_YEAR,5) -> 0 | K8: =INDEX(DAYS_PER_PT,5)<=BENCH_DAYS -> TRUE | L8: =INDEX(REASON_NO_BED,5)+INDEX(REASON_BEHAVIOR,5)+INDEX(REASON_SPECIAL_CARE,5)+INDEX(REASON_FINANCIAL,5)+INDEX(REASON_GUARDIANSHIP,5)+INDEX(REASON_PASARR,5)+INDEX(REASON_OTHER,5) -> 189 | M8: =INDEX(REASON_NO_BED,5)/INDEX(REASON_SUM,5) -> 0.26455026 | N8: =INDEX(REASON_BEHAVIOR,5)/INDEX(REASON_SUM,5) -> 0.19047619 | O8: =INDEX(REASON_SPECIAL_CARE,5)/INDEX(REASON_SUM,5) -> 0.11640212 | P8: =INDEX(REASON_FINANCIAL,5)/INDEX(REASON_SUM,5) -> 0.22751323 | Q8: =INDEX(REASON_GUARDIANSHIP,5)/INDEX(REASON_SUM,5) -> 0.10582011 | R8: =INDEX(REASON_PASARR,5)/INDEX(REASON_SUM,5) -> 0 | S8: =INDEX(REASON_OTHER,5)/INDEX(REASON_SUM,5) -> 0.095238095 | T8: =INDEX(LTC_UNSTAFFED,5) -> 614 | U8: =COUNTIF(COVID_YEARS,INDEX(YEAR,5))>0 -> TRUE
A9: =INDEX(YEAR,6) -> 2022 | B9: =INDEX(WL_DAYS,6)/INDEX(WL_PATIENTS,6) -> 21.342298 | C9: =INDEX(WL_PATIENTS,6)*BENCH_DAYS -> 51534 | D9: =INDEX(DAYS_PER_PT,6)-BENCH_DAYS -> 7.3422983 | E9: =INDEX(WL_DAYS,6) -> 78561 | F9: =MAX(0,INDEX(WL_DAYS,6)-INDEX(BENCH_TOTAL,6)) -> 27027 | G9: =INDEX(WL_DAYS,6)-INDEX(EXCESS_DAYS,6) -> 51534 | H9: =INDEX(EXCESS_DAYS,6)/INDEX(WL_DAYS,6) -> 0.34402566 | I9: =DATE(INDEX(YEAR,6)+1,1,1)-DATE(INDEX(YEAR,6),1,1) -> 365 | J9: =INDEX(EXCESS_DAYS,6)/INDEX(DAYS_IN_YEAR,6) -> 74.046575 | K9: =INDEX(DAYS_PER_PT,6)<=BENCH_DAYS -> FALSE | L9: =INDEX(REASON_NO_BED,6)+INDEX(REASON_BEHAVIOR,6)+INDEX(REASON_SPECIAL_CARE,6)+INDEX(REASON_FINANCIAL,6)+INDEX(REASON_GUARDIANSHIP,6)+INDEX(REASON_PASARR,6)+INDEX(REASON_OTHER,6) -> 250 | M9: =INDEX(REASON_NO_BED,6)/INDEX(REASON_SUM,6) -> 0.228 | N9: =INDEX(REASON_BEHAVIOR,6)/INDEX(REASON_SUM,6) -> 0.14 | O9: =INDEX(REASON_SPECIAL_CARE,6)/INDEX(REASON_SUM,6) -> 0.156 | P9: =INDEX(REASON_FINANCIAL,6)/INDEX(REASON_SUM,6) -> 0.3 | Q9: =INDEX(REASON_GUARDIANSHIP,6)/INDEX(REASON_SUM,6) -> 0.116 | R9: =INDEX(REASON_PASARR,6)/INDEX(REASON_SUM,6) -> 0.02 | S9: =INDEX(REASON_OTHER,6)/INDEX(REASON_SUM,6) -> 0.04 | T9: =INDEX(LTC_UNSTAFFED,6) -> 661 | U9: =COUNTIF(COVID_YEARS,INDEX(YEAR,6))>0 -> FALSE
A10: =INDEX(YEAR,7) -> 2023 | B10: =INDEX(WL_DAYS,7)/INDEX(WL_PATIENTS,7) -> 23.01856 | C10: =INDEX(WL_PATIENTS,7)*BENCH_DAYS -> 50540 | D10: =INDEX(DAYS_PER_PT,7)-BENCH_DAYS -> 9.0185596 | E10: =INDEX(WL_DAYS,7) -> 83097 | F10: =MAX(0,INDEX(WL_DAYS,7)-INDEX(BENCH_TOTAL,7)) -> 32557 | G10: =INDEX(WL_DAYS,7)-INDEX(EXCESS_DAYS,7) -> 50540 | H10: =INDEX(EXCESS_DAYS,7)/INDEX(WL_DAYS,7) -> 0.39179513 | I10: =DATE(INDEX(YEAR,7)+1,1,1)-DATE(INDEX(YEAR,7),1,1) -> 365 | J10: =INDEX(EXCESS_DAYS,7)/INDEX(DAYS_IN_YEAR,7) -> 89.19726 | K10: =INDEX(DAYS_PER_PT,7)<=BENCH_DAYS -> FALSE | L10: =INDEX(REASON_NO_BED,7)+INDEX(REASON_BEHAVIOR,7)+INDEX(REASON_SPECIAL_CARE,7)+INDEX(REASON_FINANCIAL,7)+INDEX(REASON_GUARDIANSHIP,7)+INDEX(REASON_PASARR,7)+INDEX(REASON_OTHER,7) -> 191 | M10: =INDEX(REASON_NO_BED,7)/INDEX(REASON_SUM,7) -> 0.21989529 | N10: =INDEX(REASON_BEHAVIOR,7)/INDEX(REASON_SUM,7) -> 0.2513089 | O10: =INDEX(REASON_SPECIAL_CARE,7)/INDEX(REASON_SUM,7) -> 0.13612565 | P10: =INDEX(REASON_FINANCIAL,7)/INDEX(REASON_SUM,7) -> 0.23560209 | Q10: =INDEX(REASON_GUARDIANSHIP,7)/INDEX(REASON_SUM,7) -> 0.14659686 | R10: =INDEX(REASON_PASARR,7)/INDEX(REASON_SUM,7) -> 0.0052356021 | S10: =INDEX(REASON_OTHER,7)/INDEX(REASON_SUM,7) -> 0.0052356021 | T10: =INDEX(LTC_UNSTAFFED,7) -> 510 | U10: =COUNTIF(COVID_YEARS,INDEX(YEAR,7))>0 -> FALSE
A11: =INDEX(YEAR,8) -> 2024 | B11: =INDEX(WL_DAYS,8)/INDEX(WL_PATIENTS,8) -> 19.492795 | C11: =INDEX(WL_PATIENTS,8)*BENCH_DAYS -> 43722 | D11: =INDEX(DAYS_PER_PT,8)-BENCH_DAYS -> 5.4927954 | E11: =INDEX(WL_DAYS,8) -> 60876 | F11: =MAX(0,INDEX(WL_DAYS,8)-INDEX(BENCH_TOTAL,8)) -> 17154 | G11: =INDEX(WL_DAYS,8)-INDEX(EXCESS_DAYS,8) -> 43722 | H11: =INDEX(EXCESS_DAYS,8)/INDEX(WL_DAYS,8) -> 0.28178593 | I11: =DATE(INDEX(YEAR,8)+1,1,1)-DATE(INDEX(YEAR,8),1,1) -> 366 | J11: =INDEX(EXCESS_DAYS,8)/INDEX(DAYS_IN_YEAR,8) -> 46.868852 | K11: =INDEX(DAYS_PER_PT,8)<=BENCH_DAYS -> FALSE | L11: =INDEX(REASON_NO_BED,8)+INDEX(REASON_BEHAVIOR,8)+INDEX(REASON_SPECIAL_CARE,8)+INDEX(REASON_FINANCIAL,8)+INDEX(REASON_GUARDIANSHIP,8)+INDEX(REASON_PASARR,8)+INDEX(REASON_OTHER,8) -> 173 | M11: =INDEX(REASON_NO_BED,8)/INDEX(REASON_SUM,8) -> 0.17919075 | N11: =INDEX(REASON_BEHAVIOR,8)/INDEX(REASON_SUM,8) -> 0.16763006 | O11: =INDEX(REASON_SPECIAL_CARE,8)/INDEX(REASON_SUM,8) -> 0.10404624 | P11: =INDEX(REASON_FINANCIAL,8)/INDEX(REASON_SUM,8) -> 0.34682081 | Q11: =INDEX(REASON_GUARDIANSHIP,8)/INDEX(REASON_SUM,8) -> 0.17919075 | R11: =INDEX(REASON_PASARR,8)/INDEX(REASON_SUM,8) -> 0 | S11: =INDEX(REASON_OTHER,8)/INDEX(REASON_SUM,8) -> 0.023121387 | T11: =INDEX(LTC_UNSTAFFED,8) -> 548 | U11: =COUNTIF(COVID_YEARS,INDEX(YEAR,8))>0 -> FALSE
A13: Flags and notes
A14: FLAG_2017_INCOMPLETE | B14: =INDEX(REASON_SUM,1)<INDEX(DEC31_TOTAL,1) -> TRUE | C14: 2017 reasons recorded for 120 of 157 patients on Dec 31; its shares use the recorded reasons only.
A15: Unstaffed LTC beds, 2024 | B15: =INDEX(LTC_UNSTAFFED,8) -> 548 | C15: Staffing note (reported only)
A16: of which, for lack of staff | B16: =LTC_UNSTAFFED_STAFF_2024 -> 353
A17: Excess days are measured against the average benchmark and are a lower bound on days patients spent beyond 14. All levels of care. Beds use calendar days (366 in 2020 and 2024).

Sheet Cost
A1: Cost of the gap: net avoidable cost of excess days, 2023, 2024 and the current case (Jan 2026 rate)
A3: Measure | B3: Unit | C3: 2023 | D3: 2024 | E3: Now (2024 excess days at the Jan 2026 rate)
A4: Excess days | B4: days | C4: =INDEX(EXCESS_DAYS,MATCH(2023,YEAR,0)) -> 32557 | D4: =INDEX(EXCESS_DAYS,MATCH(2024,YEAR,0)) -> 17154 | E4: =INDEX(EXCESS_DAYS,MATCH(2024,YEAR,0)) -> 17154
A5: Waitlisted rate, January | B5: USD per day | C5: =INDEX(WL_RATE_JAN,MATCH(2023,YEAR,0)) -> 283.6 | D5: =INDEX(WL_RATE_JAN,MATCH(2024,YEAR,0)) -> 464.97
A6: Waitlisted rate, July | B6: USD per day | C6: =INDEX(WL_RATE_JUL,MATCH(2023,YEAR,0)) -> 302.89 | D6: =INDEX(WL_RATE_JUL,MATCH(2024,YEAR,0)) -> 455.59
A7: Average waitlisted rate (WL_RATE_AVG); Now = WL_RATE_2026 | B7: USD per day | C7: =(INDEX(WL_RATE_JAN,MATCH(2023,YEAR,0))+INDEX(WL_RATE_JUL,MATCH(2023,YEAR,0)))/2 -> 293.245 | D7: =(INDEX(WL_RATE_JAN,MATCH(2024,YEAR,0))+INDEX(WL_RATE_JUL,MATCH(2024,YEAR,0)))/2 -> 460.28 | E7: =WL_RATE_2026 -> 486.76
A8: Net cost per day, low (NET_COST_LO) | B8: USD per day | C8: =AVOID_COST_LO-INDEX(WL_RATE_AVG,1) -> 256.755 | D8: =AVOID_COST_LO-INDEX(WL_RATE_AVG,2) -> 89.72 | E8: =AVOID_COST_LO-WL_RATE_2026 -> 63.24
A9: Net cost per day, high (NET_COST_HI) | B9: USD per day | C9: =AVOID_COST_HI-INDEX(WL_RATE_AVG,1) -> 1176.755 | D9: =AVOID_COST_HI-INDEX(WL_RATE_AVG,2) -> 1009.72 | E9: =AVOID_COST_HI-WL_RATE_2026 -> 983.24
A10: Cost of excess days, low (EXCESS_COST_LO) | B10: USD per year | C10: =INDEX(EXCESS_DAYS,MATCH(2023,YEAR,0))*INDEX(NET_COST_LO,1) -> 8359172.5 | D10: =INDEX(EXCESS_DAYS,MATCH(2024,YEAR,0))*INDEX(NET_COST_LO,2) -> 1539056.9 | E10: =INDEX(EXCESS_DAYS,MATCH(2024,YEAR,0))*NET_COST_LO_NOW -> 1084819
A11: Cost of excess days, high (EXCESS_COST_HI) | B11: USD per year | C11: =INDEX(EXCESS_DAYS,MATCH(2023,YEAR,0))*INDEX(NET_COST_HI,1) -> 38311613 | D11: =INDEX(EXCESS_DAYS,MATCH(2024,YEAR,0))*INDEX(NET_COST_HI,2) -> 17320737 | E11: =INDEX(EXCESS_DAYS,MATCH(2024,YEAR,0))*NET_COST_HI_NOW -> 16866499
A12: Nursing-facility share of Dec 31 waitlist (NF_SHARE_DEC31), reported beside the result only | B12: share | C12: =INDEX(DEC31_NF,MATCH(2023,YEAR,0))/INDEX(DEC31_TOTAL,MATCH(2023,YEAR,0)) -> 0.82198953 | D12: =INDEX(DEC31_NF,MATCH(2024,YEAR,0))/INDEX(DEC31_TOTAL,MATCH(2024,YEAR,0)) -> 0.69364162
A14: Change in waitlist days, 2023 to 2024 (WL_DAYS_CHANGE_2024) | B14: share | C14: =INDEX(WL_DAYS,MATCH(2024,YEAR,0))/INDEX(WL_DAYS,MATCH(2023,YEAR,0))-1 -> -0.26741038
A15: Note: Leahi Hospital, Jan 2026 waitlisted rate | B15: USD per day | C15: =WL_RATE_LEAHI_2026 -> 480.19 | D15: Reported as a note; the other hospitals are at WL_RATE_2026. Not used in a calculation.
A17: Avoidable cost range AVOID_COST_LO to AVOID_COST_HI per waitlisted day, net of the waitlisted rate. All levels of care.

Sheet Tests
A1: Tests: definitions set on Sep 28, after the results were known (see spec Conventions)
A3: Test 1: opportunity cost | B3: Value | C3: Note
A4: Financial share, Dec 31 2020 | B4: =INDEX(SHARE_FINANCIAL,MATCH(2020,YEAR,0)) -> 0.20833333 | C4: COVID year
A5: Financial share, Dec 31 2021 | B5: =INDEX(SHARE_FINANCIAL,MATCH(2021,YEAR,0)) -> 0.22751323 | C5: COVID year
A6: Drop, 2020 to 2021 (T1_DROP_2021; negative = rise) | B6: =INDEX(SHARE_FINANCIAL,MATCH(2020,YEAR,0))-INDEX(SHARE_FINANCIAL,MATCH(2021,YEAR,0)) -> -0.019179894 | C6: Shown as a percent of the reasons total, i.e. percentage points
A7: Passes (drop >= T1_MIN_DROP_PTS) (T1_PASS_2021) | B7: =T1_DROP_2021*100>=T1_MIN_DROP_PTS -> FALSE | C7: Unrounded comparison; 2021 comparison is COVID-confounded
A8: Financial share, Dec 31 2023 | B8: =INDEX(SHARE_FINANCIAL,MATCH(2023,YEAR,0)) -> 0.23560209
A9: Financial share, Dec 31 2024 | B9: =INDEX(SHARE_FINANCIAL,MATCH(2024,YEAR,0)) -> 0.34682081
A10: Drop, 2023 to 2024 (T1_DROP_2024; negative = rise) | B10: =INDEX(SHARE_FINANCIAL,MATCH(2023,YEAR,0))-INDEX(SHARE_FINANCIAL,MATCH(2024,YEAR,0)) -> -0.11121872 | C10: Shown as a percent of the reasons total, i.e. percentage points
A11: Passes (drop >= T1_MIN_DROP_PTS) (T1_PASS_2024) | B11: =T1_DROP_2024*100>=T1_MIN_DROP_PTS -> FALSE | C11: Unrounded comparison
A12: Verdict (T1_VERDICT) | B12: =IF(AND(NOT(T1_PASS_2021),NOT(T1_PASS_2024)),"Falsified",IF(AND(T1_PASS_2021,NOT(T1_PASS_2024)),"Not falsified; weak (rests on the COVID-confounded 2021 comparison)","Not falsified")) -> Falsified | C12: Fails only if both drops fall short (lenient reading)
A14: Test 2: wait for the reset | B14: Value | C14: Note
A15: Least-squares slope of days per patient, 2017 to 2023 (T2_SLOPE) | B15: =SLOPE(INDEX(DAYS_PER_PT,1):INDEX(DAYS_PER_PT,7),INDEX(YEAR,1):INDEX(YEAR,7)) -> 1.8814213 | C15: days per patient per year
A16: Verdict (T2_VERDICT) | B16: =IF(T2_SLOPE<0,"Met","Not met") -> Not met | C16: Met = the trend slopes down (falling steadily toward 14)
A18: Test 3: new capacity | B18: Largest reason (LARGEST_REASON) | C18: Top count | D18: Reasons at the top count | E18: Recorded reasons incomplete
A19: =INDEX(YEAR,1) -> 2017 | B19: =IF((IF(INDEX(REASON_NO_BED,1)=MAX(INDEX(REASON_NO_BED,1),INDEX(REASON_BEHAVIOR,1),INDEX(REASON_SPECIAL_CARE,1),INDEX(REASON_FINANCIAL,1),INDEX(REASON_GUARDIANSHIP,1),INDEX(REASON_PASARR,1),INDEX(REASON_OTHER,1)),1,0)+IF(INDEX(REASON_BEHAVIOR,1)=MAX(INDEX(REASON_NO_BED,1),INDEX(REASON_BEHAVIOR,1),INDEX(REASON_SPECIAL_CARE,1),INDEX(REASON_FINANCIAL,1),INDEX(REASON_GUARDIANSHIP,1),INDEX(REASON_PASARR,1),INDEX(REASON_OTHER,1)),1,0)+IF(INDEX(REASON_SPECIAL_CARE,1)=MAX(INDEX(REASON_NO_BED,1),INDEX(REASON_BEHAVIOR,1),INDEX(REASON_SPECIAL_CARE,1),INDEX(REASON_FINANCIAL,1),INDEX(REASON_GUARDIANSHIP,1),INDEX(REASON_PASARR,1),INDEX(REASON_OTHER,1)),1,0)+IF(INDEX(REASON_FINANCIAL,1)=MAX(INDEX(REASON_NO_BED,1),INDEX(REASON_BEHAVIOR,1),INDEX(REASON_SPECIAL_CARE,1),INDEX(REASON_FINANCIAL,1),INDEX(REASON_GUARDIANSHIP,1),INDEX(REASON_PASARR,1),INDEX(REASON_OTHER,1)),1,0)+IF(INDEX(REASON_GUARDIANSHIP,1)=MAX(INDEX(REASON_NO_BED,1),INDEX(REASON_BEHAVIOR,1),INDEX(REASON_SPECIAL_CARE,1),INDEX(REASON_FINANCIAL,1),INDEX(REASON_GUARDIANSHIP,1),INDEX(REASON_PASARR,1),INDEX(REASON_OTHER,1)),1,0)+IF(INDEX(REASON_PASARR,1)=MAX(INDEX(REASON_NO_BED,1),INDEX(REASON_BEHAVIOR,1),INDEX(REASON_SPECIAL_CARE,1),INDEX(REASON_FINANCIAL,1),INDEX(REASON_GUARDIANSHIP,1),INDEX(REASON_PASARR,1),INDEX(REASON_OTHER,1)),1,0)+IF(INDEX(REASON_OTHER,1)=MAX(INDEX(REASON_NO_BED,1),INDEX(REASON_BEHAVIOR,1),INDEX(REASON_SPECIAL_CARE,1),INDEX(REASON_FINANCIAL,1),INDEX(REASON_GUARDIANSHIP,1),INDEX(REASON_PASARR,1),INDEX(REASON_OTHER,1)),1,0))>1,"Tie (none largest)",IF(INDEX(REASON_NO_BED,1)=MAX(INDEX(REASON_NO_BED,1),INDEX(REASON_BEHAVIOR,1),INDEX(REASON_SPECIAL_CARE,1),INDEX(REASON_FINANCIAL,1),INDEX(REASON_GUARDIANSHIP,1),INDEX(REASON_PASARR,1),INDEX(REASON_OTHER,1)),"No bed",IF(INDEX(REASON_BEHAVIOR,1)=MAX(INDEX(REASON_NO_BED,1),INDEX(REASON_BEHAVIOR,1),INDEX(REASON_SPECIAL_CARE,1),INDEX(REASON_FINANCIAL,1),INDEX(REASON_GUARDIANSHIP,1),INDEX(REASON_PASARR,1),INDEX(REASON_OTHER,1)),"Behavior",IF(INDEX(REASON_SPECIAL_CARE,1)=MAX(INDEX(REASON_NO_BED,1),INDEX(REASON_BEHAVIOR,1),INDEX(REASON_SPECIAL_CARE,1),INDEX(REASON_FINANCIAL,1),INDEX(REASON_GUARDIANSHIP,1),INDEX(REASON_PASARR,1),INDEX(REASON_OTHER,1)),"Special care",IF(INDEX(REASON_FINANCIAL,1)=MAX(INDEX(REASON_NO_BED,1),INDEX(REASON_BEHAVIOR,1),INDEX(REASON_SPECIAL_CARE,1),INDEX(REASON_FINANCIAL,1),INDEX(REASON_GUARDIANSHIP,1),INDEX(REASON_PASARR,1),INDEX(REASON_OTHER,1)),"Financial",IF(INDEX(REASON_GUARDIANSHIP,1)=MAX(INDEX(REASON_NO_BED,1),INDEX(REASON_BEHAVIOR,1),INDEX(REASON_SPECIAL_CARE,1),INDEX(REASON_FINANCIAL,1),INDEX(REASON_GUARDIANSHIP,1),INDEX(REASON_PASARR,1),INDEX(REASON_OTHER,1)),"Guardianship",IF(INDEX(REASON_PASARR,1)=MAX(INDEX(REASON_NO_BED,1),INDEX(REASON_BEHAVIOR,1),INDEX(REASON_SPECIAL_CARE,1),INDEX(REASON_FINANCIAL,1),INDEX(REASON_GUARDIANSHIP,1),INDEX(REASON_PASARR,1),INDEX(REASON_OTHER,1)),"PASARR",IF(INDEX(REASON_OTHER,1)=MAX(INDEX(REASON_NO_BED,1),INDEX(REASON_BEHAVIOR,1),INDEX(REASON_SPECIAL_CARE,1),INDEX(REASON_FINANCIAL,1),INDEX(REASON_GUARDIANSHIP,1),INDEX(REASON_PASARR,1),INDEX(REASON_OTHER,1)),"Other","?")))))))) -> No bed | C19: =MAX(INDEX(REASON_NO_BED,1),INDEX(REASON_BEHAVIOR,1),INDEX(REASON_SPECIAL_CARE,1),INDEX(REASON_FINANCIAL,1),INDEX(REASON_GUARDIANSHIP,1),INDEX(REASON_PASARR,1),INDEX(REASON_OTHER,1)) -> 39 | D19: =IF(INDEX(REASON_NO_BED,1)=MAX(INDEX(REASON_NO_BED,1),INDEX(REASON_BEHAVIOR,1),INDEX(REASON_SPECIAL_CARE,1),INDEX(REASON_FINANCIAL,1),INDEX(REASON_GUARDIANSHIP,1),INDEX(REASON_PASARR,1),INDEX(REASON_OTHER,1)),1,0)+IF(INDEX(REASON_BEHAVIOR,1)=MAX(INDEX(REASON_NO_BED,1),INDEX(REASON_BEHAVIOR,1),INDEX(REASON_SPECIAL_CARE,1),INDEX(REASON_FINANCIAL,1),INDEX(REASON_GUARDIANSHIP,1),INDEX(REASON_PASARR,1),INDEX(REASON_OTHER,1)),1,0)+IF(INDEX(REASON_SPECIAL_CARE,1)=MAX(INDEX(REASON_NO_BED,1),INDEX(REASON_BEHAVIOR,1),INDEX(REASON_SPECIAL_CARE,1),INDEX(REASON_FINANCIAL,1),INDEX(REASON_GUARDIANSHIP,1),INDEX(REASON_PASARR,1),INDEX(REASON_OTHER,1)),1,0)+IF(INDEX(REASON_FINANCIAL,1)=MAX(INDEX(REASON_NO_BED,1),INDEX(REASON_BEHAVIOR,1),INDEX(REASON_SPECIAL_CARE,1),INDEX(REASON_FINANCIAL,1),INDEX(REASON_GUARDIANSHIP,1),INDEX(REASON_PASARR,1),INDEX(REASON_OTHER,1)),1,0)+IF(INDEX(REASON_GUARDIANSHIP,1)=MAX(INDEX(REASON_NO_BED,1),INDEX(REASON_BEHAVIOR,1),INDEX(REASON_SPECIAL_CARE,1),INDEX(REASON_FINANCIAL,1),INDEX(REASON_GUARDIANSHIP,1),INDEX(REASON_PASARR,1),INDEX(REASON_OTHER,1)),1,0)+IF(INDEX(REASON_PASARR,1)=MAX(INDEX(REASON_NO_BED,1),INDEX(REASON_BEHAVIOR,1),INDEX(REASON_SPECIAL_CARE,1),INDEX(REASON_FINANCIAL,1),INDEX(REASON_GUARDIANSHIP,1),INDEX(REASON_PASARR,1),INDEX(REASON_OTHER,1)),1,0)+IF(INDEX(REASON_OTHER,1)=MAX(INDEX(REASON_NO_BED,1),INDEX(REASON_BEHAVIOR,1),INDEX(REASON_SPECIAL_CARE,1),INDEX(REASON_FINANCIAL,1),INDEX(REASON_GUARDIANSHIP,1),INDEX(REASON_PASARR,1),INDEX(REASON_OTHER,1)),1,0) -> 1 | E19: =INDEX(REASON_SUM,1)<INDEX(DEC31_TOTAL,1) -> TRUE
A20: =INDEX(YEAR,2) -> 2018 | B20: =IF((IF(INDEX(REASON_NO_BED,2)=MAX(INDEX(REASON_NO_BED,2),INDEX(REASON_BEHAVIOR,2),INDEX(REASON_SPECIAL_CARE,2),INDEX(REASON_FINANCIAL,2),INDEX(REASON_GUARDIANSHIP,2),INDEX(REASON_PASARR,2),INDEX(REASON_OTHER,2)),1,0)+IF(INDEX(REASON_BEHAVIOR,2)=MAX(INDEX(REASON_NO_BED,2),INDEX(REASON_BEHAVIOR,2),INDEX(REASON_SPECIAL_CARE,2),INDEX(REASON_FINANCIAL,2),INDEX(REASON_GUARDIANSHIP,2),INDEX(REASON_PASARR,2),INDEX(REASON_OTHER,2)),1,0)+IF(INDEX(REASON_SPECIAL_CARE,2)=MAX(INDEX(REASON_NO_BED,2),INDEX(REASON_BEHAVIOR,2),INDEX(REASON_SPECIAL_CARE,2),INDEX(REASON_FINANCIAL,2),INDEX(REASON_GUARDIANSHIP,2),INDEX(REASON_PASARR,2),INDEX(REASON_OTHER,2)),1,0)+IF(INDEX(REASON_FINANCIAL,2)=MAX(INDEX(REASON_NO_BED,2),INDEX(REASON_BEHAVIOR,2),INDEX(REASON_SPECIAL_CARE,2),INDEX(REASON_FINANCIAL,2),INDEX(REASON_GUARDIANSHIP,2),INDEX(REASON_PASARR,2),INDEX(REASON_OTHER,2)),1,0)+IF(INDEX(REASON_GUARDIANSHIP,2)=MAX(INDEX(REASON_NO_BED,2),INDEX(REASON_BEHAVIOR,2),INDEX(REASON_SPECIAL_CARE,2),INDEX(REASON_FINANCIAL,2),INDEX(REASON_GUARDIANSHIP,2),INDEX(REASON_PASARR,2),INDEX(REASON_OTHER,2)),1,0)+IF(INDEX(REASON_PASARR,2)=MAX(INDEX(REASON_NO_BED,2),INDEX(REASON_BEHAVIOR,2),INDEX(REASON_SPECIAL_CARE,2),INDEX(REASON_FINANCIAL,2),INDEX(REASON_GUARDIANSHIP,2),INDEX(REASON_PASARR,2),INDEX(REASON_OTHER,2)),1,0)+IF(INDEX(REASON_OTHER,2)=MAX(INDEX(REASON_NO_BED,2),INDEX(REASON_BEHAVIOR,2),INDEX(REASON_SPECIAL_CARE,2),INDEX(REASON_FINANCIAL,2),INDEX(REASON_GUARDIANSHIP,2),INDEX(REASON_PASARR,2),INDEX(REASON_OTHER,2)),1,0))>1,"Tie (none largest)",IF(INDEX(REASON_NO_BED,2)=MAX(INDEX(REASON_NO_BED,2),INDEX(REASON_BEHAVIOR,2),INDEX(REASON_SPECIAL_CARE,2),INDEX(REASON_FINANCIAL,2),INDEX(REASON_GUARDIANSHIP,2),INDEX(REASON_PASARR,2),INDEX(REASON_OTHER,2)),"No bed",IF(INDEX(REASON_BEHAVIOR,2)=MAX(INDEX(REASON_NO_BED,2),INDEX(REASON_BEHAVIOR,2),INDEX(REASON_SPECIAL_CARE,2),INDEX(REASON_FINANCIAL,2),INDEX(REASON_GUARDIANSHIP,2),INDEX(REASON_PASARR,2),INDEX(REASON_OTHER,2)),"Behavior",IF(INDEX(REASON_SPECIAL_CARE,2)=MAX(INDEX(REASON_NO_BED,2),INDEX(REASON_BEHAVIOR,2),INDEX(REASON_SPECIAL_CARE,2),INDEX(REASON_FINANCIAL,2),INDEX(REASON_GUARDIANSHIP,2),INDEX(REASON_PASARR,2),INDEX(REASON_OTHER,2)),"Special care",IF(INDEX(REASON_FINANCIAL,2)=MAX(INDEX(REASON_NO_BED,2),INDEX(REASON_BEHAVIOR,2),INDEX(REASON_SPECIAL_CARE,2),INDEX(REASON_FINANCIAL,2),INDEX(REASON_GUARDIANSHIP,2),INDEX(REASON_PASARR,2),INDEX(REASON_OTHER,2)),"Financial",IF(INDEX(REASON_GUARDIANSHIP,2)=MAX(INDEX(REASON_NO_BED,2),INDEX(REASON_BEHAVIOR,2),INDEX(REASON_SPECIAL_CARE,2),INDEX(REASON_FINANCIAL,2),INDEX(REASON_GUARDIANSHIP,2),INDEX(REASON_PASARR,2),INDEX(REASON_OTHER,2)),"Guardianship",IF(INDEX(REASON_PASARR,2)=MAX(INDEX(REASON_NO_BED,2),INDEX(REASON_BEHAVIOR,2),INDEX(REASON_SPECIAL_CARE,2),INDEX(REASON_FINANCIAL,2),INDEX(REASON_GUARDIANSHIP,2),INDEX(REASON_PASARR,2),INDEX(REASON_OTHER,2)),"PASARR",IF(INDEX(REASON_OTHER,2)=MAX(INDEX(REASON_NO_BED,2),INDEX(REASON_BEHAVIOR,2),INDEX(REASON_SPECIAL_CARE,2),INDEX(REASON_FINANCIAL,2),INDEX(REASON_GUARDIANSHIP,2),INDEX(REASON_PASARR,2),INDEX(REASON_OTHER,2)),"Other","?")))))))) -> No bed | C20: =MAX(INDEX(REASON_NO_BED,2),INDEX(REASON_BEHAVIOR,2),INDEX(REASON_SPECIAL_CARE,2),INDEX(REASON_FINANCIAL,2),INDEX(REASON_GUARDIANSHIP,2),INDEX(REASON_PASARR,2),INDEX(REASON_OTHER,2)) -> 57 | D20: =IF(INDEX(REASON_NO_BED,2)=MAX(INDEX(REASON_NO_BED,2),INDEX(REASON_BEHAVIOR,2),INDEX(REASON_SPECIAL_CARE,2),INDEX(REASON_FINANCIAL,2),INDEX(REASON_GUARDIANSHIP,2),INDEX(REASON_PASARR,2),INDEX(REASON_OTHER,2)),1,0)+IF(INDEX(REASON_BEHAVIOR,2)=MAX(INDEX(REASON_NO_BED,2),INDEX(REASON_BEHAVIOR,2),INDEX(REASON_SPECIAL_CARE,2),INDEX(REASON_FINANCIAL,2),INDEX(REASON_GUARDIANSHIP,2),INDEX(REASON_PASARR,2),INDEX(REASON_OTHER,2)),1,0)+IF(INDEX(REASON_SPECIAL_CARE,2)=MAX(INDEX(REASON_NO_BED,2),INDEX(REASON_BEHAVIOR,2),INDEX(REASON_SPECIAL_CARE,2),INDEX(REASON_FINANCIAL,2),INDEX(REASON_GUARDIANSHIP,2),INDEX(REASON_PASARR,2),INDEX(REASON_OTHER,2)),1,0)+IF(INDEX(REASON_FINANCIAL,2)=MAX(INDEX(REASON_NO_BED,2),INDEX(REASON_BEHAVIOR,2),INDEX(REASON_SPECIAL_CARE,2),INDEX(REASON_FINANCIAL,2),INDEX(REASON_GUARDIANSHIP,2),INDEX(REASON_PASARR,2),INDEX(REASON_OTHER,2)),1,0)+IF(INDEX(REASON_GUARDIANSHIP,2)=MAX(INDEX(REASON_NO_BED,2),INDEX(REASON_BEHAVIOR,2),INDEX(REASON_SPECIAL_CARE,2),INDEX(REASON_FINANCIAL,2),INDEX(REASON_GUARDIANSHIP,2),INDEX(REASON_PASARR,2),INDEX(REASON_OTHER,2)),1,0)+IF(INDEX(REASON_PASARR,2)=MAX(INDEX(REASON_NO_BED,2),INDEX(REASON_BEHAVIOR,2),INDEX(REASON_SPECIAL_CARE,2),INDEX(REASON_FINANCIAL,2),INDEX(REASON_GUARDIANSHIP,2),INDEX(REASON_PASARR,2),INDEX(REASON_OTHER,2)),1,0)+IF(INDEX(REASON_OTHER,2)=MAX(INDEX(REASON_NO_BED,2),INDEX(REASON_BEHAVIOR,2),INDEX(REASON_SPECIAL_CARE,2),INDEX(REASON_FINANCIAL,2),INDEX(REASON_GUARDIANSHIP,2),INDEX(REASON_PASARR,2),INDEX(REASON_OTHER,2)),1,0) -> 1 | E20: =INDEX(REASON_SUM,2)<INDEX(DEC31_TOTAL,2) -> FALSE
A21: =INDEX(YEAR,3) -> 2019 | B21: =IF((IF(INDEX(REASON_NO_BED,3)=MAX(INDEX(REASON_NO_BED,3),INDEX(REASON_BEHAVIOR,3),INDEX(REASON_SPECIAL_CARE,3),INDEX(REASON_FINANCIAL,3),INDEX(REASON_GUARDIANSHIP,3),INDEX(REASON_PASARR,3),INDEX(REASON_OTHER,3)),1,0)+IF(INDEX(REASON_BEHAVIOR,3)=MAX(INDEX(REASON_NO_BED,3),INDEX(REASON_BEHAVIOR,3),INDEX(REASON_SPECIAL_CARE,3),INDEX(REASON_FINANCIAL,3),INDEX(REASON_GUARDIANSHIP,3),INDEX(REASON_PASARR,3),INDEX(REASON_OTHER,3)),1,0)+IF(INDEX(REASON_SPECIAL_CARE,3)=MAX(INDEX(REASON_NO_BED,3),INDEX(REASON_BEHAVIOR,3),INDEX(REASON_SPECIAL_CARE,3),INDEX(REASON_FINANCIAL,3),INDEX(REASON_GUARDIANSHIP,3),INDEX(REASON_PASARR,3),INDEX(REASON_OTHER,3)),1,0)+IF(INDEX(REASON_FINANCIAL,3)=MAX(INDEX(REASON_NO_BED,3),INDEX(REASON_BEHAVIOR,3),INDEX(REASON_SPECIAL_CARE,3),INDEX(REASON_FINANCIAL,3),INDEX(REASON_GUARDIANSHIP,3),INDEX(REASON_PASARR,3),INDEX(REASON_OTHER,3)),1,0)+IF(INDEX(REASON_GUARDIANSHIP,3)=MAX(INDEX(REASON_NO_BED,3),INDEX(REASON_BEHAVIOR,3),INDEX(REASON_SPECIAL_CARE,3),INDEX(REASON_FINANCIAL,3),INDEX(REASON_GUARDIANSHIP,3),INDEX(REASON_PASARR,3),INDEX(REASON_OTHER,3)),1,0)+IF(INDEX(REASON_PASARR,3)=MAX(INDEX(REASON_NO_BED,3),INDEX(REASON_BEHAVIOR,3),INDEX(REASON_SPECIAL_CARE,3),INDEX(REASON_FINANCIAL,3),INDEX(REASON_GUARDIANSHIP,3),INDEX(REASON_PASARR,3),INDEX(REASON_OTHER,3)),1,0)+IF(INDEX(REASON_OTHER,3)=MAX(INDEX(REASON_NO_BED,3),INDEX(REASON_BEHAVIOR,3),INDEX(REASON_SPECIAL_CARE,3),INDEX(REASON_FINANCIAL,3),INDEX(REASON_GUARDIANSHIP,3),INDEX(REASON_PASARR,3),INDEX(REASON_OTHER,3)),1,0))>1,"Tie (none largest)",IF(INDEX(REASON_NO_BED,3)=MAX(INDEX(REASON_NO_BED,3),INDEX(REASON_BEHAVIOR,3),INDEX(REASON_SPECIAL_CARE,3),INDEX(REASON_FINANCIAL,3),INDEX(REASON_GUARDIANSHIP,3),INDEX(REASON_PASARR,3),INDEX(REASON_OTHER,3)),"No bed",IF(INDEX(REASON_BEHAVIOR,3)=MAX(INDEX(REASON_NO_BED,3),INDEX(REASON_BEHAVIOR,3),INDEX(REASON_SPECIAL_CARE,3),INDEX(REASON_FINANCIAL,3),INDEX(REASON_GUARDIANSHIP,3),INDEX(REASON_PASARR,3),INDEX(REASON_OTHER,3)),"Behavior",IF(INDEX(REASON_SPECIAL_CARE,3)=MAX(INDEX(REASON_NO_BED,3),INDEX(REASON_BEHAVIOR,3),INDEX(REASON_SPECIAL_CARE,3),INDEX(REASON_FINANCIAL,3),INDEX(REASON_GUARDIANSHIP,3),INDEX(REASON_PASARR,3),INDEX(REASON_OTHER,3)),"Special care",IF(INDEX(REASON_FINANCIAL,3)=MAX(INDEX(REASON_NO_BED,3),INDEX(REASON_BEHAVIOR,3),INDEX(REASON_SPECIAL_CARE,3),INDEX(REASON_FINANCIAL,3),INDEX(REASON_GUARDIANSHIP,3),INDEX(REASON_PASARR,3),INDEX(REASON_OTHER,3)),"Financial",IF(INDEX(REASON_GUARDIANSHIP,3)=MAX(INDEX(REASON_NO_BED,3),INDEX(REASON_BEHAVIOR,3),INDEX(REASON_SPECIAL_CARE,3),INDEX(REASON_FINANCIAL,3),INDEX(REASON_GUARDIANSHIP,3),INDEX(REASON_PASARR,3),INDEX(REASON_OTHER,3)),"Guardianship",IF(INDEX(REASON_PASARR,3)=MAX(INDEX(REASON_NO_BED,3),INDEX(REASON_BEHAVIOR,3),INDEX(REASON_SPECIAL_CARE,3),INDEX(REASON_FINANCIAL,3),INDEX(REASON_GUARDIANSHIP,3),INDEX(REASON_PASARR,3),INDEX(REASON_OTHER,3)),"PASARR",IF(INDEX(REASON_OTHER,3)=MAX(INDEX(REASON_NO_BED,3),INDEX(REASON_BEHAVIOR,3),INDEX(REASON_SPECIAL_CARE,3),INDEX(REASON_FINANCIAL,3),INDEX(REASON_GUARDIANSHIP,3),INDEX(REASON_PASARR,3),INDEX(REASON_OTHER,3)),"Other","?")))))))) -> No bed | C21: =MAX(INDEX(REASON_NO_BED,3),INDEX(REASON_BEHAVIOR,3),INDEX(REASON_SPECIAL_CARE,3),INDEX(REASON_FINANCIAL,3),INDEX(REASON_GUARDIANSHIP,3),INDEX(REASON_PASARR,3),INDEX(REASON_OTHER,3)) -> 72 | D21: =IF(INDEX(REASON_NO_BED,3)=MAX(INDEX(REASON_NO_BED,3),INDEX(REASON_BEHAVIOR,3),INDEX(REASON_SPECIAL_CARE,3),INDEX(REASON_FINANCIAL,3),INDEX(REASON_GUARDIANSHIP,3),INDEX(REASON_PASARR,3),INDEX(REASON_OTHER,3)),1,0)+IF(INDEX(REASON_BEHAVIOR,3)=MAX(INDEX(REASON_NO_BED,3),INDEX(REASON_BEHAVIOR,3),INDEX(REASON_SPECIAL_CARE,3),INDEX(REASON_FINANCIAL,3),INDEX(REASON_GUARDIANSHIP,3),INDEX(REASON_PASARR,3),INDEX(REASON_OTHER,3)),1,0)+IF(INDEX(REASON_SPECIAL_CARE,3)=MAX(INDEX(REASON_NO_BED,3),INDEX(REASON_BEHAVIOR,3),INDEX(REASON_SPECIAL_CARE,3),INDEX(REASON_FINANCIAL,3),INDEX(REASON_GUARDIANSHIP,3),INDEX(REASON_PASARR,3),INDEX(REASON_OTHER,3)),1,0)+IF(INDEX(REASON_FINANCIAL,3)=MAX(INDEX(REASON_NO_BED,3),INDEX(REASON_BEHAVIOR,3),INDEX(REASON_SPECIAL_CARE,3),INDEX(REASON_FINANCIAL,3),INDEX(REASON_GUARDIANSHIP,3),INDEX(REASON_PASARR,3),INDEX(REASON_OTHER,3)),1,0)+IF(INDEX(REASON_GUARDIANSHIP,3)=MAX(INDEX(REASON_NO_BED,3),INDEX(REASON_BEHAVIOR,3),INDEX(REASON_SPECIAL_CARE,3),INDEX(REASON_FINANCIAL,3),INDEX(REASON_GUARDIANSHIP,3),INDEX(REASON_PASARR,3),INDEX(REASON_OTHER,3)),1,0)+IF(INDEX(REASON_PASARR,3)=MAX(INDEX(REASON_NO_BED,3),INDEX(REASON_BEHAVIOR,3),INDEX(REASON_SPECIAL_CARE,3),INDEX(REASON_FINANCIAL,3),INDEX(REASON_GUARDIANSHIP,3),INDEX(REASON_PASARR,3),INDEX(REASON_OTHER,3)),1,0)+IF(INDEX(REASON_OTHER,3)=MAX(INDEX(REASON_NO_BED,3),INDEX(REASON_BEHAVIOR,3),INDEX(REASON_SPECIAL_CARE,3),INDEX(REASON_FINANCIAL,3),INDEX(REASON_GUARDIANSHIP,3),INDEX(REASON_PASARR,3),INDEX(REASON_OTHER,3)),1,0) -> 1 | E21: =INDEX(REASON_SUM,3)<INDEX(DEC31_TOTAL,3) -> FALSE
A22: =INDEX(YEAR,4) -> 2020 | B22: =IF((IF(INDEX(REASON_NO_BED,4)=MAX(INDEX(REASON_NO_BED,4),INDEX(REASON_BEHAVIOR,4),INDEX(REASON_SPECIAL_CARE,4),INDEX(REASON_FINANCIAL,4),INDEX(REASON_GUARDIANSHIP,4),INDEX(REASON_PASARR,4),INDEX(REASON_OTHER,4)),1,0)+IF(INDEX(REASON_BEHAVIOR,4)=MAX(INDEX(REASON_NO_BED,4),INDEX(REASON_BEHAVIOR,4),INDEX(REASON_SPECIAL_CARE,4),INDEX(REASON_FINANCIAL,4),INDEX(REASON_GUARDIANSHIP,4),INDEX(REASON_PASARR,4),INDEX(REASON_OTHER,4)),1,0)+IF(INDEX(REASON_SPECIAL_CARE,4)=MAX(INDEX(REASON_NO_BED,4),INDEX(REASON_BEHAVIOR,4),INDEX(REASON_SPECIAL_CARE,4),INDEX(REASON_FINANCIAL,4),INDEX(REASON_GUARDIANSHIP,4),INDEX(REASON_PASARR,4),INDEX(REASON_OTHER,4)),1,0)+IF(INDEX(REASON_FINANCIAL,4)=MAX(INDEX(REASON_NO_BED,4),INDEX(REASON_BEHAVIOR,4),INDEX(REASON_SPECIAL_CARE,4),INDEX(REASON_FINANCIAL,4),INDEX(REASON_GUARDIANSHIP,4),INDEX(REASON_PASARR,4),INDEX(REASON_OTHER,4)),1,0)+IF(INDEX(REASON_GUARDIANSHIP,4)=MAX(INDEX(REASON_NO_BED,4),INDEX(REASON_BEHAVIOR,4),INDEX(REASON_SPECIAL_CARE,4),INDEX(REASON_FINANCIAL,4),INDEX(REASON_GUARDIANSHIP,4),INDEX(REASON_PASARR,4),INDEX(REASON_OTHER,4)),1,0)+IF(INDEX(REASON_PASARR,4)=MAX(INDEX(REASON_NO_BED,4),INDEX(REASON_BEHAVIOR,4),INDEX(REASON_SPECIAL_CARE,4),INDEX(REASON_FINANCIAL,4),INDEX(REASON_GUARDIANSHIP,4),INDEX(REASON_PASARR,4),INDEX(REASON_OTHER,4)),1,0)+IF(INDEX(REASON_OTHER,4)=MAX(INDEX(REASON_NO_BED,4),INDEX(REASON_BEHAVIOR,4),INDEX(REASON_SPECIAL_CARE,4),INDEX(REASON_FINANCIAL,4),INDEX(REASON_GUARDIANSHIP,4),INDEX(REASON_PASARR,4),INDEX(REASON_OTHER,4)),1,0))>1,"Tie (none largest)",IF(INDEX(REASON_NO_BED,4)=MAX(INDEX(REASON_NO_BED,4),INDEX(REASON_BEHAVIOR,4),INDEX(REASON_SPECIAL_CARE,4),INDEX(REASON_FINANCIAL,4),INDEX(REASON_GUARDIANSHIP,4),INDEX(REASON_PASARR,4),INDEX(REASON_OTHER,4)),"No bed",IF(INDEX(REASON_BEHAVIOR,4)=MAX(INDEX(REASON_NO_BED,4),INDEX(REASON_BEHAVIOR,4),INDEX(REASON_SPECIAL_CARE,4),INDEX(REASON_FINANCIAL,4),INDEX(REASON_GUARDIANSHIP,4),INDEX(REASON_PASARR,4),INDEX(REASON_OTHER,4)),"Behavior",IF(INDEX(REASON_SPECIAL_CARE,4)=MAX(INDEX(REASON_NO_BED,4),INDEX(REASON_BEHAVIOR,4),INDEX(REASON_SPECIAL_CARE,4),INDEX(REASON_FINANCIAL,4),INDEX(REASON_GUARDIANSHIP,4),INDEX(REASON_PASARR,4),INDEX(REASON_OTHER,4)),"Special care",IF(INDEX(REASON_FINANCIAL,4)=MAX(INDEX(REASON_NO_BED,4),INDEX(REASON_BEHAVIOR,4),INDEX(REASON_SPECIAL_CARE,4),INDEX(REASON_FINANCIAL,4),INDEX(REASON_GUARDIANSHIP,4),INDEX(REASON_PASARR,4),INDEX(REASON_OTHER,4)),"Financial",IF(INDEX(REASON_GUARDIANSHIP,4)=MAX(INDEX(REASON_NO_BED,4),INDEX(REASON_BEHAVIOR,4),INDEX(REASON_SPECIAL_CARE,4),INDEX(REASON_FINANCIAL,4),INDEX(REASON_GUARDIANSHIP,4),INDEX(REASON_PASARR,4),INDEX(REASON_OTHER,4)),"Guardianship",IF(INDEX(REASON_PASARR,4)=MAX(INDEX(REASON_NO_BED,4),INDEX(REASON_BEHAVIOR,4),INDEX(REASON_SPECIAL_CARE,4),INDEX(REASON_FINANCIAL,4),INDEX(REASON_GUARDIANSHIP,4),INDEX(REASON_PASARR,4),INDEX(REASON_OTHER,4)),"PASARR",IF(INDEX(REASON_OTHER,4)=MAX(INDEX(REASON_NO_BED,4),INDEX(REASON_BEHAVIOR,4),INDEX(REASON_SPECIAL_CARE,4),INDEX(REASON_FINANCIAL,4),INDEX(REASON_GUARDIANSHIP,4),INDEX(REASON_PASARR,4),INDEX(REASON_OTHER,4)),"Other","?")))))))) -> No bed | C22: =MAX(INDEX(REASON_NO_BED,4),INDEX(REASON_BEHAVIOR,4),INDEX(REASON_SPECIAL_CARE,4),INDEX(REASON_FINANCIAL,4),INDEX(REASON_GUARDIANSHIP,4),INDEX(REASON_PASARR,4),INDEX(REASON_OTHER,4)) -> 41 | D22: =IF(INDEX(REASON_NO_BED,4)=MAX(INDEX(REASON_NO_BED,4),INDEX(REASON_BEHAVIOR,4),INDEX(REASON_SPECIAL_CARE,4),INDEX(REASON_FINANCIAL,4),INDEX(REASON_GUARDIANSHIP,4),INDEX(REASON_PASARR,4),INDEX(REASON_OTHER,4)),1,0)+IF(INDEX(REASON_BEHAVIOR,4)=MAX(INDEX(REASON_NO_BED,4),INDEX(REASON_BEHAVIOR,4),INDEX(REASON_SPECIAL_CARE,4),INDEX(REASON_FINANCIAL,4),INDEX(REASON_GUARDIANSHIP,4),INDEX(REASON_PASARR,4),INDEX(REASON_OTHER,4)),1,0)+IF(INDEX(REASON_SPECIAL_CARE,4)=MAX(INDEX(REASON_NO_BED,4),INDEX(REASON_BEHAVIOR,4),INDEX(REASON_SPECIAL_CARE,4),INDEX(REASON_FINANCIAL,4),INDEX(REASON_GUARDIANSHIP,4),INDEX(REASON_PASARR,4),INDEX(REASON_OTHER,4)),1,0)+IF(INDEX(REASON_FINANCIAL,4)=MAX(INDEX(REASON_NO_BED,4),INDEX(REASON_BEHAVIOR,4),INDEX(REASON_SPECIAL_CARE,4),INDEX(REASON_FINANCIAL,4),INDEX(REASON_GUARDIANSHIP,4),INDEX(REASON_PASARR,4),INDEX(REASON_OTHER,4)),1,0)+IF(INDEX(REASON_GUARDIANSHIP,4)=MAX(INDEX(REASON_NO_BED,4),INDEX(REASON_BEHAVIOR,4),INDEX(REASON_SPECIAL_CARE,4),INDEX(REASON_FINANCIAL,4),INDEX(REASON_GUARDIANSHIP,4),INDEX(REASON_PASARR,4),INDEX(REASON_OTHER,4)),1,0)+IF(INDEX(REASON_PASARR,4)=MAX(INDEX(REASON_NO_BED,4),INDEX(REASON_BEHAVIOR,4),INDEX(REASON_SPECIAL_CARE,4),INDEX(REASON_FINANCIAL,4),INDEX(REASON_GUARDIANSHIP,4),INDEX(REASON_PASARR,4),INDEX(REASON_OTHER,4)),1,0)+IF(INDEX(REASON_OTHER,4)=MAX(INDEX(REASON_NO_BED,4),INDEX(REASON_BEHAVIOR,4),INDEX(REASON_SPECIAL_CARE,4),INDEX(REASON_FINANCIAL,4),INDEX(REASON_GUARDIANSHIP,4),INDEX(REASON_PASARR,4),INDEX(REASON_OTHER,4)),1,0) -> 1 | E22: =INDEX(REASON_SUM,4)<INDEX(DEC31_TOTAL,4) -> FALSE
A23: =INDEX(YEAR,5) -> 2021 | B23: =IF((IF(INDEX(REASON_NO_BED,5)=MAX(INDEX(REASON_NO_BED,5),INDEX(REASON_BEHAVIOR,5),INDEX(REASON_SPECIAL_CARE,5),INDEX(REASON_FINANCIAL,5),INDEX(REASON_GUARDIANSHIP,5),INDEX(REASON_PASARR,5),INDEX(REASON_OTHER,5)),1,0)+IF(INDEX(REASON_BEHAVIOR,5)=MAX(INDEX(REASON_NO_BED,5),INDEX(REASON_BEHAVIOR,5),INDEX(REASON_SPECIAL_CARE,5),INDEX(REASON_FINANCIAL,5),INDEX(REASON_GUARDIANSHIP,5),INDEX(REASON_PASARR,5),INDEX(REASON_OTHER,5)),1,0)+IF(INDEX(REASON_SPECIAL_CARE,5)=MAX(INDEX(REASON_NO_BED,5),INDEX(REASON_BEHAVIOR,5),INDEX(REASON_SPECIAL_CARE,5),INDEX(REASON_FINANCIAL,5),INDEX(REASON_GUARDIANSHIP,5),INDEX(REASON_PASARR,5),INDEX(REASON_OTHER,5)),1,0)+IF(INDEX(REASON_FINANCIAL,5)=MAX(INDEX(REASON_NO_BED,5),INDEX(REASON_BEHAVIOR,5),INDEX(REASON_SPECIAL_CARE,5),INDEX(REASON_FINANCIAL,5),INDEX(REASON_GUARDIANSHIP,5),INDEX(REASON_PASARR,5),INDEX(REASON_OTHER,5)),1,0)+IF(INDEX(REASON_GUARDIANSHIP,5)=MAX(INDEX(REASON_NO_BED,5),INDEX(REASON_BEHAVIOR,5),INDEX(REASON_SPECIAL_CARE,5),INDEX(REASON_FINANCIAL,5),INDEX(REASON_GUARDIANSHIP,5),INDEX(REASON_PASARR,5),INDEX(REASON_OTHER,5)),1,0)+IF(INDEX(REASON_PASARR,5)=MAX(INDEX(REASON_NO_BED,5),INDEX(REASON_BEHAVIOR,5),INDEX(REASON_SPECIAL_CARE,5),INDEX(REASON_FINANCIAL,5),INDEX(REASON_GUARDIANSHIP,5),INDEX(REASON_PASARR,5),INDEX(REASON_OTHER,5)),1,0)+IF(INDEX(REASON_OTHER,5)=MAX(INDEX(REASON_NO_BED,5),INDEX(REASON_BEHAVIOR,5),INDEX(REASON_SPECIAL_CARE,5),INDEX(REASON_FINANCIAL,5),INDEX(REASON_GUARDIANSHIP,5),INDEX(REASON_PASARR,5),INDEX(REASON_OTHER,5)),1,0))>1,"Tie (none largest)",IF(INDEX(REASON_NO_BED,5)=MAX(INDEX(REASON_NO_BED,5),INDEX(REASON_BEHAVIOR,5),INDEX(REASON_SPECIAL_CARE,5),INDEX(REASON_FINANCIAL,5),INDEX(REASON_GUARDIANSHIP,5),INDEX(REASON_PASARR,5),INDEX(REASON_OTHER,5)),"No bed",IF(INDEX(REASON_BEHAVIOR,5)=MAX(INDEX(REASON_NO_BED,5),INDEX(REASON_BEHAVIOR,5),INDEX(REASON_SPECIAL_CARE,5),INDEX(REASON_FINANCIAL,5),INDEX(REASON_GUARDIANSHIP,5),INDEX(REASON_PASARR,5),INDEX(REASON_OTHER,5)),"Behavior",IF(INDEX(REASON_SPECIAL_CARE,5)=MAX(INDEX(REASON_NO_BED,5),INDEX(REASON_BEHAVIOR,5),INDEX(REASON_SPECIAL_CARE,5),INDEX(REASON_FINANCIAL,5),INDEX(REASON_GUARDIANSHIP,5),INDEX(REASON_PASARR,5),INDEX(REASON_OTHER,5)),"Special care",IF(INDEX(REASON_FINANCIAL,5)=MAX(INDEX(REASON_NO_BED,5),INDEX(REASON_BEHAVIOR,5),INDEX(REASON_SPECIAL_CARE,5),INDEX(REASON_FINANCIAL,5),INDEX(REASON_GUARDIANSHIP,5),INDEX(REASON_PASARR,5),INDEX(REASON_OTHER,5)),"Financial",IF(INDEX(REASON_GUARDIANSHIP,5)=MAX(INDEX(REASON_NO_BED,5),INDEX(REASON_BEHAVIOR,5),INDEX(REASON_SPECIAL_CARE,5),INDEX(REASON_FINANCIAL,5),INDEX(REASON_GUARDIANSHIP,5),INDEX(REASON_PASARR,5),INDEX(REASON_OTHER,5)),"Guardianship",IF(INDEX(REASON_PASARR,5)=MAX(INDEX(REASON_NO_BED,5),INDEX(REASON_BEHAVIOR,5),INDEX(REASON_SPECIAL_CARE,5),INDEX(REASON_FINANCIAL,5),INDEX(REASON_GUARDIANSHIP,5),INDEX(REASON_PASARR,5),INDEX(REASON_OTHER,5)),"PASARR",IF(INDEX(REASON_OTHER,5)=MAX(INDEX(REASON_NO_BED,5),INDEX(REASON_BEHAVIOR,5),INDEX(REASON_SPECIAL_CARE,5),INDEX(REASON_FINANCIAL,5),INDEX(REASON_GUARDIANSHIP,5),INDEX(REASON_PASARR,5),INDEX(REASON_OTHER,5)),"Other","?")))))))) -> No bed | C23: =MAX(INDEX(REASON_NO_BED,5),INDEX(REASON_BEHAVIOR,5),INDEX(REASON_SPECIAL_CARE,5),INDEX(REASON_FINANCIAL,5),INDEX(REASON_GUARDIANSHIP,5),INDEX(REASON_PASARR,5),INDEX(REASON_OTHER,5)) -> 50 | D23: =IF(INDEX(REASON_NO_BED,5)=MAX(INDEX(REASON_NO_BED,5),INDEX(REASON_BEHAVIOR,5),INDEX(REASON_SPECIAL_CARE,5),INDEX(REASON_FINANCIAL,5),INDEX(REASON_GUARDIANSHIP,5),INDEX(REASON_PASARR,5),INDEX(REASON_OTHER,5)),1,0)+IF(INDEX(REASON_BEHAVIOR,5)=MAX(INDEX(REASON_NO_BED,5),INDEX(REASON_BEHAVIOR,5),INDEX(REASON_SPECIAL_CARE,5),INDEX(REASON_FINANCIAL,5),INDEX(REASON_GUARDIANSHIP,5),INDEX(REASON_PASARR,5),INDEX(REASON_OTHER,5)),1,0)+IF(INDEX(REASON_SPECIAL_CARE,5)=MAX(INDEX(REASON_NO_BED,5),INDEX(REASON_BEHAVIOR,5),INDEX(REASON_SPECIAL_CARE,5),INDEX(REASON_FINANCIAL,5),INDEX(REASON_GUARDIANSHIP,5),INDEX(REASON_PASARR,5),INDEX(REASON_OTHER,5)),1,0)+IF(INDEX(REASON_FINANCIAL,5)=MAX(INDEX(REASON_NO_BED,5),INDEX(REASON_BEHAVIOR,5),INDEX(REASON_SPECIAL_CARE,5),INDEX(REASON_FINANCIAL,5),INDEX(REASON_GUARDIANSHIP,5),INDEX(REASON_PASARR,5),INDEX(REASON_OTHER,5)),1,0)+IF(INDEX(REASON_GUARDIANSHIP,5)=MAX(INDEX(REASON_NO_BED,5),INDEX(REASON_BEHAVIOR,5),INDEX(REASON_SPECIAL_CARE,5),INDEX(REASON_FINANCIAL,5),INDEX(REASON_GUARDIANSHIP,5),INDEX(REASON_PASARR,5),INDEX(REASON_OTHER,5)),1,0)+IF(INDEX(REASON_PASARR,5)=MAX(INDEX(REASON_NO_BED,5),INDEX(REASON_BEHAVIOR,5),INDEX(REASON_SPECIAL_CARE,5),INDEX(REASON_FINANCIAL,5),INDEX(REASON_GUARDIANSHIP,5),INDEX(REASON_PASARR,5),INDEX(REASON_OTHER,5)),1,0)+IF(INDEX(REASON_OTHER,5)=MAX(INDEX(REASON_NO_BED,5),INDEX(REASON_BEHAVIOR,5),INDEX(REASON_SPECIAL_CARE,5),INDEX(REASON_FINANCIAL,5),INDEX(REASON_GUARDIANSHIP,5),INDEX(REASON_PASARR,5),INDEX(REASON_OTHER,5)),1,0) -> 1 | E23: =INDEX(REASON_SUM,5)<INDEX(DEC31_TOTAL,5) -> FALSE
A24: =INDEX(YEAR,6) -> 2022 | B24: =IF((IF(INDEX(REASON_NO_BED,6)=MAX(INDEX(REASON_NO_BED,6),INDEX(REASON_BEHAVIOR,6),INDEX(REASON_SPECIAL_CARE,6),INDEX(REASON_FINANCIAL,6),INDEX(REASON_GUARDIANSHIP,6),INDEX(REASON_PASARR,6),INDEX(REASON_OTHER,6)),1,0)+IF(INDEX(REASON_BEHAVIOR,6)=MAX(INDEX(REASON_NO_BED,6),INDEX(REASON_BEHAVIOR,6),INDEX(REASON_SPECIAL_CARE,6),INDEX(REASON_FINANCIAL,6),INDEX(REASON_GUARDIANSHIP,6),INDEX(REASON_PASARR,6),INDEX(REASON_OTHER,6)),1,0)+IF(INDEX(REASON_SPECIAL_CARE,6)=MAX(INDEX(REASON_NO_BED,6),INDEX(REASON_BEHAVIOR,6),INDEX(REASON_SPECIAL_CARE,6),INDEX(REASON_FINANCIAL,6),INDEX(REASON_GUARDIANSHIP,6),INDEX(REASON_PASARR,6),INDEX(REASON_OTHER,6)),1,0)+IF(INDEX(REASON_FINANCIAL,6)=MAX(INDEX(REASON_NO_BED,6),INDEX(REASON_BEHAVIOR,6),INDEX(REASON_SPECIAL_CARE,6),INDEX(REASON_FINANCIAL,6),INDEX(REASON_GUARDIANSHIP,6),INDEX(REASON_PASARR,6),INDEX(REASON_OTHER,6)),1,0)+IF(INDEX(REASON_GUARDIANSHIP,6)=MAX(INDEX(REASON_NO_BED,6),INDEX(REASON_BEHAVIOR,6),INDEX(REASON_SPECIAL_CARE,6),INDEX(REASON_FINANCIAL,6),INDEX(REASON_GUARDIANSHIP,6),INDEX(REASON_PASARR,6),INDEX(REASON_OTHER,6)),1,0)+IF(INDEX(REASON_PASARR,6)=MAX(INDEX(REASON_NO_BED,6),INDEX(REASON_BEHAVIOR,6),INDEX(REASON_SPECIAL_CARE,6),INDEX(REASON_FINANCIAL,6),INDEX(REASON_GUARDIANSHIP,6),INDEX(REASON_PASARR,6),INDEX(REASON_OTHER,6)),1,0)+IF(INDEX(REASON_OTHER,6)=MAX(INDEX(REASON_NO_BED,6),INDEX(REASON_BEHAVIOR,6),INDEX(REASON_SPECIAL_CARE,6),INDEX(REASON_FINANCIAL,6),INDEX(REASON_GUARDIANSHIP,6),INDEX(REASON_PASARR,6),INDEX(REASON_OTHER,6)),1,0))>1,"Tie (none largest)",IF(INDEX(REASON_NO_BED,6)=MAX(INDEX(REASON_NO_BED,6),INDEX(REASON_BEHAVIOR,6),INDEX(REASON_SPECIAL_CARE,6),INDEX(REASON_FINANCIAL,6),INDEX(REASON_GUARDIANSHIP,6),INDEX(REASON_PASARR,6),INDEX(REASON_OTHER,6)),"No bed",IF(INDEX(REASON_BEHAVIOR,6)=MAX(INDEX(REASON_NO_BED,6),INDEX(REASON_BEHAVIOR,6),INDEX(REASON_SPECIAL_CARE,6),INDEX(REASON_FINANCIAL,6),INDEX(REASON_GUARDIANSHIP,6),INDEX(REASON_PASARR,6),INDEX(REASON_OTHER,6)),"Behavior",IF(INDEX(REASON_SPECIAL_CARE,6)=MAX(INDEX(REASON_NO_BED,6),INDEX(REASON_BEHAVIOR,6),INDEX(REASON_SPECIAL_CARE,6),INDEX(REASON_FINANCIAL,6),INDEX(REASON_GUARDIANSHIP,6),INDEX(REASON_PASARR,6),INDEX(REASON_OTHER,6)),"Special care",IF(INDEX(REASON_FINANCIAL,6)=MAX(INDEX(REASON_NO_BED,6),INDEX(REASON_BEHAVIOR,6),INDEX(REASON_SPECIAL_CARE,6),INDEX(REASON_FINANCIAL,6),INDEX(REASON_GUARDIANSHIP,6),INDEX(REASON_PASARR,6),INDEX(REASON_OTHER,6)),"Financial",IF(INDEX(REASON_GUARDIANSHIP,6)=MAX(INDEX(REASON_NO_BED,6),INDEX(REASON_BEHAVIOR,6),INDEX(REASON_SPECIAL_CARE,6),INDEX(REASON_FINANCIAL,6),INDEX(REASON_GUARDIANSHIP,6),INDEX(REASON_PASARR,6),INDEX(REASON_OTHER,6)),"Guardianship",IF(INDEX(REASON_PASARR,6)=MAX(INDEX(REASON_NO_BED,6),INDEX(REASON_BEHAVIOR,6),INDEX(REASON_SPECIAL_CARE,6),INDEX(REASON_FINANCIAL,6),INDEX(REASON_GUARDIANSHIP,6),INDEX(REASON_PASARR,6),INDEX(REASON_OTHER,6)),"PASARR",IF(INDEX(REASON_OTHER,6)=MAX(INDEX(REASON_NO_BED,6),INDEX(REASON_BEHAVIOR,6),INDEX(REASON_SPECIAL_CARE,6),INDEX(REASON_FINANCIAL,6),INDEX(REASON_GUARDIANSHIP,6),INDEX(REASON_PASARR,6),INDEX(REASON_OTHER,6)),"Other","?")))))))) -> Financial | C24: =MAX(INDEX(REASON_NO_BED,6),INDEX(REASON_BEHAVIOR,6),INDEX(REASON_SPECIAL_CARE,6),INDEX(REASON_FINANCIAL,6),INDEX(REASON_GUARDIANSHIP,6),INDEX(REASON_PASARR,6),INDEX(REASON_OTHER,6)) -> 75 | D24: =IF(INDEX(REASON_NO_BED,6)=MAX(INDEX(REASON_NO_BED,6),INDEX(REASON_BEHAVIOR,6),INDEX(REASON_SPECIAL_CARE,6),INDEX(REASON_FINANCIAL,6),INDEX(REASON_GUARDIANSHIP,6),INDEX(REASON_PASARR,6),INDEX(REASON_OTHER,6)),1,0)+IF(INDEX(REASON_BEHAVIOR,6)=MAX(INDEX(REASON_NO_BED,6),INDEX(REASON_BEHAVIOR,6),INDEX(REASON_SPECIAL_CARE,6),INDEX(REASON_FINANCIAL,6),INDEX(REASON_GUARDIANSHIP,6),INDEX(REASON_PASARR,6),INDEX(REASON_OTHER,6)),1,0)+IF(INDEX(REASON_SPECIAL_CARE,6)=MAX(INDEX(REASON_NO_BED,6),INDEX(REASON_BEHAVIOR,6),INDEX(REASON_SPECIAL_CARE,6),INDEX(REASON_FINANCIAL,6),INDEX(REASON_GUARDIANSHIP,6),INDEX(REASON_PASARR,6),INDEX(REASON_OTHER,6)),1,0)+IF(INDEX(REASON_FINANCIAL,6)=MAX(INDEX(REASON_NO_BED,6),INDEX(REASON_BEHAVIOR,6),INDEX(REASON_SPECIAL_CARE,6),INDEX(REASON_FINANCIAL,6),INDEX(REASON_GUARDIANSHIP,6),INDEX(REASON_PASARR,6),INDEX(REASON_OTHER,6)),1,0)+IF(INDEX(REASON_GUARDIANSHIP,6)=MAX(INDEX(REASON_NO_BED,6),INDEX(REASON_BEHAVIOR,6),INDEX(REASON_SPECIAL_CARE,6),INDEX(REASON_FINANCIAL,6),INDEX(REASON_GUARDIANSHIP,6),INDEX(REASON_PASARR,6),INDEX(REASON_OTHER,6)),1,0)+IF(INDEX(REASON_PASARR,6)=MAX(INDEX(REASON_NO_BED,6),INDEX(REASON_BEHAVIOR,6),INDEX(REASON_SPECIAL_CARE,6),INDEX(REASON_FINANCIAL,6),INDEX(REASON_GUARDIANSHIP,6),INDEX(REASON_PASARR,6),INDEX(REASON_OTHER,6)),1,0)+IF(INDEX(REASON_OTHER,6)=MAX(INDEX(REASON_NO_BED,6),INDEX(REASON_BEHAVIOR,6),INDEX(REASON_SPECIAL_CARE,6),INDEX(REASON_FINANCIAL,6),INDEX(REASON_GUARDIANSHIP,6),INDEX(REASON_PASARR,6),INDEX(REASON_OTHER,6)),1,0) -> 1 | E24: =INDEX(REASON_SUM,6)<INDEX(DEC31_TOTAL,6) -> FALSE
A25: =INDEX(YEAR,7) -> 2023 | B25: =IF((IF(INDEX(REASON_NO_BED,7)=MAX(INDEX(REASON_NO_BED,7),INDEX(REASON_BEHAVIOR,7),INDEX(REASON_SPECIAL_CARE,7),INDEX(REASON_FINANCIAL,7),INDEX(REASON_GUARDIANSHIP,7),INDEX(REASON_PASARR,7),INDEX(REASON_OTHER,7)),1,0)+IF(INDEX(REASON_BEHAVIOR,7)=MAX(INDEX(REASON_NO_BED,7),INDEX(REASON_BEHAVIOR,7),INDEX(REASON_SPECIAL_CARE,7),INDEX(REASON_FINANCIAL,7),INDEX(REASON_GUARDIANSHIP,7),INDEX(REASON_PASARR,7),INDEX(REASON_OTHER,7)),1,0)+IF(INDEX(REASON_SPECIAL_CARE,7)=MAX(INDEX(REASON_NO_BED,7),INDEX(REASON_BEHAVIOR,7),INDEX(REASON_SPECIAL_CARE,7),INDEX(REASON_FINANCIAL,7),INDEX(REASON_GUARDIANSHIP,7),INDEX(REASON_PASARR,7),INDEX(REASON_OTHER,7)),1,0)+IF(INDEX(REASON_FINANCIAL,7)=MAX(INDEX(REASON_NO_BED,7),INDEX(REASON_BEHAVIOR,7),INDEX(REASON_SPECIAL_CARE,7),INDEX(REASON_FINANCIAL,7),INDEX(REASON_GUARDIANSHIP,7),INDEX(REASON_PASARR,7),INDEX(REASON_OTHER,7)),1,0)+IF(INDEX(REASON_GUARDIANSHIP,7)=MAX(INDEX(REASON_NO_BED,7),INDEX(REASON_BEHAVIOR,7),INDEX(REASON_SPECIAL_CARE,7),INDEX(REASON_FINANCIAL,7),INDEX(REASON_GUARDIANSHIP,7),INDEX(REASON_PASARR,7),INDEX(REASON_OTHER,7)),1,0)+IF(INDEX(REASON_PASARR,7)=MAX(INDEX(REASON_NO_BED,7),INDEX(REASON_BEHAVIOR,7),INDEX(REASON_SPECIAL_CARE,7),INDEX(REASON_FINANCIAL,7),INDEX(REASON_GUARDIANSHIP,7),INDEX(REASON_PASARR,7),INDEX(REASON_OTHER,7)),1,0)+IF(INDEX(REASON_OTHER,7)=MAX(INDEX(REASON_NO_BED,7),INDEX(REASON_BEHAVIOR,7),INDEX(REASON_SPECIAL_CARE,7),INDEX(REASON_FINANCIAL,7),INDEX(REASON_GUARDIANSHIP,7),INDEX(REASON_PASARR,7),INDEX(REASON_OTHER,7)),1,0))>1,"Tie (none largest)",IF(INDEX(REASON_NO_BED,7)=MAX(INDEX(REASON_NO_BED,7),INDEX(REASON_BEHAVIOR,7),INDEX(REASON_SPECIAL_CARE,7),INDEX(REASON_FINANCIAL,7),INDEX(REASON_GUARDIANSHIP,7),INDEX(REASON_PASARR,7),INDEX(REASON_OTHER,7)),"No bed",IF(INDEX(REASON_BEHAVIOR,7)=MAX(INDEX(REASON_NO_BED,7),INDEX(REASON_BEHAVIOR,7),INDEX(REASON_SPECIAL_CARE,7),INDEX(REASON_FINANCIAL,7),INDEX(REASON_GUARDIANSHIP,7),INDEX(REASON_PASARR,7),INDEX(REASON_OTHER,7)),"Behavior",IF(INDEX(REASON_SPECIAL_CARE,7)=MAX(INDEX(REASON_NO_BED,7),INDEX(REASON_BEHAVIOR,7),INDEX(REASON_SPECIAL_CARE,7),INDEX(REASON_FINANCIAL,7),INDEX(REASON_GUARDIANSHIP,7),INDEX(REASON_PASARR,7),INDEX(REASON_OTHER,7)),"Special care",IF(INDEX(REASON_FINANCIAL,7)=MAX(INDEX(REASON_NO_BED,7),INDEX(REASON_BEHAVIOR,7),INDEX(REASON_SPECIAL_CARE,7),INDEX(REASON_FINANCIAL,7),INDEX(REASON_GUARDIANSHIP,7),INDEX(REASON_PASARR,7),INDEX(REASON_OTHER,7)),"Financial",IF(INDEX(REASON_GUARDIANSHIP,7)=MAX(INDEX(REASON_NO_BED,7),INDEX(REASON_BEHAVIOR,7),INDEX(REASON_SPECIAL_CARE,7),INDEX(REASON_FINANCIAL,7),INDEX(REASON_GUARDIANSHIP,7),INDEX(REASON_PASARR,7),INDEX(REASON_OTHER,7)),"Guardianship",IF(INDEX(REASON_PASARR,7)=MAX(INDEX(REASON_NO_BED,7),INDEX(REASON_BEHAVIOR,7),INDEX(REASON_SPECIAL_CARE,7),INDEX(REASON_FINANCIAL,7),INDEX(REASON_GUARDIANSHIP,7),INDEX(REASON_PASARR,7),INDEX(REASON_OTHER,7)),"PASARR",IF(INDEX(REASON_OTHER,7)=MAX(INDEX(REASON_NO_BED,7),INDEX(REASON_BEHAVIOR,7),INDEX(REASON_SPECIAL_CARE,7),INDEX(REASON_FINANCIAL,7),INDEX(REASON_GUARDIANSHIP,7),INDEX(REASON_PASARR,7),INDEX(REASON_OTHER,7)),"Other","?")))))))) -> Behavior | C25: =MAX(INDEX(REASON_NO_BED,7),INDEX(REASON_BEHAVIOR,7),INDEX(REASON_SPECIAL_CARE,7),INDEX(REASON_FINANCIAL,7),INDEX(REASON_GUARDIANSHIP,7),INDEX(REASON_PASARR,7),INDEX(REASON_OTHER,7)) -> 48 | D25: =IF(INDEX(REASON_NO_BED,7)=MAX(INDEX(REASON_NO_BED,7),INDEX(REASON_BEHAVIOR,7),INDEX(REASON_SPECIAL_CARE,7),INDEX(REASON_FINANCIAL,7),INDEX(REASON_GUARDIANSHIP,7),INDEX(REASON_PASARR,7),INDEX(REASON_OTHER,7)),1,0)+IF(INDEX(REASON_BEHAVIOR,7)=MAX(INDEX(REASON_NO_BED,7),INDEX(REASON_BEHAVIOR,7),INDEX(REASON_SPECIAL_CARE,7),INDEX(REASON_FINANCIAL,7),INDEX(REASON_GUARDIANSHIP,7),INDEX(REASON_PASARR,7),INDEX(REASON_OTHER,7)),1,0)+IF(INDEX(REASON_SPECIAL_CARE,7)=MAX(INDEX(REASON_NO_BED,7),INDEX(REASON_BEHAVIOR,7),INDEX(REASON_SPECIAL_CARE,7),INDEX(REASON_FINANCIAL,7),INDEX(REASON_GUARDIANSHIP,7),INDEX(REASON_PASARR,7),INDEX(REASON_OTHER,7)),1,0)+IF(INDEX(REASON_FINANCIAL,7)=MAX(INDEX(REASON_NO_BED,7),INDEX(REASON_BEHAVIOR,7),INDEX(REASON_SPECIAL_CARE,7),INDEX(REASON_FINANCIAL,7),INDEX(REASON_GUARDIANSHIP,7),INDEX(REASON_PASARR,7),INDEX(REASON_OTHER,7)),1,0)+IF(INDEX(REASON_GUARDIANSHIP,7)=MAX(INDEX(REASON_NO_BED,7),INDEX(REASON_BEHAVIOR,7),INDEX(REASON_SPECIAL_CARE,7),INDEX(REASON_FINANCIAL,7),INDEX(REASON_GUARDIANSHIP,7),INDEX(REASON_PASARR,7),INDEX(REASON_OTHER,7)),1,0)+IF(INDEX(REASON_PASARR,7)=MAX(INDEX(REASON_NO_BED,7),INDEX(REASON_BEHAVIOR,7),INDEX(REASON_SPECIAL_CARE,7),INDEX(REASON_FINANCIAL,7),INDEX(REASON_GUARDIANSHIP,7),INDEX(REASON_PASARR,7),INDEX(REASON_OTHER,7)),1,0)+IF(INDEX(REASON_OTHER,7)=MAX(INDEX(REASON_NO_BED,7),INDEX(REASON_BEHAVIOR,7),INDEX(REASON_SPECIAL_CARE,7),INDEX(REASON_FINANCIAL,7),INDEX(REASON_GUARDIANSHIP,7),INDEX(REASON_PASARR,7),INDEX(REASON_OTHER,7)),1,0) -> 1 | E25: =INDEX(REASON_SUM,7)<INDEX(DEC31_TOTAL,7) -> FALSE
